Workbook
Name ANDRES: #REF!
Name ANDRES: #REF!
Name ANDRES: #REF!
Name ANDRES: #REF!
Name ARON: #REF!
Name AUX: [1]SEM.01!$AJ$6:$AK$45
Name BASE: #REF!
Name COPIA: #REF!
Name COPIAA: #REF!
Name CRUCE: #REF!
Name CRUCES: #REF!
Name IGOB: #REF!
Name INCON: #REF!
Name MIRE: #REF!
Name MIRO: #REF!
Name NOM: #REF!
Name NOM.: #REF!
Name NOM.04: #REF!
Name NOMIN: #REF!
Name NOMINA: #REF!
Name NUEVO: #REF!
Name SEM.03: #REF!
Name SEM.03B: #REF!
Name SEM.03C: #REF!
Name SEM.03V: #REF!
Name SEM.04: #REF!
Name SEM.04.: #REF!
Name SEMANA.03: #REF!
Name SSEM.08: [1]SEM.01!$AG$6:$AH$45
Name TABLA3: #REF!
Name TABLA4: #REF!
Name TABLA7: #REF!
Name TABLA7.05: #REF!
Name TABLA7.08: [1]SEM.01!$AM$6:$AN$45
Name TABLA7.3: #REF!
Name TABLA7.31: #REF!
Name TABLA7.5: #REF!
Name TABLA8: #REF!

Sheet NOMINA
B1: FLETES SOTELO S.A. DE C.V.
B2: VIAJES FORANEOS JUAREZ - CHIHUAHUA
B3: SEMANA #42 PERIODO DEL 06 AL 12 DE OCTUBRE DEL 2025
C4: EMPLEADO | D4: VIAJES FORANEOS | E4: NO. DE REPORTE | L4: RENDIMIENTO
B5: 0001 | C5: AGUILAR ESQUIVEL CARLOS | D5: =+'AGUILAR ESQUIVEL CARLOS'!Q37 -> 9671.0291 | E5: =+'AGUILAR ESQUIVEL CARLOS'!O40 -> 45901 | F5: =+'AGUILAR ESQUIVEL CARLOS'!O41 -> 45913 | G5: =+'AGUILAR ESQUIVEL CARLOS'!O42 -> 45944 | H5: =+'AGUILAR ESQUIVEL CARLOS'!O43 -> 45980 | I5: =+'AGUILAR ESQUIVEL CARLOS'!O44 -> 0 | J5: =+'AGUILAR ESQUIVEL CARLOS'!O45 -> 0 | K5: 0
B6: 1332 | C6: AGUILAR RODRIGUEZ JORGE ALONSO | D6: =+'AGUILAR RODRIGUEZ JORGE ALONSO'!Q37 -> 8324.5218 | E6: =+'AGUILAR RODRIGUEZ JORGE ALONSO'!O40 -> 45859 | F6: =+'AGUILAR RODRIGUEZ JORGE ALONSO'!O41 -> 45885 | G6: =+'AGUILAR RODRIGUEZ JORGE ALONSO'!O42 -> 46315 | H6: =+'AGUILAR RODRIGUEZ JORGE ALONSO'!O43 -> 46333 | I6: =+'AGUILAR RODRIGUEZ JORGE ALONSO'!O44 -> 0 | J6: =+'AGUILAR RODRIGUEZ JORGE ALONSO'!O45 -> 0 | K6: 0
B7: 2067 | C7: =+'AGUILERA CONTRERAS LUIS GERARDO'!E11 -> AGUILERA CONTRERAS LUIS GERARDO | D7: =+'AGUILERA CONTRERAS LUIS GERARDO'!Q38 -> 6532.4526 | E7: =+'AGUILERA CONTRERAS LUIS GERARDO'!O41 -> 46386 | F7: =+'AGUILERA CONTRERAS LUIS GERARDO'!O42 -> 45920 | G7: =+'AGUILERA CONTRERAS LUIS GERARDO'!O43 -> 45931 | H7: =+'AGUILERA CONTRERAS LUIS GERARDO'!O44 -> 45964 | I7: =+'AGUILERA CONTRERAS LUIS GERARDO'!O45 -> 0 | J7: =+'AGUILERA CONTRERAS LUIS GERARDO'!O46 -> 0
B8: 2505 | C8: ANCHONDO ROMERO CESAR ALEJANDRO | D8: =+'ANCHONDO ROMERO CESAR ALEJANDRO'!Q37 -> 2113.339 | E8: =+'ANCHONDO ROMERO CESAR ALEJANDRO'!O40 -> 45949 | F8: =+'ANCHONDO ROMERO CESAR ALEJANDRO'!O41 -> 45967 | G8: =+'ANCHONDO ROMERO CESAR ALEJANDRO'!O42 -> 0 | H8: =+'ANCHONDO ROMERO CESAR ALEJANDRO'!O43 -> 0 | I8: =+'ANCHONDO ROMERO CESAR ALEJANDRO'!O44 -> 0 | J8: =+'ANCHONDO ROMERO CESAR ALEJANDRO'!O45 -> 0
B9: 0007 | C9: BALDERRAMA ROBLES JORGE | D9: =+'BALDERRAMA ROBLES JORGE'!Q37 -> #N/A | E9: =+'BALDERRAMA ROBLES JORGE'!O40 -> 0 | F9: =+'BALDERRAMA ROBLES JORGE'!O41 -> 0 | G9: =+'BALDERRAMA ROBLES JORGE'!O42 -> 0 | H9: =+'BALDERRAMA ROBLES JORGE'!O43 -> 0 | I9: =+'BALDERRAMA ROBLES JORGE'!O44 -> 0 | J9: =+'BALDERRAMA ROBLES JORGE'!O45 -> 0
B10: 0028 | C10: BALLEZA RAMIREZ JESUS JOSE | D10: =+'BALLEZA RAMIREZ JESUS JOSE'!Q37 -> 14125.009 | E10: =+'BALLEZA RAMIREZ JESUS JOSE'!O40 -> 46394 | F10: =+'BALLEZA RAMIREZ JESUS JOSE'!O41 -> 45912 | G10: =+'BALLEZA RAMIREZ JESUS JOSE'!O42 -> 45955 | H10: =+'BALLEZA RAMIREZ JESUS JOSE'!O43 -> 45946 | I10: =+'BALLEZA RAMIREZ JESUS JOSE'!O44 -> 45983 | J10: =+'BALLEZA RAMIREZ JESUS JOSE'!O45 -> 0
B11: 0029 | C11: BURGOS TORRES RIGOBERTO | D11: =+'BURGOS TORRES RIGOBERTO'!Q36 -> 8962.2219 | E11: =+'BURGOS TORRES RIGOBERTO'!O39 -> 46392 | F11: =+'BURGOS TORRES RIGOBERTO'!O40 -> 45916 | G11: =+'BURGOS TORRES RIGOBERTO'!O41 -> 45952 | H11: =+'BURGOS TORRES RIGOBERTO'!O42 -> 0 | I11: =+'BURGOS TORRES RIGOBERTO'!O43 -> 0 | J11: =+'BURGOS TORRES RIGOBERTO'!O44 -> 0 | K11: =+'BURGOS TORRES RIGOBERTO'!O45 -> 0
B12: 2550 | C12: CARDENAS CARDENAS JAVIER ALEJANDRO | D12: =+'CARDENAS CARDENAS JAVIER '!Q37 -> #N/A | E12: =+'CARDENAS CARDENAS JAVIER '!O40 -> 0 | F12: =+'CARDENAS CARDENAS JAVIER '!O41 -> 0 | G12: =+'CARDENAS CARDENAS JAVIER '!O42 -> 0 | H12: =+'CARDENAS CARDENAS JAVIER '!O43 -> 0 | I12: =+'CARDENAS CARDENAS JAVIER '!O44 -> 0 | J12: =+'CARDENAS CARDENAS JAVIER '!O45 -> 0 | K12: =+'CARDENAS CARDENAS JAVIER '!O46 -> 0
B13: 0035 | C13: CARRERA REYES MARTIN SEBASTIAN | D13: =+'CARRERA REYES MARTIN SEBASTIAN'!Q38 -> 7511.5417 | E13: =+'CARRERA REYES MARTIN SEBASTIAN'!O41 -> 46381 | F13: =+'CARRERA REYES MARTIN SEBASTIAN'!O42 -> 45917 | G13: =+'CARRERA REYES MARTIN SEBASTIAN'!O43 -> 45932 | H13: =+'CARRERA REYES MARTIN SEBASTIAN'!O44 -> 45962 | I13: =+'CARRERA REYES MARTIN SEBASTIAN'!O45 -> 0 | J13: =+'CARRERA REYES MARTIN SEBASTIAN'!O46 -> 0
B14: 2548 | C14: CORDOVA URIBE JOSE ADRIAN | D14: =+'CORDOVA URIBE JOSE ADRIAN'!Q37 -> #N/A | E14: =+'CORDOVA URIBE JOSE ADRIAN'!O40 -> 0 | F14: =+'CORDOVA URIBE JOSE ADRIAN'!O41 -> 0 | G14: =+'CORDOVA URIBE JOSE ADRIAN'!O42 -> 0 | H14: =+'CORDOVA URIBE JOSE ADRIAN'!O43 -> 0 | I14: =+'CORDOVA URIBE JOSE ADRIAN'!O44 -> 0 | J14: =+'CORDOVA URIBE JOSE ADRIAN'!O45 -> 0 | K14: =+'CORDOVA URIBE JOSE ADRIAN'!O46 -> 0
B15: 2508 | C15: GUZMAN CHAPARRO PEDRO | D15: =+'GUZMAN CHAPARRO PEDRO'!Q37 -> 5842.532 | E15: =+'GUZMAN CHAPARRO PEDRO'!O40 -> 45902 | F15: =+'GUZMAN CHAPARRO PEDRO'!O41 -> 45927 | G15: =+'GUZMAN CHAPARRO PEDRO'!O42 -> 45971 | H15: =+'GUZMAN CHAPARRO PEDRO'!O43 -> 0 | I15: =+'GUZMAN CHAPARRO PEDRO'!O44 -> 0 | J15: =+'GUZMAN CHAPARRO PEDRO'!O45 -> 0
C16: HERNANDEZ LICANO JOSE LUIS | D16: =+'HERNANDEZ LICANO JOSE LUIS'!Q37 -> 6324.7247 | E16: =+'HERNANDEZ LICANO JOSE LUIS'!O40 -> 45907 | F16: =+'HERNANDEZ LICANO JOSE LUIS'!O41 -> 45926 | G16: =+'HERNANDEZ LICANO JOSE LUIS'!O42 -> 45951 | H16: =+'HERNANDEZ LICANO JOSE LUIS'!O43 -> 0 | I16: =+'HERNANDEZ LICANO JOSE LUIS'!O44 -> 0 | J16: =+'HERNANDEZ LICANO JOSE LUIS'!O45 -> 0 | K16: =+'HERNANDEZ LICANO JOSE LUIS'!O46 -> 0
B17: 2020 | C17: LIRA ARCEO JOEL EDUARDO | D17: =+'LIRA ARCEO JOEL EDUARDO'!Q37 -> 689.7019 | E17: =+'LIRA ARCEO JOEL EDUARDO'!O40 -> 46358 | F17: =+'LIRA ARCEO JOEL EDUARDO'!O41 -> 0 | G17: =+'LIRA ARCEO JOEL EDUARDO'!O42 -> 0 | H17: =+'LIRA ARCEO JOEL EDUARDO'!O43 -> 0 | I17: =+'LIRA ARCEO JOEL EDUARDO'!O44 -> 0 | J17: =+'LIRA ARCEO JOEL EDUARDO'!O45 -> 0 | K17: =+'LIRA ARCEO JOEL EDUARDO'!O46 -> 0
B18: 1133 | C18: MACHADO MAZUCA ADOLFO | D18: =+'MACHADO MAZUCA ADOLFO'!Q37 -> 4905.4381 | E18: =+'MACHADO MAZUCA ADOLFO'!O40 -> 45905 | F18: =+'MACHADO MAZUCA ADOLFO'!O41 -> 45924 | G18: =+'MACHADO MAZUCA ADOLFO'!O42 -> 45950 | H18: =+'MACHADO MAZUCA ADOLFO'!O43 -> 0 | I18: =+'MACHADO MAZUCA ADOLFO'!O44 -> 0 | J18: =+'MACHADO MAZUCA ADOLFO'!O45 -> 0 | K18: =+'MACHADO MAZUCA ADOLFO'!O46 -> 0
B19: 2319 | C19: MARTINEZ RAMIREZ ROSALIO | D19: =+'MARTINEZ RAMIREZ ROSALIO'!Q37 -> 4966.2125 | E19: =+'MARTINEZ RAMIREZ ROSALIO'!O40 -> 45908 | F19: =+'MARTINEZ RAMIREZ ROSALIO'!O41 -> 45948 | G19: =+'MARTINEZ RAMIREZ ROSALIO'!O42 -> 45960 | H19: =+'MARTINEZ RAMIREZ ROSALIO'!O43 -> 0 | I19: =+'MARTINEZ RAMIREZ ROSALIO'!O44 -> 0 | J19: =+'MARTINEZ RAMIREZ ROSALIO'!O45 -> 0 | K19: =+'MARTINEZ RAMIREZ ROSALIO'!O46 -> 0
B20: 2549 | C20: MELENDEZ SINALOA MANUEL ARAT | D20: =+'MELENDEZ SINALOA MANUEL ARAT'!Q37 -> 6162.6723 | E20: =+'MELENDEZ SINALOA MANUEL ARAT'!O40 -> 46384 | F20: =+'MELENDEZ SINALOA MANUEL ARAT'!O41 -> 45918 | G20: =+'MELENDEZ SINALOA MANUEL ARAT'!O42 -> 45930 | H20: =+'MELENDEZ SINALOA MANUEL ARAT'!O43 -> 45961 | I20: =+'MELENDEZ SINALOA MANUEL ARAT'!O44 -> 0 | J20: =+'MELENDEZ SINALOA MANUEL ARAT'!O45 -> 0 | K20: =+'MELENDEZ SINALOA MANUEL ARAT'!O46 -> 0
B21: 1089 | C21: MERCADO LOPEZ JESUS | D21: =+'MERCADO LOPEZ JESUS'!Q37 -> #N/A | E21: =+'MERCADO LOPEZ JESUS'!O40 -> 0 | F21: =+'MERCADO LOPEZ JESUS'!O41 -> 0 | G21: =+'MERCADO LOPEZ JESUS'!O42 -> 0 | H21: =+'MERCADO LOPEZ JESUS'!O43 -> 0 | I21: =+'MERCADO LOPEZ JESUS'!O44 -> 0 | J21: =+'MERCADO LOPEZ JESUS'!O45 -> 0
B22: 1047 | C22: MONTERO BURROLA LUIS LEOBARDO | D22: =+'MONTERO BURROLA LUIS'!Q35 -> 16970.18 | E22: =+'MONTERO BURROLA LUIS'!O38 -> 46393 | F22: =+'MONTERO BURROLA LUIS'!O39 -> 45911 | G22: =+'MONTERO BURROLA LUIS'!O40 -> 45945 | H22: =+'MONTERO BURROLA LUIS'!O41 -> 45953 | I22: =+'MONTERO BURROLA LUIS'!O42 -> 45982 | J22: =+'MONTERO BURROLA LUIS'!O43 -> 0 | K22: =+'MONTERO BURROLA LUIS'!O44 -> 0
B23: 0176 | C23: MORALES LOPEZ DE LARA MARIANO | D23: =+'MORALES LOPEZ DE LARA MARIANO'!Q37 -> #N/A | E23: =+'MORALES LOPEZ DE LARA MARIANO'!O40 -> 0 | F23: =+'MORALES LOPEZ DE LARA MARIANO'!O41 -> 0 | G23: =+'MORALES LOPEZ DE LARA MARIANO'!O42 -> 0 | H23: =+'MORALES LOPEZ DE LARA MARIANO'!O43 -> 0 | I23: =+'MORALES LOPEZ DE LARA MARIANO'!O44 -> 0 | J23: =+'MORALES LOPEZ DE LARA MARIANO'!O45 -> 0
B24: 0178 | C24: NUÑEZ RUIZ IRVING JAVIER | D24: =+'NUÑEZ RUIZ IRVING JAVIER.'!Q38 -> 6280.166 | E24: =+'NUÑEZ RUIZ IRVING JAVIER.'!O42 -> 46360 | F24: =+'NUÑEZ RUIZ IRVING JAVIER.'!O43 -> 45922 | G24: =+'NUÑEZ RUIZ IRVING JAVIER.'!O44 -> 45934 | H24: =+'NUÑEZ RUIZ IRVING JAVIER.'!O45 -> 45966 | I24: =+'NUÑEZ RUIZ IRVING JAVIER.'!O46 -> 0 | J24: =+'NUÑEZ RUIZ IRVING JAVIER.'!O47 -> 0 | K24: =+'NUÑEZ RUIZ IRVING JAVIER.'!O48 -> 0
B25: 2590 | C25: ONTIVEROS LIRA JUAN | D25: =+'ONTIVEROS LIRA JUAN'!Q37 -> 6540.2785 | E25: =+'ONTIVEROS LIRA JUAN'!O40 -> 45903 | F25: =+'ONTIVEROS LIRA JUAN'!O41 -> 45915 | G25: =+'ONTIVEROS LIRA JUAN'!O42 -> 0 | H25: =+'ONTIVEROS LIRA JUAN'!O43 -> 0 | I25: =+'ONTIVEROS LIRA JUAN'!O44 -> 0 | J25: =+'ONTIVEROS LIRA JUAN'!O45 -> 0
B26: 194 | C26: ORONA BECERRA MAURO JOSE | D26: =+'ORONA BECERRA MAURO JOSE'!Q37 -> 4160.5009 | E26: =+'ORONA BECERRA MAURO JOSE'!O40 -> 45936 | F26: =+'ORONA BECERRA MAURO JOSE'!O41 -> 45987 | G26: =+'ORONA BECERRA MAURO JOSE'!O42 -> 0 | H26: =+'ORONA BECERRA MAURO JOSE'!O43 -> 0 | I26: =+'ORONA BECERRA MAURO JOSE'!O44 -> 0 | J26: =+'ORONA BECERRA MAURO JOSE'!O45 -> 0 | K26: =+'ORONA BECERRA MAURO JOSE'!O46 -> 0
B27: 2616 | C27: ORTIZ RAMIREZ HECTOR MANUEL | D27: =+'ORTIZ RAMIREZ HECTOR MANUEL'!Q37 -> 4579.2184 | E27: =+'ORTIZ RAMIREZ HECTOR MANUEL'!O40 -> 46390 | F27: =+'ORTIZ RAMIREZ HECTOR MANUEL'!O41 -> 0 | G27: =+'ORTIZ RAMIREZ HECTOR MANUEL'!O42 -> 0 | H27: =+'ORTIZ RAMIREZ HECTOR MANUEL'!O43 -> 0 | I27: =+'ORTIZ RAMIREZ HECTOR MANUEL'!O44 -> 0 | J27: =+'ORTIZ RAMIREZ HECTOR MANUEL'!O45 -> 0 | K27: =+'ORTIZ RAMIREZ HECTOR MANUEL'!O46 -> 0
B28: 2018 | C28: RAMIREZ BAUTISTA ADRIAN | D28: =+'RAMIREZ BAUTISTA ADRIAN'!Q37 -> 7964.8636 | E28: =+'RAMIREZ BAUTISTA ADRIAN'!O40 -> 46387 | F28: =+'RAMIREZ BAUTISTA ADRIAN'!O41 -> 45921 | G28: =+'RAMIREZ BAUTISTA ADRIAN'!O42 -> 45933 | H28: =+'RAMIREZ BAUTISTA ADRIAN'!O43 -> 45965 | I28: =+'RAMIREZ BAUTISTA ADRIAN'!O44 -> 0 | J28: =+'RAMIREZ BAUTISTA ADRIAN'!O45 -> 0
B29: 2046 | C29: REYES LARA DANTE | D29: =+'REYES LARA DANTE'!Q37 -> 3529.4271 | E29: =+'REYES LARA DANTE'!O40 -> 46385 | F29: =+'REYES LARA DANTE'!O41 -> 45935 | G29: =+'REYES LARA DANTE'!O42 -> 0 | H29: =+'REYES LARA DANTE'!O43 -> 0 | I29: =+'REYES LARA DANTE'!O44 -> 0 | J29: =+'REYES LARA DANTE'!O45 -> 0 | K29: =+'REYES LARA DANTE'!O46 -> 0
C30: RODRIGUEZ FLORES BRYAN DARIO | D30: =+'RODRIGUEZ FLORES BRYAN DARIO'!Q37 -> 4239.3923 | E30: =+'RODRIGUEZ FLORES BRYAN DARIO'!O40 -> 45906 | F30: =+'RODRIGUEZ FLORES BRYAN DARIO'!O41 -> 45925 | G30: =+'RODRIGUEZ FLORES BRYAN DARIO'!O42 -> 45959 | H30: =+'RODRIGUEZ FLORES BRYAN DARIO'!O43 -> 0 | I30: =+'RODRIGUEZ FLORES BRYAN DARIO'!O44 -> 0 | J30: =+'RODRIGUEZ FLORES BRYAN DARIO'!O45 -> 0 | K30: =+'RODRIGUEZ FLORES BRYAN DARIO'!O46 -> 0
B31: 2546 | C31: RUIZ SAUCEDO DANIEL ALEJANDRO | D31: =+'RUIZ SAUCEDO DANIEL ALEJANDRO'!Q37 -> #N/A | E31: =+'RUIZ SAUCEDO DANIEL ALEJANDRO'!O40 -> 0 | F31: =+'RUIZ SAUCEDO DANIEL ALEJANDRO'!O41 -> 0 | G31: =+'RUIZ SAUCEDO DANIEL ALEJANDRO'!O42 -> 0 | H31: =+'RUIZ SAUCEDO DANIEL ALEJANDRO'!O43 -> 0 | I31: =+'RUIZ SAUCEDO DANIEL ALEJANDRO'!O44 -> 0 | J31: =+'RUIZ SAUCEDO DANIEL ALEJANDRO'!O45 -> 0
B32: 0273 | C32: VALLES HERNANDEZ MANUEL MARCELINO | D32: =+'VALLES HERNANDEZ MANUEL MARCELI'!Q36 -> 9784.7051 | E32: =+'VALLES HERNANDEZ MANUEL MARCELI'!O39 -> 45904 | F32: =+'VALLES HERNANDEZ MANUEL MARCELI'!O40 -> 45914 | G32: =+'VALLES HERNANDEZ MANUEL MARCELI'!O41 -> 45947 | H32: =+'VALLES HERNANDEZ MANUEL MARCELI'!O42 -> 45954 | I32: =+'VALLES HERNANDEZ MANUEL MARCELI'!O43 -> 0 | J32: =+'VALLES HERNANDEZ MANUEL MARCELI'!O44 -> 0
C33: TOTAL | D33: =SUM(D5:D32) -> #N/A
D34: =SUM(D16:D18,D20,D26:D29+D23+D24)+D14+D12+D11+D10+D9+D7+D6+D5 -> #VALUE!
D35: =+D32+D29+D28+D27+D26+D24+D23+D20+D18+D17+D16+D14+D12+D11+D10+D9+D7+D6+D5 -> #N/A
D37: =+D31+D30+D28+D24+D23+D20+D18+D16+D13+D11+D6 -> #N/A

Sheet AGUILAR ESQUIVEL CARLOS
Q2: SEMANA:
I3: FLETES SOTELO S.A DE C.V | Q3: 42
I4: RFC: FSO880915JP8
I5: CAMINO DE LOS ESTEROS 720 | Q5: FOLIO DE LIQUIDACION
I6: PARTIDO DOBALDO CD.JUAREZ CHIHU. | Q6: 25
I9: INFORMACION DEL OPERADOR
D11: OPERADOR: | E11: AGUILAR ESQUIVEL CARLOS | K11: FECHA DE PERIODO: | L11: =+NOMINA!B3 -> SEMANA #42 PERIODO DEL 06 AL 12 DE OCTUBRE DEL 2025
D12: UNIDAD: | E12: F-021
D14: ODOM.INIC: | F14: 157771 | I14: COMBUSTIBLE INICI: | O14: COMBUSTIBLE CARGADO:
D15: ODOM.FINAL: | F15: 158520 | I15: COMBUSTIBLE FIN: | O15: DIF. DE DIESEL:
D16: KM RECORRIDOS: | F16: =SUM(J19:J32) -> 3160 | I16: DIESEL CONSUMIDO: | J16: =SUM(K19:K32) -> 878.661 | O16: RENDIMIENTO: | P16: =+F16/J16 -> 3.5963813
C18: FOLIO LIQUIDACION | D18: CORDENADA | E18: FECHA SALIDA | F18: FECHA LLEGADA | G18: R: | H18: ORIGEN | I18: DESTINO | J18: KMS | K18: RECARGA | L18: RENDIMIENTO | M18: PESO DE CARGA (kg) | N18: C / V / PT | O18: REMOLQUE | P18: CLIENTE | Q18: PAGO POR KM | R18: RENDIMIENTO PAGO | S18: LITROS A PAGO | T18: DIESEL A FAVOR | U18: SALIDA | V18: REGRESO
C19: 45901 | D19: 2874140-4 | E19: 45937 | F19: 45938 | G19: 4 | H19: =IF(G19=1,KILOMETRAJE!C$4,IF(G19=2,KILOMETRAJE!C$5,IF(G19=3,KILOMETRAJE!C$6,IF(G19=4,KILOMETRAJE!C$7,IF(G19=5,KILOMETRAJE!C$8,IF(G19=6,KILOMETRAJE!C$9,IF(G19=7,KILOMETRAJE!C$10,IF(G19=8,KILOMETRAJE!C$11,IF(G19=9,KILOMETRAJE!C$12,IF(G19=10,KILOMETRAJE!C$13,IF(G19=11,KILOMETRAJE!C$14,IF(G19=12,KILOMETRAJE!C$15,IF(G19=13,KILOMETRAJE!C$16,IF(G19=14,KILOMETRAJE!C$17,IF(G19=15,KILOMETRAJE!C$18,IF(G19=16,KILOMETRAJE!C$19,IF(G19=17,KILOMETRAJE!C$20,IF(G19=18,KILOMETRAJE!C$21,IF(G19=19,KILOMETRAJE!C$22,IF(G19=20,KILOMETRAJE!C$23,IF(G19=21,KILOMETRAJE!C$24,IF(G19=22,KILOMETRAJE!C$25,IF(G19=23,KILOMETRAJE!C$26,IF(G19=24,KILOMETRAJE!C$27,IF(G19=25,KILOMETRAJE!C$28,IF(G19=26,KILOMETRAJE!C$29,IF(G19=27,KILOMETRAJE!C$30,IF(G19=28,KILOMETRAJE!C$31,IF(G19=29,KILOMETRAJE!C$32,IF(G19=30,KILOMETRAJE!C$33,IF(G19=31,KILOMETRAJE!C$34,IF(G19=32,KILOMETRAJE!C$35,IF(G19=33,KILOMETRAJE!C$36,IF(G19=34,KILOMETRAJE!C$37,IF(G19=35,KILOMETRAJE!C$38,IF(G19=36,KILOMETRAJE!C$39,IF(G19=37,KILOMETRAJE!C$40,IF(G19=38,KILOMETRAJE!C$41,IF(G19=39,KILOMETRAJE!C$42,IF(G19=40,KILOMETRAJE!C$43,IF(G19=41,KILOMETRAJE!C$44,IF(G19=42,KILOMETRAJE!C$45,IF(G19=43,KILOMETRAJE!C$46,IF(G19=44,KILOMETRAJE!C$47,IF(G19=45,KILOMETRAJE!C$48,IF(G19=46,KILOMETRAJE!C$49,IF(G19=47,KILOMETRAJE!C$50,IF(G19=48,KILOMETRAJE!C$51,IF(G19=49,KILOMETRAJE!C$52,IF(G19=50,KILOMETRAJE!C$53,IF(G19=51,KILOMETRAJE!C$54,IF(G19=52,KILOMETRAJE!C$55,IF(G19=53,KILOMETRAJE!C$56,IF(G19=54,KILOMETRAJE!C$57,IF(G19=55,KILOMETRAJE!C$58,IF(G19=56,KILOMETRAJE!C$59,IF(G19=57,KILOMETRAJE!C$60,IF(G19=58,KILOMETRAJE!C$61,IF(G19=59,KILOMETRAJE!C$62,IF(G19=60,KILOMETRAJE!C$63,IF(G19=61,KILOMETRAJE!C$64,IF(G19=62,KILOMETRAJE!C$65,IF(G19=63,KILOMETRAJE!C$66))))))))))))))))))))))))))))))))))))))))))))))))))))))))))))))) -> ELP. | I19: =IF(G19=1,KILOMETRAJE!E$4,IF(G19=2,KILOMETRAJE!E$5,IF(G19=3,KILOMETRAJE!E$6,IF(G19=4,KILOMETRAJE!E$7,IF(G19=5,KILOMETRAJE!E$8,IF(G19=6,KILOMETRAJE!E$9,IF(G19=7,KILOMETRAJE!E$10,IF(G19=8,KILOMETRAJE!E$11,IF(G19=9,KILOMETRAJE!E$12,IF(G19=10,KILOMETRAJE!E$13,IF(G19=11,KILOMETRAJE!E$14,IF(G19=12,KILOMETRAJE!E$15,IF(G19=13,KILOMETRAJE!E$16,IF(G19=14,KILOMETRAJE!E$17,IF(G19=15,KILOMETRAJE!E$18,IF(G19=16,KILOMETRAJE!E$19,IF(G19=17,KILOMETRAJE!E$20,IF(G19=18,KILOMETRAJE!E$21,IF(G19=19,KILOMETRAJE!E$22,IF(G19=20,KILOMETRAJE!E$23,IF(G19=21,KILOMETRAJE!E$24,IF(G19=22,KILOMETRAJE!E$25,IF(G19=23,KILOMETRAJE!E$26,IF(G19=24,KILOMETRAJE!E$27,IF(G19=25,KILOMETRAJE!E$28,IF(G19=26,KILOMETRAJE!E$29,IF(G19=27,KILOMETRAJE!E$30,IF(G19=28,KILOMETRAJE!E$31,IF(G19=29,KILOMETRAJE!E$32,IF(G19=30,KILOMETRAJE!E$33,IF(G19=31,KILOMETRAJE!E$34,IF(G19=32,KILOMETRAJE!E$35,IF(G19=33,KILOMETRAJE!E$36,IF(G19=34,KILOMETRAJE!E$37,IF(G19=35,KILOMETRAJE!E$38,IF(G19=36,KILOMETRAJE!E$39,IF(G19=37,KILOMETRAJE!E$40,IF(G19=38,KILOMETRAJE!E$41,IF(G19=39,KILOMETRAJE!E$42,IF(G19=40,KILOMETRAJE!E$43,IF(G19=41,KILOMETRAJE!E$44,IF(G19=42,KILOMETRAJE!E$45,IF(G19=43,KILOMETRAJE!E$46,IF(G19=44,KILOMETRAJE!E$47,IF(G19=45,KILOMETRAJE!E$48,IF(G19=46,KILOMETRAJE!E$49,IF(G19=47,KILOMETRAJE!E$50,IF(G19=48,KILOMETRAJE!E$51,IF(G19=49,KILOMETRAJE!E$52,IF(G19=50,KILOMETRAJE!E$53,IF(G19=51,KILOMETRAJE!E$54,IF(G19=52,KILOMETRAJE!E$55,IF(G19=53,KILOMETRAJE!E$56,IF(G19=54,KILOMETRAJE!E$57,IF(G19=55,KILOMETRAJE!E$58,IF(G19=56,KILOMETRAJE!E$59,IF(G19=57,KILOMETRAJE!E$60,IF(G19=58,KILOMETRAJE!E$61,IF(G19=59,KILOMETRAJE!E$62,IF(G19=60,KILOMETRAJE!E$63,IF(G19=61,KILOMETRAJE!E$64,IF(G19=62,KILOMETRAJE!E$65,IF(G19=63,KILOMETRAJE!E$66))))))))))))))))))))))))))))))))))))))))))))))))))))))))))))))) -> CHIH. | J19: =IF(G19=1,KILOMETRAJE!G$4,IF(G19=2,KILOMETRAJE!G$5,IF(G19=3,KILOMETRAJE!G$6,IF(G19=4,KILOMETRAJE!G$7,IF(G19=5,KILOMETRAJE!G$8,IF(G19=6,KILOMETRAJE!G$9,IF(G19=7,KILOMETRAJE!G$10,IF(G19=8,KILOMETRAJE!G$11,IF(G19=9,KILOMETRAJE!G$12,IF(G19=10,KILOMETRAJE!G$13,IF(G19=11,KILOMETRAJE!G$14,IF(G19=12,KILOMETRAJE!G$15,IF(G19=13,KILOMETRAJE!G$16,IF(G19=14,KILOMETRAJE!G$17,IF(G19=15,KILOMETRAJE!G$18,IF(G19=16,KILOMETRAJE!G$19,IF(G19=17,KILOMETRAJE!G$20,IF(G19=18,KILOMETRAJE!G$21,IF(G19=19,KILOMETRAJE!G$22,IF(G19=20,KILOMETRAJE!G$23,IF(G19=21,KILOMETRAJE!G$24,IF(G19=22,KILOMETRAJE!G$25,IF(G19=23,KILOMETRAJE!G$26,IF(G19=24,KILOMETRAJE!G$27,IF(G19=25,KILOMETRAJE!G$28,IF(G19=26,KILOMETRAJE!G$29,IF(G19=27,KILOMETRAJE!G$30,IF(G19=28,KILOMETRAJE!G$31,IF(G19=29,KILOMETRAJE!G$32,IF(G19=30,KILOMETRAJE!G$33,IF(G19=31,KILOMETRAJE!G$34,IF(G19=32,KILOMETRAJE!G$35,IF(G19=33,KILOMETRAJE!G$36,IF(G19=34,KILOMETRAJE!G$37,IF(G19=35,KILOMETRAJE!G$38,IF(G19=36,KILOMETRAJE!G$39,IF(G19=37,KILOMETRAJE!G$40,IF(G19=38,KILOMETRAJE!G$41,IF(G19=39,KILOMETRAJE!G$42,IF(G19=40,KILOMETRAJE!G$43,IF(G19=41,KILOMETRAJE!G$44,IF(G19=42,KILOMETRAJE!G$45,IF(G19=43,KILOMETRAJE!G$46,IF(G19=44,KILOMETRAJE!G$47,IF(G19=45,KILOMETRAJE!G$48,IF(G19=46,KILOMETRAJE!G$49,IF(G19=47,KILOMETRAJE!G$50,IF(G19=48,KILOMETRAJE!G$51,IF(G19=49,KILOMETRAJE!G$52,IF(G19=50,KILOMETRAJE!G$53,IF(G19=51,KILOMETRAJE!G$54,IF(G19=52,KILOMETRAJE!G$55,IF(G19=53,KILOMETRAJE!G$56,IF(G19=54,KILOMETRAJE!G$57,IF(G19=55,KILOMETRAJE!G$58,IF(G19=56,KILOMETRAJE!G$59,IF(G19=57,KILOMETRAJE!G$60,IF(G19=58,KILOMETRAJE!G$61,IF(G19=59,KILOMETRAJE!G$62,IF(G19=60,KILOMETRAJE!G$63,IF(G19=61,KILOMETRAJE!G$64,IF(G19=62,KILOMETRAJE!G$65,IF(G19=63,KILOMETRAJE!G$66))))))))))))))))))))))))))))))))))))))))))))))))))))))))))))))) -> 415 | M19: 255.05 | N19: 4 | O19: BS35030 | P19: G. AMERICAN | Q19: =((((IF(N19=1,((J19)*0.29333)))+(IF(N19=2,((J19)*0.146666)))+(IF(N19=3,((J19)*0.146666)))))+(IF(N19=4,((J19-40)*0.29333)))+(IF(N19=5,((J19-50)*0.29333)))+(IF(N19=6,((J19-90)*0.29333)))) -> 109.99875 | U19: NA | V19: NA
D20: 2874276-2 | E20: 45938 | F20: 45938 | G20: 3 | H20: =IF(G20=1,KILOMETRAJE!C$4,IF(G20=2,KILOMETRAJE!C$5,IF(G20=3,KILOMETRAJE!C$6,IF(G20=4,KILOMETRAJE!C$7,IF(G20=5,KILOMETRAJE!C$8,IF(G20=6,KILOMETRAJE!C$9,IF(G20=7,KILOMETRAJE!C$10,IF(G20=8,KILOMETRAJE!C$11,IF(G20=9,KILOMETRAJE!C$12,IF(G20=10,KILOMETRAJE!C$13,IF(G20=11,KILOMETRAJE!C$14,IF(G20=12,KILOMETRAJE!C$15,IF(G20=13,KILOMETRAJE!C$16,IF(G20=14,KILOMETRAJE!C$17,IF(G20=15,KILOMETRAJE!C$18,IF(G20=16,KILOMETRAJE!C$19,IF(G20=17,KILOMETRAJE!C$20,IF(G20=18,KILOMETRAJE!C$21,IF(G20=19,KILOMETRAJE!C$22,IF(G20=20,KILOMETRAJE!C$23,IF(G20=21,KILOMETRAJE!C$24,IF(G20=22,KILOMETRAJE!C$25,IF(G20=23,KILOMETRAJE!C$26,IF(G20=24,KILOMETRAJE!C$27,IF(G20=25,KILOMETRAJE!C$28,IF(G20=26,KILOMETRAJE!C$29,IF(G20=27,KILOMETRAJE!C$30,IF(G20=28,KILOMETRAJE!C$31,IF(G20=29,KILOMETRAJE!C$32,IF(G20=30,KILOMETRAJE!C$33,IF(G20=31,KILOMETRAJE!C$34,IF(G20=32,KILOMETRAJE!C$35,IF(G20=33,KILOMETRAJE!C$36,IF(G20=34,KILOMETRAJE!C$37,IF(G20=35,KILOMETRAJE!C$38,IF(G20=36,KILOMETRAJE!C$39,IF(G20=37,KILOMETRAJE!C$40,IF(G20=38,KILOMETRAJE!C$41,IF(G20=39,KILOMETRAJE!C$42,IF(G20=40,KILOMETRAJE!C$43,IF(G20=41,KILOMETRAJE!C$44,IF(G20=42,KILOMETRAJE!C$45,IF(G20=43,KILOMETRAJE!C$46,IF(G20=44,KILOMETRAJE!C$47,IF(G20=45,KILOMETRAJE!C$48,IF(G20=46,KILOMETRAJE!C$49,IF(G20=47,KILOMETRAJE!C$50,IF(G20=48,KILOMETRAJE!C$51,IF(G20=49,KILOMETRAJE!C$52,IF(G20=50,KILOMETRAJE!C$53,IF(G20=51,KILOMETRAJE!C$54,IF(G20=52,KILOMETRAJE!C$55,IF(G20=53,KILOMETRAJE!C$56,IF(G20=54,KILOMETRAJE!C$57,IF(G20=55,KILOMETRAJE!C$58,IF(G20=56,KILOMETRAJE!C$59,IF(G20=57,KILOMETRAJE!C$60,IF(G20=58,KILOMETRAJE!C$61,IF(G20=59,KILOMETRAJE!C$62,IF(G20=60,KILOMETRAJE!C$63,IF(G20=61,KILOMETRAJE!C$64,IF(G20=62,KILOMETRAJE!C$65,IF(G20=63,KILOMETRAJE!C$66))))))))))))))))))))))))))))))))))))))))))))))))))))))))))))))) -> CHIH. | I20: =IF(G20=1,KILOMETRAJE!E$4,IF(G20=2,KILOMETRAJE!E$5,IF(G20=3,KILOMETRAJE!E$6,IF(G20=4,KILOMETRAJE!E$7,IF(G20=5,KILOMETRAJE!E$8,IF(G20=6,KILOMETRAJE!E$9,IF(G20=7,KILOMETRAJE!E$10,IF(G20=8,KILOMETRAJE!E$11,IF(G20=9,KILOMETRAJE!E$12,IF(G20=10,KILOMETRAJE!E$13,IF(G20=11,KILOMETRAJE!E$14,IF(G20=12,KILOMETRAJE!E$15,IF(G20=13,KILOMETRAJE!E$16,IF(G20=14,KILOMETRAJE!E$17,IF(G20=15,KILOMETRAJE!E$18,IF(G20=16,KILOMETRAJE!E$19,IF(G20=17,KILOMETRAJE!E$20,IF(G20=18,KILOMETRAJE!E$21,IF(G20=19,KILOMETRAJE!E$22,IF(G20=20,KILOMETRAJE!E$23,IF(G20=21,KILOMETRAJE!E$24,IF(G20=22,KILOMETRAJE!E$25,IF(G20=23,KILOMETRAJE!E$26,IF(G20=24,KILOMETRAJE!E$27,IF(G20=25,KILOMETRAJE!E$28,IF(G20=26,KILOMETRAJE!E$29,IF(G20=27,KILOMETRAJE!E$30,IF(G20=28,KILOMETRAJE!E$31,IF(G20=29,KILOMETRAJE!E$32,IF(G20=30,KILOMETRAJE!E$33,IF(G20=31,KILOMETRAJE!E$34,IF(G20=32,KILOMETRAJE!E$35,IF(G20=33,KILOMETRAJE!E$36,IF(G20=34,KILOMETRAJE!E$37,IF(G20=35,KILOMETRAJE!E$38,IF(G20=36,KILOMETRAJE!E$39,IF(G20=37,KILOMETRAJE!E$40,IF(G20=38,KILOMETRAJE!E$41,IF(G20=39,KILOMETRAJE!E$42,IF(G20=40,KILOMETRAJE!E$43,IF(G20=41,KILOMETRAJE!E$44,IF(G20=42,KILOMETRAJE!E$45,IF(G20=43,KILOMETRAJE!E$46,IF(G20=44,KILOMETRAJE!E$47,IF(G20=45,KILOMETRAJE!E$48,IF(G20=46,KILOMETRAJE!E$49,IF(G20=47,KILOMETRAJE!E$50,IF(G20=48,KILOMETRAJE!E$51,IF(G20=49,KILOMETRAJE!E$52,IF(G20=50,KILOMETRAJE!E$53,IF(G20=51,KILOMETRAJE!E$54,IF(G20=52,KILOMETRAJE!E$55,IF(G20=53,KILOMETRAJE!E$56,IF(G20=54,KILOMETRAJE!E$57,IF(G20=55,KILOMETRAJE!E$58,IF(G20=56,KILOMETRAJE!E$59,IF(G20=57,KILOMETRAJE!E$60,IF(G20=58,KILOMETRAJE!E$61,IF(G20=59,KILOMETRAJE!E$62,IF(G20=60,KILOMETRAJE!E$63,IF(G20=61,KILOMETRAJE!E$64,IF(G20=62,KILOMETRAJE!E$65,IF(G20=63,KILOMETRAJE!E$66))))))))))))))))))))))))))))))))))))))))))))))))))))))))))))))) -> JRZ | J20: =IF(G20=1,KILOMETRAJE!G$4,IF(G20=2,KILOMETRAJE!G$5,IF(G20=3,KILOMETRAJE!G$6,IF(G20=4,KILOMETRAJE!G$7,IF(G20=5,KILOMETRAJE!G$8,IF(G20=6,KILOMETRAJE!G$9,IF(G20=7,KILOMETRAJE!G$10,IF(G20=8,KILOMETRAJE!G$11,IF(G20=9,KILOMETRAJE!G$12,IF(G20=10,KILOMETRAJE!G$13,IF(G20=11,KILOMETRAJE!G$14,IF(G20=12,KILOMETRAJE!G$15,IF(G20=13,KILOMETRAJE!G$16,IF(G20=14,KILOMETRAJE!G$17,IF(G20=15,KILOMETRAJE!G$18,IF(G20=16,KILOMETRAJE!G$19,IF(G20=17,KILOMETRAJE!G$20,IF(G20=18,KILOMETRAJE!G$21,IF(G20=19,KILOMETRAJE!G$22,IF(G20=20,KILOMETRAJE!G$23,IF(G20=21,KILOMETRAJE!G$24,IF(G20=22,KILOMETRAJE!G$25,IF(G20=23,KILOMETRAJE!G$26,IF(G20=24,KILOMETRAJE!G$27,IF(G20=25,KILOMETRAJE!G$28,IF(G20=26,KILOMETRAJE!G$29,IF(G20=27,KILOMETRAJE!G$30,IF(G20=28,KILOMETRAJE!G$31,IF(G20=29,KILOMETRAJE!G$32,IF(G20=30,KILOMETRAJE!G$33,IF(G20=31,KILOMETRAJE!G$34,IF(G20=32,KILOMETRAJE!G$35,IF(G20=33,KILOMETRAJE!G$36,IF(G20=34,KILOMETRAJE!G$37,IF(G20=35,KILOMETRAJE!G$38,IF(G20=36,KILOMETRAJE!G$39,IF(G20=37,KILOMETRAJE!G$40,IF(G20=38,KILOMETRAJE!G$41,IF(G20=39,KILOMETRAJE!G$42,IF(G20=40,KILOMETRAJE!G$43,IF(G20=41,KILOMETRAJE!G$44,IF(G20=42,KILOMETRAJE!G$45,IF(G20=43,KILOMETRAJE!G$46,IF(G20=44,KILOMETRAJE!G$47,IF(G20=45,KILOMETRAJE!G$48,IF(G20=46,KILOMETRAJE!G$49,IF(G20=47,KILOMETRAJE!G$50,IF(G20=48,KILOMETRAJE!G$51,IF(G20=49,KILOMETRAJE!G$52,IF(G20=50,KILOMETRAJE!G$53,IF(G20=51,KILOMETRAJE!G$54,IF(G20=52,KILOMETRAJE!G$55,IF(G20=53,KILOMETRAJE!G$56,IF(G20=54,KILOMETRAJE!G$57,IF(G20=55,KILOMETRAJE!G$58,IF(G20=56,KILOMETRAJE!G$59,IF(G20=57,KILOMETRAJE!G$60,IF(G20=58,KILOMETRAJE!G$61,IF(G20=59,KILOMETRAJE!G$62,IF(G20=60,KILOMETRAJE!G$63,IF(G20=61,KILOMETRAJE!G$64,IF(G20=62,KILOMETRAJE!G$65,IF(G20=63,KILOMETRAJE!G$66))))))))))))))))))))))))))))))))))))))))))))))))))))))))))))))) -> 375 | K20: 222.026 | L20: =SUM(J19:J20)/K20 -> 3.5581418 | M20: 4177.73 | N20: 1 | O20: BS35096 | P20: XYLEM | Q20: =((((IF(N20=1,((J20)*0.29333)))+(IF(N20=2,((J20)*0.146666)))+(IF(N20=3,((J20)*0.146666)))))+(IF(N20=4,((J20-40)*0.29333)))+(IF(N20=5,((J20-50)*0.29333)))+(IF(N20=6,((J20-90)*0.29333)))) -> 109.99875 | R20: =+LOOKUP(P40,UNIDADES!B$3:B$59,UNIDADES!C$3:C$59) -> 2.45098 | S20: =+((SUM(J19:J20)-40)/R20)-K20 -> 83.974049 | T20: =+S20*14.85 -> 1247.0146 | U20: 57 | V20: 60
C21: 45913 | D21: 2874315-2 | E21: 45938 | F21: 45939 | G21: 4 | H21: =IF(G21=1,KILOMETRAJE!C$4,IF(G21=2,KILOMETRAJE!C$5,IF(G21=3,KILOMETRAJE!C$6,IF(G21=4,KILOMETRAJE!C$7,IF(G21=5,KILOMETRAJE!C$8,IF(G21=6,KILOMETRAJE!C$9,IF(G21=7,KILOMETRAJE!C$10,IF(G21=8,KILOMETRAJE!C$11,IF(G21=9,KILOMETRAJE!C$12,IF(G21=10,KILOMETRAJE!C$13,IF(G21=11,KILOMETRAJE!C$14,IF(G21=12,KILOMETRAJE!C$15,IF(G21=13,KILOMETRAJE!C$16,IF(G21=14,KILOMETRAJE!C$17,IF(G21=15,KILOMETRAJE!C$18,IF(G21=16,KILOMETRAJE!C$19,IF(G21=17,KILOMETRAJE!C$20,IF(G21=18,KILOMETRAJE!C$21,IF(G21=19,KILOMETRAJE!C$22,IF(G21=20,KILOMETRAJE!C$23,IF(G21=21,KILOMETRAJE!C$24,IF(G21=22,KILOMETRAJE!C$25,IF(G21=23,KILOMETRAJE!C$26,IF(G21=24,KILOMETRAJE!C$27,IF(G21=25,KILOMETRAJE!C$28,IF(G21=26,KILOMETRAJE!C$29,IF(G21=27,KILOMETRAJE!C$30,IF(G21=28,KILOMETRAJE!C$31,IF(G21=29,KILOMETRAJE!C$32,IF(G21=30,KILOMETRAJE!C$33,IF(G21=31,KILOMETRAJE!C$34,IF(G21=32,KILOMETRAJE!C$35,IF(G21=33,KILOMETRAJE!C$36,IF(G21=34,KILOMETRAJE!C$37,IF(G21=35,KILOMETRAJE!C$38,IF(G21=36,KILOMETRAJE!C$39,IF(G21=37,KILOMETRAJE!C$40,IF(G21=38,KILOMETRAJE!C$41,IF(G21=39,KILOMETRAJE!C$42,IF(G21=40,KILOMETRAJE!C$43,IF(G21=41,KILOMETRAJE!C$44,IF(G21=42,KILOMETRAJE!C$45,IF(G21=43,KILOMETRAJE!C$46,IF(G21=44,KILOMETRAJE!C$47,IF(G21=45,KILOMETRAJE!C$48,IF(G21=46,KILOMETRAJE!C$49,IF(G21=47,KILOMETRAJE!C$50,IF(G21=48,KILOMETRAJE!C$51,IF(G21=49,KILOMETRAJE!C$52,IF(G21=50,KILOMETRAJE!C$53,IF(G21=51,KILOMETRAJE!C$54,IF(G21=52,KILOMETRAJE!C$55,IF(G21=53,KILOMETRAJE!C$56,IF(G21=54,KILOMETRAJE!C$57,IF(G21=55,KILOMETRAJE!C$58,IF(G21=56,KILOMETRAJE!C$59,IF(G21=57,KILOMETRAJE!C$60,IF(G21=58,KILOMETRAJE!C$61,IF(G21=59,KILOMETRAJE!C$62,IF(G21=60,KILOMETRAJE!C$63,IF(G21=61,KILOMETRAJE!C$64,IF(G21=62,KILOMETRAJE!C$65,IF(G21=63,KILOMETRAJE!C$66))))))))))))))))))))))))))))))))))))))))))))))))))))))))))))))) -> ELP. | I21: =IF(G21=1,KILOMETRAJE!E$4,IF(G21=2,KILOMETRAJE!E$5,IF(G21=3,KILOMETRAJE!E$6,IF(G21=4,KILOMETRAJE!E$7,IF(G21=5,KILOMETRAJE!E$8,IF(G21=6,KILOMETRAJE!E$9,IF(G21=7,KILOMETRAJE!E$10,IF(G21=8,KILOMETRAJE!E$11,IF(G21=9,KILOMETRAJE!E$12,IF(G21=10,KILOMETRAJE!E$13,IF(G21=11,KILOMETRAJE!E$14,IF(G21=12,KILOMETRAJE!E$15,IF(G21=13,KILOMETRAJE!E$16,IF(G21=14,KILOMETRAJE!E$17,IF(G21=15,KILOMETRAJE!E$18,IF(G21=16,KILOMETRAJE!E$19,IF(G21=17,KILOMETRAJE!E$20,IF(G21=18,KILOMETRAJE!E$21,IF(G21=19,KILOMETRAJE!E$22,IF(G21=20,KILOMETRAJE!E$23,IF(G21=21,KILOMETRAJE!E$24,IF(G21=22,KILOMETRAJE!E$25,IF(G21=23,KILOMETRAJE!E$26,IF(G21=24,KILOMETRAJE!E$27,IF(G21=25,KILOMETRAJE!E$28,IF(G21=26,KILOMETRAJE!E$29,IF(G21=27,KILOMETRAJE!E$30,IF(G21=28,KILOMETRAJE!E$31,IF(G21=29,KILOMETRAJE!E$32,IF(G21=30,KILOMETRAJE!E$33,IF(G21=31,KILOMETRAJE!E$34,IF(G21=32,KILOMETRAJE!E$35,IF(G21=33,KILOMETRAJE!E$36,IF(G21=34,KILOMETRAJE!E$37,IF(G21=35,KILOMETRAJE!E$38,IF(G21=36,KILOMETRAJE!E$39,IF(G21=37,KILOMETRAJE!E$40,IF(G21=38,KILOMETRAJE!E$41,IF(G21=39,KILOMETRAJE!E$42,IF(G21=40,KILOMETRAJE!E$43,IF(G21=41,KILOMETRAJE!E$44,IF(G21=42,KILOMETRAJE!E$45,IF(G21=43,KILOMETRAJE!E$46,IF(G21=44,KILOMETRAJE!E$47,IF(G21=45,KILOMETRAJE!E$48,IF(G21=46,KILOMETRAJE!E$49,IF(G21=47,KILOMETRAJE!E$50,IF(G21=48,KILOMETRAJE!E$51,IF(G21=49,KILOMETRAJE!E$52,IF(G21=50,KILOMETRAJE!E$53,IF(G21=51,KILOMETRAJE!E$54,IF(G21=52,KILOMETRAJE!E$55,IF(G21=53,KILOMETRAJE!E$56,IF(G21=54,KILOMETRAJE!E$57,IF(G21=55,KILOMETRAJE!E$58,IF(G21=56,KILOMETRAJE!E$59,IF(G21=57,KILOMETRAJE!E$60,IF(G21=58,KILOMETRAJE!E$61,IF(G21=59,KILOMETRAJE!E$62,IF(G21=60,KILOMETRAJE!E$63,IF(G21=61,KILOMETRAJE!E$64,IF(G21=62,KILOMETRAJE!E$65,IF(G21=63,KILOMETRAJE!E$66))))))))))))))))))))))))))))))))))))))))))))))))))))))))))))))) -> CHIH. | J21: =IF(G21=1,KILOMETRAJE!G$4,IF(G21=2,KILOMETRAJE!G$5,IF(G21=3,KILOMETRAJE!G$6,IF(G21=4,KILOMETRAJE!G$7,IF(G21=5,KILOMETRAJE!G$8,IF(G21=6,KILOMETRAJE!G$9,IF(G21=7,KILOMETRAJE!G$10,IF(G21=8,KILOMETRAJE!G$11,IF(G21=9,KILOMETRAJE!G$12,IF(G21=10,KILOMETRAJE!G$13,IF(G21=11,KILOMETRAJE!G$14,IF(G21=12,KILOMETRAJE!G$15,IF(G21=13,KILOMETRAJE!G$16,IF(G21=14,KILOMETRAJE!G$17,IF(G21=15,KILOMETRAJE!G$18,IF(G21=16,KILOMETRAJE!G$19,IF(G21=17,KILOMETRAJE!G$20,IF(G21=18,KILOMETRAJE!G$21,IF(G21=19,KILOMETRAJE!G$22,IF(G21=20,KILOMETRAJE!G$23,IF(G21=21,KILOMETRAJE!G$24,IF(G21=22,KILOMETRAJE!G$25,IF(G21=23,KILOMETRAJE!G$26,IF(G21=24,KILOMETRAJE!G$27,IF(G21=25,KILOMETRAJE!G$28,IF(G21=26,KILOMETRAJE!G$29,IF(G21=27,KILOMETRAJE!G$30,IF(G21=28,KILOMETRAJE!G$31,IF(G21=29,KILOMETRAJE!G$32,IF(G21=30,KILOMETRAJE!G$33,IF(G21=31,KILOMETRAJE!G$34,IF(G21=32,KILOMETRAJE!G$35,IF(G21=33,KILOMETRAJE!G$36,IF(G21=34,KILOMETRAJE!G$37,IF(G21=35,KILOMETRAJE!G$38,IF(G21=36,KILOMETRAJE!G$39,IF(G21=37,KILOMETRAJE!G$40,IF(G21=38,KILOMETRAJE!G$41,IF(G21=39,KILOMETRAJE!G$42,IF(G21=40,KILOMETRAJE!G$43,IF(G21=41,KILOMETRAJE!G$44,IF(G21=42,KILOMETRAJE!G$45,IF(G21=43,KILOMETRAJE!G$46,IF(G21=44,KILOMETRAJE!G$47,IF(G21=45,KILOMETRAJE!G$48,IF(G21=46,KILOMETRAJE!G$49,IF(G21=47,KILOMETRAJE!G$50,IF(G21=48,KILOMETRAJE!G$51,IF(G21=49,KILOMETRAJE!G$52,IF(G21=50,KILOMETRAJE!G$53,IF(G21=51,KILOMETRAJE!G$54,IF(G21=52,KILOMETRAJE!G$55,IF(G21=53,KILOMETRAJE!G$56,IF(G21=54,KILOMETRAJE!G$57,IF(G21=55,KILOMETRAJE!G$58,IF(G21=56,KILOMETRAJE!G$59,IF(G21=57,KILOMETRAJE!G$60,IF(G21=58,KILOMETRAJE!G$61,IF(G21=59,KILOMETRAJE!G$62,IF(G21=60,KILOMETRAJE!G$63,IF(G21=61,KILOMETRAJE!G$64,IF(G21=62,KILOMETRAJE!G$65,IF(G21=63,KILOMETRAJE!G$66))))))))))))))))))))))))))))))))))))))))))))))))))))))))))))))) -> 415 | M21: 1219 | N21: 4 | O21: 53507 | P21: SAFRAN | Q21: =((((IF(N21=1,((J21)*0.29333)))+(IF(N21=2,((J21)*0.146666)))+(IF(N21=3,((J21)*0.146666)))))+(IF(N21=4,((J21-40)*0.29333)))+(IF(N21=5,((J21-50)*0.29333)))+(IF(N21=6,((J21-90)*0.29333)))) -> 109.99875 | U21: NA | V21: NA
D22: 2874560-1 | E22: 45939 | F22: 45939 | G22: 3 | H22: =IF(G22=1,KILOMETRAJE!C$4,IF(G22=2,KILOMETRAJE!C$5,IF(G22=3,KILOMETRAJE!C$6,IF(G22=4,KILOMETRAJE!C$7,IF(G22=5,KILOMETRAJE!C$8,IF(G22=6,KILOMETRAJE!C$9,IF(G22=7,KILOMETRAJE!C$10,IF(G22=8,KILOMETRAJE!C$11,IF(G22=9,KILOMETRAJE!C$12,IF(G22=10,KILOMETRAJE!C$13,IF(G22=11,KILOMETRAJE!C$14,IF(G22=12,KILOMETRAJE!C$15,IF(G22=13,KILOMETRAJE!C$16,IF(G22=14,KILOMETRAJE!C$17,IF(G22=15,KILOMETRAJE!C$18,IF(G22=16,KILOMETRAJE!C$19,IF(G22=17,KILOMETRAJE!C$20,IF(G22=18,KILOMETRAJE!C$21,IF(G22=19,KILOMETRAJE!C$22,IF(G22=20,KILOMETRAJE!C$23,IF(G22=21,KILOMETRAJE!C$24,IF(G22=22,KILOMETRAJE!C$25,IF(G22=23,KILOMETRAJE!C$26,IF(G22=24,KILOMETRAJE!C$27,IF(G22=25,KILOMETRAJE!C$28,IF(G22=26,KILOMETRAJE!C$29,IF(G22=27,KILOMETRAJE!C$30,IF(G22=28,KILOMETRAJE!C$31,IF(G22=29,KILOMETRAJE!C$32,IF(G22=30,KILOMETRAJE!C$33,IF(G22=31,KILOMETRAJE!C$34,IF(G22=32,KILOMETRAJE!C$35,IF(G22=33,KILOMETRAJE!C$36,IF(G22=34,KILOMETRAJE!C$37,IF(G22=35,KILOMETRAJE!C$38,IF(G22=36,KILOMETRAJE!C$39,IF(G22=37,KILOMETRAJE!C$40,IF(G22=38,KILOMETRAJE!C$41,IF(G22=39,KILOMETRAJE!C$42,IF(G22=40,KILOMETRAJE!C$43,IF(G22=41,KILOMETRAJE!C$44,IF(G22=42,KILOMETRAJE!C$45,IF(G22=43,KILOMETRAJE!C$46,IF(G22=44,KILOMETRAJE!C$47,IF(G22=45,KILOMETRAJE!C$48,IF(G22=46,KILOMETRAJE!C$49,IF(G22=47,KILOMETRAJE!C$50,IF(G22=48,KILOMETRAJE!C$51,IF(G22=49,KILOMETRAJE!C$52,IF(G22=50,KILOMETRAJE!C$53,IF(G22=51,KILOMETRAJE!C$54,IF(G22=52,KILOMETRAJE!C$55,IF(G22=53,KILOMETRAJE!C$56,IF(G22=54,KILOMETRAJE!C$57,IF(G22=55,KILOMETRAJE!C$58,IF(G22=56,KILOMETRAJE!C$59,IF(G22=57,KILOMETRAJE!C$60,IF(G22=58,KILOMETRAJE!C$61,IF(G22=59,KILOMETRAJE!C$62,IF(G22=60,KILOMETRAJE!C$63,IF(G22=61,KILOMETRAJE!C$64,IF(G22=62,KILOMETRAJE!C$65,IF(G22=63,KILOMETRAJE!C$66))))))))))))))))))))))))))))))))))))))))))))))))))))))))))))))) -> CHIH. | I22: =IF(G22=1,KILOMETRAJE!E$4,IF(G22=2,KILOMETRAJE!E$5,IF(G22=3,KILOMETRAJE!E$6,IF(G22=4,KILOMETRAJE!E$7,IF(G22=5,KILOMETRAJE!E$8,IF(G22=6,KILOMETRAJE!E$9,IF(G22=7,KILOMETRAJE!E$10,IF(G22=8,KILOMETRAJE!E$11,IF(G22=9,KILOMETRAJE!E$12,IF(G22=10,KILOMETRAJE!E$13,IF(G22=11,KILOMETRAJE!E$14,IF(G22=12,KILOMETRAJE!E$15,IF(G22=13,KILOMETRAJE!E$16,IF(G22=14,KILOMETRAJE!E$17,IF(G22=15,KILOMETRAJE!E$18,IF(G22=16,KILOMETRAJE!E$19,IF(G22=17,KILOMETRAJE!E$20,IF(G22=18,KILOMETRAJE!E$21,IF(G22=19,KILOMETRAJE!E$22,IF(G22=20,KILOMETRAJE!E$23,IF(G22=21,KILOMETRAJE!E$24,IF(G22=22,KILOMETRAJE!E$25,IF(G22=23,KILOMETRAJE!E$26,IF(G22=24,KILOMETRAJE!E$27,IF(G22=25,KILOMETRAJE!E$28,IF(G22=26,KILOMETRAJE!E$29,IF(G22=27,KILOMETRAJE!E$30,IF(G22=28,KILOMETRAJE!E$31,IF(G22=29,KILOMETRAJE!E$32,IF(G22=30,KILOMETRAJE!E$33,IF(G22=31,KILOMETRAJE!E$34,IF(G22=32,KILOMETRAJE!E$35,IF(G22=33,KILOMETRAJE!E$36,IF(G22=34,KILOMETRAJE!E$37,IF(G22=35,KILOMETRAJE!E$38,IF(G22=36,KILOMETRAJE!E$39,IF(G22=37,KILOMETRAJE!E$40,IF(G22=38,KILOMETRAJE!E$41,IF(G22=39,KILOMETRAJE!E$42,IF(G22=40,KILOMETRAJE!E$43,IF(G22=41,KILOMETRAJE!E$44,IF(G22=42,KILOMETRAJE!E$45,IF(G22=43,KILOMETRAJE!E$46,IF(G22=44,KILOMETRAJE!E$47,IF(G22=45,KILOMETRAJE!E$48,IF(G22=46,KILOMETRAJE!E$49,IF(G22=47,KILOMETRAJE!E$50,IF(G22=48,KILOMETRAJE!E$51,IF(G22=49,KILOMETRAJE!E$52,IF(G22=50,KILOMETRAJE!E$53,IF(G22=51,KILOMETRAJE!E$54,IF(G22=52,KILOMETRAJE!E$55,IF(G22=53,KILOMETRAJE!E$56,IF(G22=54,KILOMETRAJE!E$57,IF(G22=55,KILOMETRAJE!E$58,IF(G22=56,KILOMETRAJE!E$59,IF(G22=57,KILOMETRAJE!E$60,IF(G22=58,KILOMETRAJE!E$61,IF(G22=59,KILOMETRAJE!E$62,IF(G22=60,KILOMETRAJE!E$63,IF(G22=61,KILOMETRAJE!E$64,IF(G22=62,KILOMETRAJE!E$65,IF(G22=63,KILOMETRAJE!E$66))))))))))))))))))))))))))))))))))))))))))))))))))))))))))))))) -> JRZ | J22: =IF(G22=1,KILOMETRAJE!G$4,IF(G22=2,KILOMETRAJE!G$5,IF(G22=3,KILOMETRAJE!G$6,IF(G22=4,KILOMETRAJE!G$7,IF(G22=5,KILOMETRAJE!G$8,IF(G22=6,KILOMETRAJE!G$9,IF(G22=7,KILOMETRAJE!G$10,IF(G22=8,KILOMETRAJE!G$11,IF(G22=9,KILOMETRAJE!G$12,IF(G22=10,KILOMETRAJE!G$13,IF(G22=11,KILOMETRAJE!G$14,IF(G22=12,KILOMETRAJE!G$15,IF(G22=13,KILOMETRAJE!G$16,IF(G22=14,KILOMETRAJE!G$17,IF(G22=15,KILOMETRAJE!G$18,IF(G22=16,KILOMETRAJE!G$19,IF(G22=17,KILOMETRAJE!G$20,IF(G22=18,KILOMETRAJE!G$21,IF(G22=19,KILOMETRAJE!G$22,IF(G22=20,KILOMETRAJE!G$23,IF(G22=21,KILOMETRAJE!G$24,IF(G22=22,KILOMETRAJE!G$25,IF(G22=23,KILOMETRAJE!G$26,IF(G22=24,KILOMETRAJE!G$27,IF(G22=25,KILOMETRAJE!G$28,IF(G22=26,KILOMETRAJE!G$29,IF(G22=27,KILOMETRAJE!G$30,IF(G22=28,KILOMETRAJE!G$31,IF(G22=29,KILOMETRAJE!G$32,IF(G22=30,KILOMETRAJE!G$33,IF(G22=31,KILOMETRAJE!G$34,IF(G22=32,KILOMETRAJE!G$35,IF(G22=33,KILOMETRAJE!G$36,IF(G22=34,KILOMETRAJE!G$37,IF(G22=35,KILOMETRAJE!G$38,IF(G22=36,KILOMETRAJE!G$39,IF(G22=37,KILOMETRAJE!G$40,IF(G22=38,KILOMETRAJE!G$41,IF(G22=39,KILOMETRAJE!G$42,IF(G22=40,KILOMETRAJE!G$43,IF(G22=41,KILOMETRAJE!G$44,IF(G22=42,KILOMETRAJE!G$45,IF(G22=43,KILOMETRAJE!G$46,IF(G22=44,KILOMETRAJE!G$47,IF(G22=45,KILOMETRAJE!G$48,IF(G22=46,KILOMETRAJE!G$49,IF(G22=47,KILOMETRAJE!G$50,IF(G22=48,KILOMETRAJE!G$51,IF(G22=49,KILOMETRAJE!G$52,IF(G22=50,KILOMETRAJE!G$53,IF(G22=51,KILOMETRAJE!G$54,IF(G22=52,KILOMETRAJE!G$55,IF(G22=53,KILOMETRAJE!G$56,IF(G22=54,KILOMETRAJE!G$57,IF(G22=55,KILOMETRAJE!G$58,IF(G22=56,KILOMETRAJE!G$59,IF(G22=57,KILOMETRAJE!G$60,IF(G22=58,KILOMETRAJE!G$61,IF(G22=59,KILOMETRAJE!G$62,IF(G22=60,KILOMETRAJE!G$63,IF(G22=61,KILOMETRAJE!G$64,IF(G22=62,KILOMETRAJE!G$65,IF(G22=63,KILOMETRAJE!G$66))))))))))))))))))))))))))))))))))))))))))))))))))))))))))))))) -> 375 | K22: 210.02 | L22: =SUM(J21:J22)/K22 -> 3.7615465 | M22: 0 | N22: 3 | P22: SOTELO | Q22: =((((IF(N22=1,((J22)*0.29333)))+(IF(N22=2,((J22)*0.146666)))+(IF(N22=3,((J22)*0.146666)))))+(IF(N22=4,((J22-40)*0.29333)))+(IF(N22=5,((J22-50)*0.29333)))+(IF(N22=6,((J22-90)*0.29333)))) -> 54.99975 | R22: =+LOOKUP(P41,UNIDADES!B$3:B$59,UNIDADES!C$3:C$59) -> 2.45098 | S22: =+((SUM(J21:J22)-40)/R22)-K22 -> 95.980049 | T22: =+S22*14.85 -> 1425.3037 | U22: 57 | V22: 57
C23: 45944 | D23: 2874731-3 | E23: 45939 | F23: 45940 | G23: 2 | H23: =IF(G23=1,KILOMETRAJE!C$4,IF(G23=2,KILOMETRAJE!C$5,IF(G23=3,KILOMETRAJE!C$6,IF(G23=4,KILOMETRAJE!C$7,IF(G23=5,KILOMETRAJE!C$8,IF(G23=6,KILOMETRAJE!C$9,IF(G23=7,KILOMETRAJE!C$10,IF(G23=8,KILOMETRAJE!C$11,IF(G23=9,KILOMETRAJE!C$12,IF(G23=10,KILOMETRAJE!C$13,IF(G23=11,KILOMETRAJE!C$14,IF(G23=12,KILOMETRAJE!C$15,IF(G23=13,KILOMETRAJE!C$16,IF(G23=14,KILOMETRAJE!C$17,IF(G23=15,KILOMETRAJE!C$18,IF(G23=16,KILOMETRAJE!C$19,IF(G23=17,KILOMETRAJE!C$20,IF(G23=18,KILOMETRAJE!C$21,IF(G23=19,KILOMETRAJE!C$22,IF(G23=20,KILOMETRAJE!C$23,IF(G23=21,KILOMETRAJE!C$24,IF(G23=22,KILOMETRAJE!C$25,IF(G23=23,KILOMETRAJE!C$26,IF(G23=24,KILOMETRAJE!C$27,IF(G23=25,KILOMETRAJE!C$28,IF(G23=26,KILOMETRAJE!C$29,IF(G23=27,KILOMETRAJE!C$30,IF(G23=28,KILOMETRAJE!C$31,IF(G23=29,KILOMETRAJE!C$32,IF(G23=30,KILOMETRAJE!C$33,IF(G23=31,KILOMETRAJE!C$34,IF(G23=32,KILOMETRAJE!C$35,IF(G23=33,KILOMETRAJE!C$36,IF(G23=34,KILOMETRAJE!C$37,IF(G23=35,KILOMETRAJE!C$38,IF(G23=36,KILOMETRAJE!C$39,IF(G23=37,KILOMETRAJE!C$40,IF(G23=38,KILOMETRAJE!C$41,IF(G23=39,KILOMETRAJE!C$42,IF(G23=40,KILOMETRAJE!C$43,IF(G23=41,KILOMETRAJE!C$44,IF(G23=42,KILOMETRAJE!C$45,IF(G23=43,KILOMETRAJE!C$46,IF(G23=44,KILOMETRAJE!C$47,IF(G23=45,KILOMETRAJE!C$48,IF(G23=46,KILOMETRAJE!C$49,IF(G23=47,KILOMETRAJE!C$50,IF(G23=48,KILOMETRAJE!C$51,IF(G23=49,KILOMETRAJE!C$52,IF(G23=50,KILOMETRAJE!C$53,IF(G23=51,KILOMETRAJE!C$54,IF(G23=52,KILOMETRAJE!C$55,IF(G23=53,KILOMETRAJE!C$56,IF(G23=54,KILOMETRAJE!C$57,IF(G23=55,KILOMETRAJE!C$58,IF(G23=56,KILOMETRAJE!C$59,IF(G23=57,KILOMETRAJE!C$60,IF(G23=58,KILOMETRAJE!C$61,IF(G23=59,KILOMETRAJE!C$62,IF(G23=60,KILOMETRAJE!C$63,IF(G23=61,KILOMETRAJE!C$64,IF(G23=62,KILOMETRAJE!C$65,IF(G23=63,KILOMETRAJE!C$66))))))))))))))))))))))))))))))))))))))))))))))))))))))))))))))) -> JRZ | I23: =IF(G23=1,KILOMETRAJE!E$4,IF(G23=2,KILOMETRAJE!E$5,IF(G23=3,KILOMETRAJE!E$6,IF(G23=4,KILOMETRAJE!E$7,IF(G23=5,KILOMETRAJE!E$8,IF(G23=6,KILOMETRAJE!E$9,IF(G23=7,KILOMETRAJE!E$10,IF(G23=8,KILOMETRAJE!E$11,IF(G23=9,KILOMETRAJE!E$12,IF(G23=10,KILOMETRAJE!E$13,IF(G23=11,KILOMETRAJE!E$14,IF(G23=12,KILOMETRAJE!E$15,IF(G23=13,KILOMETRAJE!E$16,IF(G23=14,KILOMETRAJE!E$17,IF(G23=15,KILOMETRAJE!E$18,IF(G23=16,KILOMETRAJE!E$19,IF(G23=17,KILOMETRAJE!E$20,IF(G23=18,KILOMETRAJE!E$21,IF(G23=19,KILOMETRAJE!E$22,IF(G23=20,KILOMETRAJE!E$23,IF(G23=21,KILOMETRAJE!E$24,IF(G23=22,KILOMETRAJE!E$25,IF(G23=23,KILOMETRAJE!E$26,IF(G23=24,KILOMETRAJE!E$27,IF(G23=25,KILOMETRAJE!E$28,IF(G23=26,KILOMETRAJE!E$29,IF(G23=27,KILOMETRAJE!E$30,IF(G23=28,KILOMETRAJE!E$31,IF(G23=29,KILOMETRAJE!E$32,IF(G23=30,KILOMETRAJE!E$33,IF(G23=31,KILOMETRAJE!E$34,IF(G23=32,KILOMETRAJE!E$35,IF(G23=33,KILOMETRAJE!E$36,IF(G23=34,KILOMETRAJE!E$37,IF(G23=35,KILOMETRAJE!E$38,IF(G23=36,KILOMETRAJE!E$39,IF(G23=37,KILOMETRAJE!E$40,IF(G23=38,KILOMETRAJE!E$41,IF(G23=39,KILOMETRAJE!E$42,IF(G23=40,KILOMETRAJE!E$43,IF(G23=41,KILOMETRAJE!E$44,IF(G23=42,KILOMETRAJE!E$45,IF(G23=43,KILOMETRAJE!E$46,IF(G23=44,KILOMETRAJE!E$47,IF(G23=45,KILOMETRAJE!E$48,IF(G23=46,KILOMETRAJE!E$49,IF(G23=47,KILOMETRAJE!E$50,IF(G23=48,KILOMETRAJE!E$51,IF(G23=49,KILOMETRAJE!E$52,IF(G23=50,KILOMETRAJE!E$53,IF(G23=51,KILOMETRAJE!E$54,IF(G23=52,KILOMETRAJE!E$55,IF(G23=53,KILOMETRAJE!E$56,IF(G23=54,KILOMETRAJE!E$57,IF(G23=55,KILOMETRAJE!E$58,IF(G23=56,KILOMETRAJE!E$59,IF(G23=57,KILOMETRAJE!E$60,IF(G23=58,KILOMETRAJE!E$61,IF(G23=59,KILOMETRAJE!E$62,IF(G23=60,KILOMETRAJE!E$63,IF(G23=61,KILOMETRAJE!E$64,IF(G23=62,KILOMETRAJE!E$65,IF(G23=63,KILOMETRAJE!E$66))))))))))))))))))))))))))))))))))))))))))))))))))))))))))))))) -> CHIH. | J23: =IF(G23=1,KILOMETRAJE!G$4,IF(G23=2,KILOMETRAJE!G$5,IF(G23=3,KILOMETRAJE!G$6,IF(G23=4,KILOMETRAJE!G$7,IF(G23=5,KILOMETRAJE!G$8,IF(G23=6,KILOMETRAJE!G$9,IF(G23=7,KILOMETRAJE!G$10,IF(G23=8,KILOMETRAJE!G$11,IF(G23=9,KILOMETRAJE!G$12,IF(G23=10,KILOMETRAJE!G$13,IF(G23=11,KILOMETRAJE!G$14,IF(G23=12,KILOMETRAJE!G$15,IF(G23=13,KILOMETRAJE!G$16,IF(G23=14,KILOMETRAJE!G$17,IF(G23=15,KILOMETRAJE!G$18,IF(G23=16,KILOMETRAJE!G$19,IF(G23=17,KILOMETRAJE!G$20,IF(G23=18,KILOMETRAJE!G$21,IF(G23=19,KILOMETRAJE!G$22,IF(G23=20,KILOMETRAJE!G$23,IF(G23=21,KILOMETRAJE!G$24,IF(G23=22,KILOMETRAJE!G$25,IF(G23=23,KILOMETRAJE!G$26,IF(G23=24,KILOMETRAJE!G$27,IF(G23=25,KILOMETRAJE!G$28,IF(G23=26,KILOMETRAJE!G$29,IF(G23=27,KILOMETRAJE!G$30,IF(G23=28,KILOMETRAJE!G$31,IF(G23=29,KILOMETRAJE!G$32,IF(G23=30,KILOMETRAJE!G$33,IF(G23=31,KILOMETRAJE!G$34,IF(G23=32,KILOMETRAJE!G$35,IF(G23=33,KILOMETRAJE!G$36,IF(G23=34,KILOMETRAJE!G$37,IF(G23=35,KILOMETRAJE!G$38,IF(G23=36,KILOMETRAJE!G$39,IF(G23=37,KILOMETRAJE!G$40,IF(G23=38,KILOMETRAJE!G$41,IF(G23=39,KILOMETRAJE!G$42,IF(G23=40,KILOMETRAJE!G$43,IF(G23=41,KILOMETRAJE!G$44,IF(G23=42,KILOMETRAJE!G$45,IF(G23=43,KILOMETRAJE!G$46,IF(G23=44,KILOMETRAJE!G$47,IF(G23=45,KILOMETRAJE!G$48,IF(G23=46,KILOMETRAJE!G$49,IF(G23=47,KILOMETRAJE!G$50,IF(G23=48,KILOMETRAJE!G$51,IF(G23=49,KILOMETRAJE!G$52,IF(G23=50,KILOMETRAJE!G$53,IF(G23=51,KILOMETRAJE!G$54,IF(G23=52,KILOMETRAJE!G$55,IF(G23=53,KILOMETRAJE!G$56,IF(G23=54,KILOMETRAJE!G$57,IF(G23=55,KILOMETRAJE!G$58,IF(G23=56,KILOMETRAJE!G$59,IF(G23=57,KILOMETRAJE!G$60,IF(G23=58,KILOMETRAJE!G$61,IF(G23=59,KILOMETRAJE!G$62,IF(G23=60,KILOMETRAJE!G$63,IF(G23=61,KILOMETRAJE!G$64,IF(G23=62,KILOMETRAJE!G$65,IF(G23=63,KILOMETRAJE!G$66))))))))))))))))))))))))))))))))))))))))))))))))))))))))))))))) -> 375 | M23: 764.58 | N23: 1 | O23: BS35062 | P23: XYLEM | Q23: =((((IF(N23=1,((J23)*0.29333)))+(IF(N23=2,((J23)*0.146666)))+(IF(N23=3,((J23)*0.146666)))))+(IF(N23=4,((J23-40)*0.29333)))+(IF(N23=5,((J23-50)*0.29333)))+(IF(N23=6,((J23-90)*0.29333)))) -> 109.99875 | U23: NA | V23: NA
D24: 2874723-4 | E24: 45940 | F24: 45940 | G24: 27 | H24: =IF(G24=1,KILOMETRAJE!C$4,IF(G24=2,KILOMETRAJE!C$5,IF(G24=3,KILOMETRAJE!C$6,IF(G24=4,KILOMETRAJE!C$7,IF(G24=5,KILOMETRAJE!C$8,IF(G24=6,KILOMETRAJE!C$9,IF(G24=7,KILOMETRAJE!C$10,IF(G24=8,KILOMETRAJE!C$11,IF(G24=9,KILOMETRAJE!C$12,IF(G24=10,KILOMETRAJE!C$13,IF(G24=11,KILOMETRAJE!C$14,IF(G24=12,KILOMETRAJE!C$15,IF(G24=13,KILOMETRAJE!C$16,IF(G24=14,KILOMETRAJE!C$17,IF(G24=15,KILOMETRAJE!C$18,IF(G24=16,KILOMETRAJE!C$19,IF(G24=17,KILOMETRAJE!C$20,IF(G24=18,KILOMETRAJE!C$21,IF(G24=19,KILOMETRAJE!C$22,IF(G24=20,KILOMETRAJE!C$23,IF(G24=21,KILOMETRAJE!C$24,IF(G24=22,KILOMETRAJE!C$25,IF(G24=23,KILOMETRAJE!C$26,IF(G24=24,KILOMETRAJE!C$27,IF(G24=25,KILOMETRAJE!C$28,IF(G24=26,KILOMETRAJE!C$29,IF(G24=27,KILOMETRAJE!C$30,IF(G24=28,KILOMETRAJE!C$31,IF(G24=29,KILOMETRAJE!C$32,IF(G24=30,KILOMETRAJE!C$33,IF(G24=31,KILOMETRAJE!C$34,IF(G24=32,KILOMETRAJE!C$35,IF(G24=33,KILOMETRAJE!C$36,IF(G24=34,KILOMETRAJE!C$37,IF(G24=35,KILOMETRAJE!C$38,IF(G24=36,KILOMETRAJE!C$39,IF(G24=37,KILOMETRAJE!C$40,IF(G24=38,KILOMETRAJE!C$41,IF(G24=39,KILOMETRAJE!C$42,IF(G24=40,KILOMETRAJE!C$43,IF(G24=41,KILOMETRAJE!C$44,IF(G24=42,KILOMETRAJE!C$45,IF(G24=43,KILOMETRAJE!C$46,IF(G24=44,KILOMETRAJE!C$47,IF(G24=45,KILOMETRAJE!C$48,IF(G24=46,KILOMETRAJE!C$49,IF(G24=47,KILOMETRAJE!C$50,IF(G24=48,KILOMETRAJE!C$51,IF(G24=49,KILOMETRAJE!C$52,IF(G24=50,KILOMETRAJE!C$53,IF(G24=51,KILOMETRAJE!C$54,IF(G24=52,KILOMETRAJE!C$55,IF(G24=53,KILOMETRAJE!C$56,IF(G24=54,KILOMETRAJE!C$57,IF(G24=55,KILOMETRAJE!C$58,IF(G24=56,KILOMETRAJE!C$59,IF(G24=57,KILOMETRAJE!C$60,IF(G24=58,KILOMETRAJE!C$61,IF(G24=59,KILOMETRAJE!C$62,IF(G24=60,KILOMETRAJE!C$63,IF(G24=61,KILOMETRAJE!C$64,IF(G24=62,KILOMETRAJE!C$65,IF(G24=63,KILOMETRAJE!C$66))))))))))))))))))))))))))))))))))))))))))))))))))))))))))))))) -> CHIH. | I24: =IF(G24=1,KILOMETRAJE!E$4,IF(G24=2,KILOMETRAJE!E$5,IF(G24=3,KILOMETRAJE!E$6,IF(G24=4,KILOMETRAJE!E$7,IF(G24=5,KILOMETRAJE!E$8,IF(G24=6,KILOMETRAJE!E$9,IF(G24=7,KILOMETRAJE!E$10,IF(G24=8,KILOMETRAJE!E$11,IF(G24=9,KILOMETRAJE!E$12,IF(G24=10,KILOMETRAJE!E$13,IF(G24=11,KILOMETRAJE!E$14,IF(G24=12,KILOMETRAJE!E$15,IF(G24=13,KILOMETRAJE!E$16,IF(G24=14,KILOMETRAJE!E$17,IF(G24=15,KILOMETRAJE!E$18,IF(G24=16,KILOMETRAJE!E$19,IF(G24=17,KILOMETRAJE!E$20,IF(G24=18,KILOMETRAJE!E$21,IF(G24=19,KILOMETRAJE!E$22,IF(G24=20,KILOMETRAJE!E$23,IF(G24=21,KILOMETRAJE!E$24,IF(G24=22,KILOMETRAJE!E$25,IF(G24=23,KILOMETRAJE!E$26,IF(G24=24,KILOMETRAJE!E$27,IF(G24=25,KILOMETRAJE!E$28,IF(G24=26,KILOMETRAJE!E$29,IF(G24=27,KILOMETRAJE!E$30,IF(G24=28,KILOMETRAJE!E$31,IF(G24=29,KILOMETRAJE!E$32,IF(G24=30,KILOMETRAJE!E$33,IF(G24=31,KILOMETRAJE!E$34,IF(G24=32,KILOMETRAJE!E$35,IF(G24=33,KILOMETRAJE!E$36,IF(G24=34,KILOMETRAJE!E$37,IF(G24=35,KILOMETRAJE!E$38,IF(G24=36,KILOMETRAJE!E$39,IF(G24=37,KILOMETRAJE!E$40,IF(G24=38,KILOMETRAJE!E$41,IF(G24=39,KILOMETRAJE!E$42,IF(G24=40,KILOMETRAJE!E$43,IF(G24=41,KILOMETRAJE!E$44,IF(G24=42,KILOMETRAJE!E$45,IF(G24=43,KILOMETRAJE!E$46,IF(G24=44,KILOMETRAJE!E$47,IF(G24=45,KILOMETRAJE!E$48,IF(G24=46,KILOMETRAJE!E$49,IF(G24=47,KILOMETRAJE!E$50,IF(G24=48,KILOMETRAJE!E$51,IF(G24=49,KILOMETRAJE!E$52,IF(G24=50,KILOMETRAJE!E$53,IF(G24=51,KILOMETRAJE!E$54,IF(G24=52,KILOMETRAJE!E$55,IF(G24=53,KILOMETRAJE!E$56,IF(G24=54,KILOMETRAJE!E$57,IF(G24=55,KILOMETRAJE!E$58,IF(G24=56,KILOMETRAJE!E$59,IF(G24=57,KILOMETRAJE!E$60,IF(G24=58,KILOMETRAJE!E$61,IF(G24=59,KILOMETRAJE!E$62,IF(G24=60,KILOMETRAJE!E$63,IF(G24=61,KILOMETRAJE!E$64,IF(G24=62,KILOMETRAJE!E$65,IF(G24=63,KILOMETRAJE!E$66))))))))))))))))))))))))))))))))))))))))))))))))))))))))))))))) -> ELP | J24: =IF(G24=1,KILOMETRAJE!G$4,IF(G24=2,KILOMETRAJE!G$5,IF(G24=3,KILOMETRAJE!G$6,IF(G24=4,KILOMETRAJE!G$7,IF(G24=5,KILOMETRAJE!G$8,IF(G24=6,KILOMETRAJE!G$9,IF(G24=7,KILOMETRAJE!G$10,IF(G24=8,KILOMETRAJE!G$11,IF(G24=9,KILOMETRAJE!G$12,IF(G24=10,KILOMETRAJE!G$13,IF(G24=11,KILOMETRAJE!G$14,IF(G24=12,KILOMETRAJE!G$15,IF(G24=13,KILOMETRAJE!G$16,IF(G24=14,KILOMETRAJE!G$17,IF(G24=15,KILOMETRAJE!G$18,IF(G24=16,KILOMETRAJE!G$19,IF(G24=17,KILOMETRAJE!G$20,IF(G24=18,KILOMETRAJE!G$21,IF(G24=19,KILOMETRAJE!G$22,IF(G24=20,KILOMETRAJE!G$23,IF(G24=21,KILOMETRAJE!G$24,IF(G24=22,KILOMETRAJE!G$25,IF(G24=23,KILOMETRAJE!G$26,IF(G24=24,KILOMETRAJE!G$27,IF(G24=25,KILOMETRAJE!G$28,IF(G24=26,KILOMETRAJE!G$29,IF(G24=27,KILOMETRAJE!G$30,IF(G24=28,KILOMETRAJE!G$31,IF(G24=29,KILOMETRAJE!G$32,IF(G24=30,KILOMETRAJE!G$33,IF(G24=31,KILOMETRAJE!G$34,IF(G24=32,KILOMETRAJE!G$35,IF(G24=33,KILOMETRAJE!G$36,IF(G24=34,KILOMETRAJE!G$37,IF(G24=35,KILOMETRAJE!G$38,IF(G24=36,KILOMETRAJE!G$39,IF(G24=37,KILOMETRAJE!G$40,IF(G24=38,KILOMETRAJE!G$41,IF(G24=39,KILOMETRAJE!G$42,IF(G24=40,KILOMETRAJE!G$43,IF(G24=41,KILOMETRAJE!G$44,IF(G24=42,KILOMETRAJE!G$45,IF(G24=43,KILOMETRAJE!G$46,IF(G24=44,KILOMETRAJE!G$47,IF(G24=45,KILOMETRAJE!G$48,IF(G24=46,KILOMETRAJE!G$49,IF(G24=47,KILOMETRAJE!G$50,IF(G24=48,KILOMETRAJE!G$51,IF(G24=49,KILOMETRAJE!G$52,IF(G24=50,KILOMETRAJE!G$53,IF(G24=51,KILOMETRAJE!G$54,IF(G24=52,KILOMETRAJE!G$55,IF(G24=53,KILOMETRAJE!G$56,IF(G24=54,KILOMETRAJE!G$57,IF(G24=55,KILOMETRAJE!G$58,IF(G24=56,KILOMETRAJE!G$59,IF(G24=57,KILOMETRAJE!G$60,IF(G24=58,KILOMETRAJE!G$61,IF(G24=59,KILOMETRAJE!G$62,IF(G24=60,KILOMETRAJE!G$63,IF(G24=61,KILOMETRAJE!G$64,IF(G24=62,KILOMETRAJE!G$65,IF(G24=63,KILOMETRAJE!G$66))))))))))))))))))))))))))))))))))))))))))))))))))))))))))))))) -> 415 | K24: 250.544 | L24: =SUM(J23:J24)/K24 -> 3.1531388 | M24: 3780.65 | N24: 4 | O24: BS35095 | P24: G. AMERICAN | Q24: =((((IF(N24=1,((J24)*0.29333)))+(IF(N24=2,((J24)*0.146666)))+(IF(N24=3,((J24)*0.146666)))))+(IF(N24=4,((J24-40)*0.29333)))+(IF(N24=5,((J24-50)*0.29333)))+(IF(N24=6,((J24-90)*0.29333)))) -> 109.99875 | R24: =+LOOKUP(P42,UNIDADES!B$3:B$59,UNIDADES!C$3:C$59) -> 2.45098 | S24: =+((SUM(J23:J24)-40)/R24)-K24 -> 55.456049 | T24: =+S24*14.85 -> 823.52233 | U24: 57 | V24: 57
C25: 45980 | D25: 2875104-1 | E25: 45941 | F25: 45943 | G25: 2 | H25: =IF(G25=1,KILOMETRAJE!C$4,IF(G25=2,KILOMETRAJE!C$5,IF(G25=3,KILOMETRAJE!C$6,IF(G25=4,KILOMETRAJE!C$7,IF(G25=5,KILOMETRAJE!C$8,IF(G25=6,KILOMETRAJE!C$9,IF(G25=7,KILOMETRAJE!C$10,IF(G25=8,KILOMETRAJE!C$11,IF(G25=9,KILOMETRAJE!C$12,IF(G25=10,KILOMETRAJE!C$13,IF(G25=11,KILOMETRAJE!C$14,IF(G25=12,KILOMETRAJE!C$15,IF(G25=13,KILOMETRAJE!C$16,IF(G25=14,KILOMETRAJE!C$17,IF(G25=15,KILOMETRAJE!C$18,IF(G25=16,KILOMETRAJE!C$19,IF(G25=17,KILOMETRAJE!C$20,IF(G25=18,KILOMETRAJE!C$21,IF(G25=19,KILOMETRAJE!C$22,IF(G25=20,KILOMETRAJE!C$23,IF(G25=21,KILOMETRAJE!C$24,IF(G25=22,KILOMETRAJE!C$25,IF(G25=23,KILOMETRAJE!C$26,IF(G25=24,KILOMETRAJE!C$27,IF(G25=25,KILOMETRAJE!C$28,IF(G25=26,KILOMETRAJE!C$29,IF(G25=27,KILOMETRAJE!C$30,IF(G25=28,KILOMETRAJE!C$31,IF(G25=29,KILOMETRAJE!C$32,IF(G25=30,KILOMETRAJE!C$33,IF(G25=31,KILOMETRAJE!C$34,IF(G25=32,KILOMETRAJE!C$35,IF(G25=33,KILOMETRAJE!C$36,IF(G25=34,KILOMETRAJE!C$37,IF(G25=35,KILOMETRAJE!C$38,IF(G25=36,KILOMETRAJE!C$39,IF(G25=37,KILOMETRAJE!C$40,IF(G25=38,KILOMETRAJE!C$41,IF(G25=39,KILOMETRAJE!C$42,IF(G25=40,KILOMETRAJE!C$43,IF(G25=41,KILOMETRAJE!C$44,IF(G25=42,KILOMETRAJE!C$45,IF(G25=43,KILOMETRAJE!C$46,IF(G25=44,KILOMETRAJE!C$47,IF(G25=45,KILOMETRAJE!C$48,IF(G25=46,KILOMETRAJE!C$49,IF(G25=47,KILOMETRAJE!C$50,IF(G25=48,KILOMETRAJE!C$51,IF(G25=49,KILOMETRAJE!C$52,IF(G25=50,KILOMETRAJE!C$53,IF(G25=51,KILOMETRAJE!C$54,IF(G25=52,KILOMETRAJE!C$55,IF(G25=53,KILOMETRAJE!C$56,IF(G25=54,KILOMETRAJE!C$57,IF(G25=55,KILOMETRAJE!C$58,IF(G25=56,KILOMETRAJE!C$59,IF(G25=57,KILOMETRAJE!C$60,IF(G25=58,KILOMETRAJE!C$61,IF(G25=59,KILOMETRAJE!C$62,IF(G25=60,KILOMETRAJE!C$63,IF(G25=61,KILOMETRAJE!C$64,IF(G25=62,KILOMETRAJE!C$65,IF(G25=63,KILOMETRAJE!C$66))))))))))))))))))))))))))))))))))))))))))))))))))))))))))))))) -> JRZ | I25: =IF(G25=1,KILOMETRAJE!E$4,IF(G25=2,KILOMETRAJE!E$5,IF(G25=3,KILOMETRAJE!E$6,IF(G25=4,KILOMETRAJE!E$7,IF(G25=5,KILOMETRAJE!E$8,IF(G25=6,KILOMETRAJE!E$9,IF(G25=7,KILOMETRAJE!E$10,IF(G25=8,KILOMETRAJE!E$11,IF(G25=9,KILOMETRAJE!E$12,IF(G25=10,KILOMETRAJE!E$13,IF(G25=11,KILOMETRAJE!E$14,IF(G25=12,KILOMETRAJE!E$15,IF(G25=13,KILOMETRAJE!E$16,IF(G25=14,KILOMETRAJE!E$17,IF(G25=15,KILOMETRAJE!E$18,IF(G25=16,KILOMETRAJE!E$19,IF(G25=17,KILOMETRAJE!E$20,IF(G25=18,KILOMETRAJE!E$21,IF(G25=19,KILOMETRAJE!E$22,IF(G25=20,KILOMETRAJE!E$23,IF(G25=21,KILOMETRAJE!E$24,IF(G25=22,KILOMETRAJE!E$25,IF(G25=23,KILOMETRAJE!E$26,IF(G25=24,KILOMETRAJE!E$27,IF(G25=25,KILOMETRAJE!E$28,IF(G25=26,KILOMETRAJE!E$29,IF(G25=27,KILOMETRAJE!E$30,IF(G25=28,KILOMETRAJE!E$31,IF(G25=29,KILOMETRAJE!E$32,IF(G25=30,KILOMETRAJE!E$33,IF(G25=31,KILOMETRAJE!E$34,IF(G25=32,KILOMETRAJE!E$35,IF(G25=33,KILOMETRAJE!E$36,IF(G25=34,KILOMETRAJE!E$37,IF(G25=35,KILOMETRAJE!E$38,IF(G25=36,KILOMETRAJE!E$39,IF(G25=37,KILOMETRAJE!E$40,IF(G25=38,KILOMETRAJE!E$41,IF(G25=39,KILOMETRAJE!E$42,IF(G25=40,KILOMETRAJE!E$43,IF(G25=41,KILOMETRAJE!E$44,IF(G25=42,KILOMETRAJE!E$45,IF(G25=43,KILOMETRAJE!E$46,IF(G25=44,KILOMETRAJE!E$47,IF(G25=45,KILOMETRAJE!E$48,IF(G25=46,KILOMETRAJE!E$49,IF(G25=47,KILOMETRAJE!E$50,IF(G25=48,KILOMETRAJE!E$51,IF(G25=49,KILOMETRAJE!E$52,IF(G25=50,KILOMETRAJE!E$53,IF(G25=51,KILOMETRAJE!E$54,IF(G25=52,KILOMETRAJE!E$55,IF(G25=53,KILOMETRAJE!E$56,IF(G25=54,KILOMETRAJE!E$57,IF(G25=55,KILOMETRAJE!E$58,IF(G25=56,KILOMETRAJE!E$59,IF(G25=57,KILOMETRAJE!E$60,IF(G25=58,KILOMETRAJE!E$61,IF(G25=59,KILOMETRAJE!E$62,IF(G25=60,KILOMETRAJE!E$63,IF(G25=61,KILOMETRAJE!E$64,IF(G25=62,KILOMETRAJE!E$65,IF(G25=63,KILOMETRAJE!E$66))))))))))))))))))))))))))))))))))))))))))))))))))))))))))))))) -> CHIH. | J25: =IF(G25=1,KILOMETRAJE!G$4,IF(G25=2,KILOMETRAJE!G$5,IF(G25=3,KILOMETRAJE!G$6,IF(G25=4,KILOMETRAJE!G$7,IF(G25=5,KILOMETRAJE!G$8,IF(G25=6,KILOMETRAJE!G$9,IF(G25=7,KILOMETRAJE!G$10,IF(G25=8,KILOMETRAJE!G$11,IF(G25=9,KILOMETRAJE!G$12,IF(G25=10,KILOMETRAJE!G$13,IF(G25=11,KILOMETRAJE!G$14,IF(G25=12,KILOMETRAJE!G$15,IF(G25=13,KILOMETRAJE!G$16,IF(G25=14,KILOMETRAJE!G$17,IF(G25=15,KILOMETRAJE!G$18,IF(G25=16,KILOMETRAJE!G$19,IF(G25=17,KILOMETRAJE!G$20,IF(G25=18,KILOMETRAJE!G$21,IF(G25=19,KILOMETRAJE!G$22,IF(G25=20,KILOMETRAJE!G$23,IF(G25=21,KILOMETRAJE!G$24,IF(G25=22,KILOMETRAJE!G$25,IF(G25=23,KILOMETRAJE!G$26,IF(G25=24,KILOMETRAJE!G$27,IF(G25=25,KILOMETRAJE!G$28,IF(G25=26,KILOMETRAJE!G$29,IF(G25=27,KILOMETRAJE!G$30,IF(G25=28,KILOMETRAJE!G$31,IF(G25=29,KILOMETRAJE!G$32,IF(G25=30,KILOMETRAJE!G$33,IF(G25=31,KILOMETRAJE!G$34,IF(G25=32,KILOMETRAJE!G$35,IF(G25=33,KILOMETRAJE!G$36,IF(G25=34,KILOMETRAJE!G$37,IF(G25=35,KILOMETRAJE!G$38,IF(G25=36,KILOMETRAJE!G$39,IF(G25=37,KILOMETRAJE!G$40,IF(G25=38,KILOMETRAJE!G$41,IF(G25=39,KILOMETRAJE!G$42,IF(G25=40,KILOMETRAJE!G$43,IF(G25=41,KILOMETRAJE!G$44,IF(G25=42,KILOMETRAJE!G$45,IF(G25=43,KILOMETRAJE!G$46,IF(G25=44,KILOMETRAJE!G$47,IF(G25=45,KILOMETRAJE!G$48,IF(G25=46,KILOMETRAJE!G$49,IF(G25=47,KILOMETRAJE!G$50,IF(G25=48,KILOMETRAJE!G$51,IF(G25=49,KILOMETRAJE!G$52,IF(G25=50,KILOMETRAJE!G$53,IF(G25=51,KILOMETRAJE!G$54,IF(G25=52,KILOMETRAJE!G$55,IF(G25=53,KILOMETRAJE!G$56,IF(G25=54,KILOMETRAJE!G$57,IF(G25=55,KILOMETRAJE!G$58,IF(G25=56,KILOMETRAJE!G$59,IF(G25=57,KILOMETRAJE!G$60,IF(G25=58,KILOMETRAJE!G$61,IF(G25=59,KILOMETRAJE!G$62,IF(G25=60,KILOMETRAJE!G$63,IF(G25=61,KILOMETRAJE!G$64,IF(G25=62,KILOMETRAJE!G$65,IF(G25=63,KILOMETRAJE!G$66))))))))))))))))))))))))))))))))))))))))))))))))))))))))))))))) -> 375 | M25: 0 | N25: 2 | O25: BS53757 | P25: SOTELO | Q25: =((((IF(N25=1,((J25)*0.29333)))+(IF(N25=2,((J25)*0.146666)))+(IF(N25=3,((J25)*0.146666)))))+(IF(N25=4,((J25-40)*0.29333)))+(IF(N25=5,((J25-50)*0.29333)))+(IF(N25=6,((J25-90)*0.29333)))) -> 54.99975 | U25: NA | V25: NA
D26: 2875247-5 | E26: 45943 | F26: 45943 | G26: 27 | H26: =IF(G26=1,KILOMETRAJE!C$4,IF(G26=2,KILOMETRAJE!C$5,IF(G26=3,KILOMETRAJE!C$6,IF(G26=4,KILOMETRAJE!C$7,IF(G26=5,KILOMETRAJE!C$8,IF(G26=6,KILOMETRAJE!C$9,IF(G26=7,KILOMETRAJE!C$10,IF(G26=8,KILOMETRAJE!C$11,IF(G26=9,KILOMETRAJE!C$12,IF(G26=10,KILOMETRAJE!C$13,IF(G26=11,KILOMETRAJE!C$14,IF(G26=12,KILOMETRAJE!C$15,IF(G26=13,KILOMETRAJE!C$16,IF(G26=14,KILOMETRAJE!C$17,IF(G26=15,KILOMETRAJE!C$18,IF(G26=16,KILOMETRAJE!C$19,IF(G26=17,KILOMETRAJE!C$20,IF(G26=18,KILOMETRAJE!C$21,IF(G26=19,KILOMETRAJE!C$22,IF(G26=20,KILOMETRAJE!C$23,IF(G26=21,KILOMETRAJE!C$24,IF(G26=22,KILOMETRAJE!C$25,IF(G26=23,KILOMETRAJE!C$26,IF(G26=24,KILOMETRAJE!C$27,IF(G26=25,KILOMETRAJE!C$28,IF(G26=26,KILOMETRAJE!C$29,IF(G26=27,KILOMETRAJE!C$30,IF(G26=28,KILOMETRAJE!C$31,IF(G26=29,KILOMETRAJE!C$32,IF(G26=30,KILOMETRAJE!C$33,IF(G26=31,KILOMETRAJE!C$34,IF(G26=32,KILOMETRAJE!C$35,IF(G26=33,KILOMETRAJE!C$36,IF(G26=34,KILOMETRAJE!C$37,IF(G26=35,KILOMETRAJE!C$38,IF(G26=36,KILOMETRAJE!C$39,IF(G26=37,KILOMETRAJE!C$40,IF(G26=38,KILOMETRAJE!C$41,IF(G26=39,KILOMETRAJE!C$42,IF(G26=40,KILOMETRAJE!C$43,IF(G26=41,KILOMETRAJE!C$44,IF(G26=42,KILOMETRAJE!C$45,IF(G26=43,KILOMETRAJE!C$46,IF(G26=44,KILOMETRAJE!C$47,IF(G26=45,KILOMETRAJE!C$48,IF(G26=46,KILOMETRAJE!C$49,IF(G26=47,KILOMETRAJE!C$50,IF(G26=48,KILOMETRAJE!C$51,IF(G26=49,KILOMETRAJE!C$52,IF(G26=50,KILOMETRAJE!C$53,IF(G26=51,KILOMETRAJE!C$54,IF(G26=52,KILOMETRAJE!C$55,IF(G26=53,KILOMETRAJE!C$56,IF(G26=54,KILOMETRAJE!C$57,IF(G26=55,KILOMETRAJE!C$58,IF(G26=56,KILOMETRAJE!C$59,IF(G26=57,KILOMETRAJE!C$60,IF(G26=58,KILOMETRAJE!C$61,IF(G26=59,KILOMETRAJE!C$62,IF(G26=60,KILOMETRAJE!C$63,IF(G26=61,KILOMETRAJE!C$64,IF(G26=62,KILOMETRAJE!C$65,IF(G26=63,KILOMETRAJE!C$66))))))))))))))))))))))))))))))))))))))))))))))))))))))))))))))) -> CHIH. | I26: =IF(G26=1,KILOMETRAJE!E$4,IF(G26=2,KILOMETRAJE!E$5,IF(G26=3,KILOMETRAJE!E$6,IF(G26=4,KILOMETRAJE!E$7,IF(G26=5,KILOMETRAJE!E$8,IF(G26=6,KILOMETRAJE!E$9,IF(G26=7,KILOMETRAJE!E$10,IF(G26=8,KILOMETRAJE!E$11,IF(G26=9,KILOMETRAJE!E$12,IF(G26=10,KILOMETRAJE!E$13,IF(G26=11,KILOMETRAJE!E$14,IF(G26=12,KILOMETRAJE!E$15,IF(G26=13,KILOMETRAJE!E$16,IF(G26=14,KILOMETRAJE!E$17,IF(G26=15,KILOMETRAJE!E$18,IF(G26=16,KILOMETRAJE!E$19,IF(G26=17,KILOMETRAJE!E$20,IF(G26=18,KILOMETRAJE!E$21,IF(G26=19,KILOMETRAJE!E$22,IF(G26=20,KILOMETRAJE!E$23,IF(G26=21,KILOMETRAJE!E$24,IF(G26=22,KILOMETRAJE!E$25,IF(G26=23,KILOMETRAJE!E$26,IF(G26=24,KILOMETRAJE!E$27,IF(G26=25,KILOMETRAJE!E$28,IF(G26=26,KILOMETRAJE!E$29,IF(G26=27,KILOMETRAJE!E$30,IF(G26=28,KILOMETRAJE!E$31,IF(G26=29,KILOMETRAJE!E$32,IF(G26=30,KILOMETRAJE!E$33,IF(G26=31,KILOMETRAJE!E$34,IF(G26=32,KILOMETRAJE!E$35,IF(G26=33,KILOMETRAJE!E$36,IF(G26=34,KILOMETRAJE!E$37,IF(G26=35,KILOMETRAJE!E$38,IF(G26=36,KILOMETRAJE!E$39,IF(G26=37,KILOMETRAJE!E$40,IF(G26=38,KILOMETRAJE!E$41,IF(G26=39,KILOMETRAJE!E$42,IF(G26=40,KILOMETRAJE!E$43,IF(G26=41,KILOMETRAJE!E$44,IF(G26=42,KILOMETRAJE!E$45,IF(G26=43,KILOMETRAJE!E$46,IF(G26=44,KILOMETRAJE!E$47,IF(G26=45,KILOMETRAJE!E$48,IF(G26=46,KILOMETRAJE!E$49,IF(G26=47,KILOMETRAJE!E$50,IF(G26=48,KILOMETRAJE!E$51,IF(G26=49,KILOMETRAJE!E$52,IF(G26=50,KILOMETRAJE!E$53,IF(G26=51,KILOMETRAJE!E$54,IF(G26=52,KILOMETRAJE!E$55,IF(G26=53,KILOMETRAJE!E$56,IF(G26=54,KILOMETRAJE!E$57,IF(G26=55,KILOMETRAJE!E$58,IF(G26=56,KILOMETRAJE!E$59,IF(G26=57,KILOMETRAJE!E$60,IF(G26=58,KILOMETRAJE!E$61,IF(G26=59,KILOMETRAJE!E$62,IF(G26=60,KILOMETRAJE!E$63,IF(G26=61,KILOMETRAJE!E$64,IF(G26=62,KILOMETRAJE!E$65,IF(G26=63,KILOMETRAJE!E$66))))))))))))))))))))))))))))))))))))))))))))))))))))))))))))))) -> ELP | J26: =IF(G26=1,KILOMETRAJE!G$4,IF(G26=2,KILOMETRAJE!G$5,IF(G26=3,KILOMETRAJE!G$6,IF(G26=4,KILOMETRAJE!G$7,IF(G26=5,KILOMETRAJE!G$8,IF(G26=6,KILOMETRAJE!G$9,IF(G26=7,KILOMETRAJE!G$10,IF(G26=8,KILOMETRAJE!G$11,IF(G26=9,KILOMETRAJE!G$12,IF(G26=10,KILOMETRAJE!G$13,IF(G26=11,KILOMETRAJE!G$14,IF(G26=12,KILOMETRAJE!G$15,IF(G26=13,KILOMETRAJE!G$16,IF(G26=14,KILOMETRAJE!G$17,IF(G26=15,KILOMETRAJE!G$18,IF(G26=16,KILOMETRAJE!G$19,IF(G26=17,KILOMETRAJE!G$20,IF(G26=18,KILOMETRAJE!G$21,IF(G26=19,KILOMETRAJE!G$22,IF(G26=20,KILOMETRAJE!G$23,IF(G26=21,KILOMETRAJE!G$24,IF(G26=22,KILOMETRAJE!G$25,IF(G26=23,KILOMETRAJE!G$26,IF(G26=24,KILOMETRAJE!G$27,IF(G26=25,KILOMETRAJE!G$28,IF(G26=26,KILOMETRAJE!G$29,IF(G26=27,KILOMETRAJE!G$30,IF(G26=28,KILOMETRAJE!G$31,IF(G26=29,KILOMETRAJE!G$32,IF(G26=30,KILOMETRAJE!G$33,IF(G26=31,KILOMETRAJE!G$34,IF(G26=32,KILOMETRAJE!G$35,IF(G26=33,KILOMETRAJE!G$36,IF(G26=34,KILOMETRAJE!G$37,IF(G26=35,KILOMETRAJE!G$38,IF(G26=36,KILOMETRAJE!G$39,IF(G26=37,KILOMETRAJE!G$40,IF(G26=38,KILOMETRAJE!G$41,IF(G26=39,KILOMETRAJE!G$42,IF(G26=40,KILOMETRAJE!G$43,IF(G26=41,KILOMETRAJE!G$44,IF(G26=42,KILOMETRAJE!G$45,IF(G26=43,KILOMETRAJE!G$46,IF(G26=44,KILOMETRAJE!G$47,IF(G26=45,KILOMETRAJE!G$48,IF(G26=46,KILOMETRAJE!G$49,IF(G26=47,KILOMETRAJE!G$50,IF(G26=48,KILOMETRAJE!G$51,IF(G26=49,KILOMETRAJE!G$52,IF(G26=50,KILOMETRAJE!G$53,IF(G26=51,KILOMETRAJE!G$54,IF(G26=52,KILOMETRAJE!G$55,IF(G26=53,KILOMETRAJE!G$56,IF(G26=54,KILOMETRAJE!G$57,IF(G26=55,KILOMETRAJE!G$58,IF(G26=56,KILOMETRAJE!G$59,IF(G26=57,KILOMETRAJE!G$60,IF(G26=58,KILOMETRAJE!G$61,IF(G26=59,KILOMETRAJE!G$62,IF(G26=60,KILOMETRAJE!G$63,IF(G26=61,KILOMETRAJE!G$64,IF(G26=62,KILOMETRAJE!G$65,IF(G26=63,KILOMETRAJE!G$66))))))))))))))))))))))))))))))))))))))))))))))))))))))))))))))) -> 415 | K26: 196.071 | L26: =SUM(J25:J26)/K26 -> 4.0291527 | M26: 1413.46 | N26: 4 | O26: BS53757 | P26: G. AMERICAN | Q26: =((((IF(N26=1,((J26)*0.29333)))+(IF(N26=2,((J26)*0.146666)))+(IF(N26=3,((J26)*0.146666)))))+(IF(N26=4,((J26-40)*0.29333)))+(IF(N26=5,((J26-50)*0.29333)))+(IF(N26=6,((J26-90)*0.29333)))) -> 109.99875 | R26: =+LOOKUP(P43,UNIDADES!B$3:B$59,UNIDADES!C$3:C$59) -> 2.45098 | S26: =+((SUM(J25:J26)-40)/R26)-K26 -> 109.92905 | T26: =+S26*14.85 -> 1632.4464 | U26: 57 | V26: 57
E34: CRUCES | F34: 45936 | H34: =+F34+1 -> 45937 | I34: =+H34+1 -> 45938 | J34: =+I34+1 -> 45939 | K34: =+J34+1 -> 45940 | L34: =+K34+2 -> 45942 | M34: TOTAL.C
H35: 750 | I35: 750 | J35: 900 | K35: 500 | L35: 500 | M35: =SUM(F35:L35) -> 3400
C37: PERCEPCIONES DE LA SEMANA | O37: TOTAL: | Q37: =+F49-L46 -> 9671.0291
C38: PAGO POR KM | F38: =SUM(Q18:Q33) -> 769.992 | I38: CONCEPTO | J38: FECHA | K38: FOLIO | L38: MONTO
