Workbook
Name ANDRES: #REF!
Name ANDRES: #REF!
Name ANDRES: #REF!
Name ANDRES: #REF!
Name ANDRES: #REF!
Name ARON: #REF!
Name ARON: #REF!
Name AUX: #REF!
Name BASE: #REF!
Name COPIA: #REF!
Name COPIAA: #REF!
Name CRUCE: #REF!
Name CRUCES: #REF!
Name IGOB: #REF!
Name INCON: #REF!
Name MIRE: #REF!
Name MIRO: #REF!
Name NOM: #REF!
Name NOM.: #REF!
Name NOM.04: #REF!
Name NOMIN: #REF!
Name NOMINA: #REF!
Name NUEVO: #REF!
Name SEM.03: #REF!
Name SEM.03B: #REF!
Name SEM.03C: #REF!
Name SEM.03V: #REF!
Name SEM.04: #REF!
Name SEM.04.: #REF!
Name SEMANA.03: #REF!
Name SSEM.08: #REF!
Name TABLA3: #REF!
Name TABLA4: #REF!
Name TABLA7: #REF!
Name TABLA7.05: #REF!
Name TABLA7.08: #REF!
Name TABLA7.3: #REF!
Name TABLA7.31: #REF!
Name TABLA7.5: #REF!
Name TABLA8: #REF!

Sheet NOMINA
B1: FLETES SOTELO S.A. DE C.V.
B2: VIAJES FORANEOS JUAREZ - PACIFICO
B3: SEMANA #42 PERIODO DEL 06 AL 12 DE OCTUBRE DEL 2025
B4: # | C4: EMPLEADO | D4: VIAJES | E4: NO. DE REPORTE | I4: RENDIMIENTO
B5: 2639 | C5: CERDA HERNANDEZ JOSE LUIS | D5: =+'CERDA HERNANDEZ JOSE LUIS'!Q32 -> 8241.4434 | E5: =+'CERDA HERNANDEZ JOSE LUIS'!O35 -> 46372 | F5: =+'CERDA HERNANDEZ JOSE LUIS'!O36 -> 45938 | G5: =+'CERDA HERNANDEZ JOSE LUIS'!O37 -> 0 | H5: 0
B6: 2550 | C6: CHAVEZ VARELA NESTOR ADRIAN | D6: =+'CHAVEZ VARELA NESTOR ADRIAN'!Q32 -> 0 | E6: =+'CHAVEZ VARELA NESTOR ADRIAN'!O35 -> 0 | F6: =+'CHAVEZ VARELA NESTOR ADRIAN'!O36 -> 0 | G6: =+'CHAVEZ VARELA NESTOR ADRIAN'!O37 -> 0 | H6: 0
B7: 1987 | C7: ESCARCEGA GALDEAN JESUS OMAR | D7: =+'ESCARCEGA GALDEAN JESUS OMAR'!Q35 -> 0 | E7: =+'ESCARCEGA GALDEAN JESUS OMAR'!O38 -> 0 | F7: =+'ESCARCEGA GALDEAN JESUS OMAR'!O39 -> 0 | G7: =+'ESCARCEGA GALDEAN JESUS OMAR'!O40 -> 0 | H7: 0
B8: 1538 | C8: ESTRADA ARELLANO ARTURO | D8: =+'ESTRADA ARELLANO ARTURO'!Q37 -> 0 | E8: =+'ESTRADA ARELLANO ARTURO'!O40 -> 0 | F8: =+'ESTRADA ARELLANO ARTURO'!O41 -> 0 | G8: =+'ESTRADA ARELLANO ARTURO'!O42 -> 0 | H8: 0
B9: 2647 | C9: GONZALEZ LOZANO ENRIQUE | D9: =+'GONZALEZ LOZANO ENRIQUE '!Q35 -> 0 | E9: =+'GONZALEZ LOZANO ENRIQUE '!O38 -> 0 | F9: =+'GONZALEZ LOZANO ENRIQUE '!O39 -> 0 | G9: =+'GONZALEZ LOZANO ENRIQUE '!O40 -> 0 | H9: 0
B10: 2492 | C10: GONZALEZ MARTINEZ MAURICIO | D10: =+'GONZALEZ MARTINEZ MAURICIO'!Q35 -> 10550.954 | E10: =+'GONZALEZ MARTINEZ MAURICIO'!O38 -> 46388 | F10: =+'GONZALEZ MARTINEZ MAURICIO'!O39 -> 45958 | G10: =+'GONZALEZ MARTINEZ MAURICIO'!O40 -> 0 | H10: 0
B11: 1794 | C11: GONZALEZ SOTO JOEL | D11: =+'GONZALEZ SOTO JOEL'!Q36 -> 0 | E11: =+'GONZALEZ SOTO JOEL'!O39 -> 0 | F11: =+'GONZALEZ SOTO JOEL'!O40 -> 0 | G11: =+'GONZALEZ SOTO JOEL'!O41 -> 0 | H11: 0
C12: GRIJALVA VALDEZ CESAR EUSEBIO | D12: =+'GRIJALVA VALDEZ CESAR EUSEBIO'!Q32 -> 0 | E12: =+'GRIJALVA VALDEZ CESAR EUSEBIO'!O35 -> 0 | F12: =+'GRIJALVA VALDEZ CESAR EUSEBIO'!O36 -> 0 | G12: =+'GRIJALVA VALDEZ CESAR EUSEBIO'!O37 -> 0 | H12: 0
B13: 1067 | C13: TORRES GARAY LUIS HUMBERTO | D13: =+'TORRES GARAY LUIS HUMBERTO'!Q35 -> 7348.9268 | E13: =+'TORRES GARAY LUIS HUMBERTO'!O38 -> 45910 | F13: =+'TORRES GARAY LUIS HUMBERTO'!O39 -> 0 | G13: =+'TORRES GARAY LUIS HUMBERTO'!O40 -> 0 | H13: 0
C14: GUZMAN MORALES ALFREDO | D14: =+'GUZMAN MORALES'!Q37 -> 0 | E14: =+'GUZMAN MORALES'!O40 -> 0 | F14: =+'GUZMAN MORALES'!O41 -> 0 | G14: =+'GUZMAN MORALES'!O42 -> 0 | H14: 0
C15: HARO IMPERIAL JOSÉ ANTONIO | D15: =+'HARO IMPERIAL JOSÉ ANTONIO'!Q38 -> 9514.2581 | E15: =+'HARO IMPERIAL JOSÉ ANTONIO'!O41 -> 46391 | F15: =+'HARO IMPERIAL JOSÉ ANTONIO'!O42 -> 45969 | G15: =+'HARO IMPERIAL JOSÉ ANTONIO'!O43 -> 0 | H15: 0
B16: 2476 | C16: HERNANDEZ CONTRERAS JOSE FERNANDO | D16: =+'HERNANDEZ CONTRERAS JOSE FERNAN'!Q34 -> 11026.735 | E16: =+'HERNANDEZ CONTRERAS JOSE FERNAN'!O37 -> 46389 | F16: =+'HERNANDEZ CONTRERAS JOSE FERNAN'!O38 -> 45942 | G16: =+'HERNANDEZ CONTRERAS JOSE FERNAN'!O39 -> 0 | H16: 0
B17: 1536 | C17: LIRA TRISTAN JOSE ANGEL | D17: =+'LIRA TRISTAN JOSE ANGEL'!Q33 -> 10526.391 | E17: =+'LIRA TRISTAN JOSE ANGEL'!O36 -> 46369 | F17: =+'LIRA TRISTAN JOSE ANGEL'!O37 -> 45943 | G17: =+'LIRA TRISTAN JOSE ANGEL'!O38 -> 0 | H17: 0
B18: 1658 | C18: MARTA RUBIO MARTIN | D18: =+'MARTA RUBIO MARTIN'!Q36 -> 0 | E18: =+'MARTA RUBIO MARTIN'!O39 -> 0 | F18: =+'MARTA RUBIO MARTIN'!O40 -> 0 | G18: =+'MARTA RUBIO MARTIN'!O41 -> 0 | H18: 0
B19: 0186 | C19: NEVAREZ JUAN MANUEL | D19: =+'NEVAREZ JUAN MANUEL'!Q34 -> 10047.735 | E19: =+'NEVAREZ JUAN MANUEL'!O37 -> 46375 | F19: =+'NEVAREZ JUAN MANUEL'!O38 -> 45929 | G19: =+'NEVAREZ JUAN MANUEL'!O39 -> 0 | H19: 0
B20: 2316 | C20: PACHECO BAÑUELOS ALFONSO | D20: =+'PACHECO BAÑUELOS ALFONSO'!Q36 -> 3841.7004 | E20: =+'PACHECO BAÑUELOS ALFONSO'!O39 -> 45957 | F20: =+'PACHECO BAÑUELOS ALFONSO'!O40 -> 0 | G20: =+'PACHECO BAÑUELOS ALFONSO'!O41 -> 0 | H20: 0
B21: 2173 | C21: PAYAN ESTRADA JOSE ANGEL | D21: =+'PAYAN ESTRADA JOSE ANGEL'!Q34 -> 0 | E21: =+'PAYAN ESTRADA JOSE ANGEL'!O37 -> 0 | F21: =+'PAYAN ESTRADA JOSE ANGEL'!O38 -> 0 | G21: =+'PAYAN ESTRADA JOSE ANGEL'!O39 -> 0 | H21: 0
B22: 1633 | C22: RODRIGUEZ RAMIREZ FERNANDO | D22: =+'RODRIGUEZ RAMIREZ FERNANDO'!Q32 -> 19386.997 | E22: =+'RODRIGUEZ RAMIREZ FERNANDO'!O35 -> 46368 | F22: =+'RODRIGUEZ RAMIREZ FERNANDO'!O36 -> 45909 | G22: =+'RODRIGUEZ RAMIREZ FERNANDO'!O37 -> 0 | H22: 0
B23: 0235 | C23: RODRIGUEZ VALLES JOSE FRANCISCO | D23: =+'RODRIGUEZ VALLES JOSE FRANCISCO'!Q37 -> 9907.5907 | E23: =+'RODRIGUEZ VALLES JOSE FRANCISCO'!O40 -> 46370 | F23: =+'RODRIGUEZ VALLES JOSE FRANCISCO'!O41 -> 45941 | G23: =+'RODRIGUEZ VALLES JOSE FRANCISCO'!O42 -> 0 | H23: 0
B24: 2078 | C24: RUEDA SALAZAR ISMAEL | D24: =+'RUEDA SALAZAR ISMAEL'!Q32 -> 9829.035 | E24: =+'RUEDA SALAZAR ISMAEL'!O35 -> 46371 | F24: =+'RUEDA SALAZAR ISMAEL'!O36 -> 45923 | G24: =+'RUEDA SALAZAR ISMAEL'!O37 -> 45937 | H24: 45970
C25: RUIZ ALVARADO PEDRO | D25: =+'RUIZ ALVARADO PEDRO'!Q29 -> 8374.8666 | E25: =+'RUIZ ALVARADO PEDRO'!O32 -> 45939 | F25: =+'RUIZ ALVARADO PEDRO'!O33 -> 45972 | G25: =+'RUIZ ALVARADO PEDRO'!O34 -> 0 | H25: 0
C26: RUIZ HERRERA ERICK | D26: =+'RUIZ HERRERA ERICK '!Q30 -> 0 | E26: =+'RUIZ HERRERA ERICK '!O33 -> 45940 | F26: =+'RUIZ HERRERA ERICK '!O34 -> 45973 | G26: =+'RUIZ HERRERA ERICK '!O35 -> 0 | H26: 0
B27: 2474 | C27: SALAZAR PEREZ JUAN CARLOS | D27: =+'SALAZAR PEREZ JUAN CARLOS'!Q35 -> 0 | E27: =+'SALAZAR PEREZ JUAN CARLOS'!O38 -> 0 | F27: =+'SALAZAR PEREZ JUAN CARLOS'!O39 -> 0 | G27: =+'SALAZAR PEREZ JUAN CARLOS'!O40 -> 0 | H27: 0
B28: 2293 | C28: SANCHEZ GUERRERO JOSE LUIS | D28: =+'SANCHEZ GUERRERO JOSE LUIS'!Q37 -> 0 | E28: =+'SANCHEZ GUERRERO JOSE LUIS'!O40 -> 0 | F28: =+'SANCHEZ GUERRERO JOSE LUIS'!O41 -> 0 | G28: =+'SANCHEZ GUERRERO JOSE LUIS'!O42 -> 0 | H28: 0
C29: TOTAL | D29: =SUM(D5:D28) -> 118596.63
D31: =+D22+D21+D20+D18+D15+D14+D10+D7 -> 43293.91
D33: =+D28+D23+D22+D27+D20+D24+D25+D18+D15+D16+D11+D10+D9+D7+D12 -> 82432.137

Sheet CHAVEZ VARELA NESTOR ADRIAN
Q2: SEMANA:
I3: FLETES SOTELO S.A DE C.V | Q3: 42
I4: RFC: FSO880915JP8
I5: CAMINO DE LOS ESTEROS 720 | Q5: FOLIO DE LIQUIDACION
I6: PARTIDO DOBALDO CD.JUAREZ CHIHU. | Q6: 1
I9: INFORMACION DEL OPERADOR
D11: OPERADOR: | E11: CHAVEZ VARELA NESTOR ADRIAN | K11: FECHA DE PERIODO: | L11: =+NOMINA!B3 -> SEMANA #42 PERIODO DEL 06 AL 12 DE OCTUBRE DEL 2025
D12: UNIDAD: | E12: F-112
D14: ODOM.INIC: | F14: 225171 | I14: COMBUSTIBLE INICI: | O14: COMBUSTIBLE CARGADO:
D15: ODOM.FINAL: | F15: 227165 | I15: COMBUSTIBLE FIN: | O15: DIF. DE DIESEL:
D16: KM RECORRIDOS: | F16: =SUM(J19:J27) -> 0 | I16: DIESEL CONSUMIDO: | J16: =SUM(K19:K27) -> 0 | O16: RENDIMIENTO: | P16: =+F16/J16 -> #DIV/0!
C18: FOLIO LIQUIDACION | D18: CORDENADA | E18: FECHA SALIDA | F18: FECHA LLEGADA | G18: R: | H18: ORIGEN | I18: DESTINO | J18: KMS | K18: RECARGA | L18: RENDIMIENTO | M18: REN.PAGO | N18: C / V / PT | O18: REMOLQUE | P18: CLIENTE | Q18: PAGO POR KM | R18: RENDIMIENTO PAGO | S18: LITROS A PAGO | T18: DIESEL A FAVOR
H19: =IF(G19=1,KILOMETRAJE!C$4,IF(G19=2,KILOMETRAJE!C$5,IF(G19=3,KILOMETRAJE!C$6,IF(G19=4,KILOMETRAJE!C$7,IF(G19=5,KILOMETRAJE!C$8,IF(G19=6,KILOMETRAJE!C$9,IF(G19=7,KILOMETRAJE!C$10,IF(G19=8,KILOMETRAJE!C$11,IF(G19=9,KILOMETRAJE!C$12,IF(G19=10,KILOMETRAJE!C$13,IF(G19=11,KILOMETRAJE!C$14,IF(G19=12,KILOMETRAJE!C$15,IF(G19=13,KILOMETRAJE!C$16,IF(G19=14,KILOMETRAJE!C$17,IF(G19=15,KILOMETRAJE!C$18,IF(G19=16,KILOMETRAJE!C$19,IF(G19=17,KILOMETRAJE!C$20,IF(G19=18,KILOMETRAJE!C$21,IF(G19=19,KILOMETRAJE!C$22,IF(G19=20,KILOMETRAJE!C$23,IF(G19=21,KILOMETRAJE!C$24,IF(G19=22,KILOMETRAJE!C$25,IF(G19=23,KILOMETRAJE!C$26,IF(G19=24,KILOMETRAJE!C$27,IF(G19=25,KILOMETRAJE!C$28,IF(G19=26,KILOMETRAJE!C$29,IF(G19=27,KILOMETRAJE!C$30,IF(G19=28,KILOMETRAJE!C$31,IF(G19=29,KILOMETRAJE!C$32,IF(G19=30,KILOMETRAJE!C$33,IF(G19=31,KILOMETRAJE!C$34,IF(G19=32,KILOMETRAJE!C$35,IF(G19=33,KILOMETRAJE!C$36,IF(G19=34,KILOMETRAJE!C$37,IF(G19=35,KILOMETRAJE!C$38,IF(G19=36,KILOMETRAJE!C$39,IF(G19=37,KILOMETRAJE!C$40,IF(G19=38,KILOMETRAJE!C$41,IF(G19=39,KILOMETRAJE!C$42,IF(G19=40,KILOMETRAJE!C$43,IF(G19=41,KILOMETRAJE!C$44,IF(G19=42,KILOMETRAJE!C$45,IF(G19=43,KILOMETRAJE!C$46,IF(G19=44,KILOMETRAJE!C$47,IF(G19=45,KILOMETRAJE!C$48,IF(G19=46,KILOMETRAJE!C$49,IF(G19=47,KILOMETRAJE!C$50,IF(G19=48,KILOMETRAJE!C$51,IF(G19=49,KILOMETRAJE!C$52,IF(G19=50,KILOMETRAJE!C$53,IF(G19=51,KILOMETRAJE!C$54,IF(G19=52,KILOMETRAJE!C$55,IF(G19=53,KILOMETRAJE!C$56,IF(G19=54,KILOMETRAJE!C$57,IF(G19=55,KILOMETRAJE!C$58,IF(G19=56,KILOMETRAJE!C$59,IF(G19=57,KILOMETRAJE!C$60,IF(G19=58,KILOMETRAJE!C$61,IF(G19=59,KILOMETRAJE!C$62,IF(G19=60,KILOMETRAJE!C$63,IF(G19=61,KILOMETRAJE!C$64,IF(G19=62,KILOMETRAJE!C$65)))))))))))))))))))))))))))))))))))))))))))))))))))))))))))))) -> FALSE | I19: =IF(G19=1,KILOMETRAJE!E$4,IF(G19=2,KILOMETRAJE!E$5,IF(G19=3,KILOMETRAJE!E$6,IF(G19=4,KILOMETRAJE!E$7,IF(G19=5,KILOMETRAJE!E$8,IF(G19=6,KILOMETRAJE!E$9,IF(G19=7,KILOMETRAJE!E$10,IF(G19=8,KILOMETRAJE!E$11,IF(G19=9,KILOMETRAJE!E$12,IF(G19=10,KILOMETRAJE!E$13,IF(G19=11,KILOMETRAJE!E$14,IF(G19=12,KILOMETRAJE!E$15,IF(G19=13,KILOMETRAJE!E$16,IF(G19=14,KILOMETRAJE!E$17,IF(G19=15,KILOMETRAJE!E$18,IF(G19=16,KILOMETRAJE!E$19,IF(G19=17,KILOMETRAJE!E$20,IF(G19=18,KILOMETRAJE!E$21,IF(G19=19,KILOMETRAJE!E$22,IF(G19=20,KILOMETRAJE!E$23,IF(G19=21,KILOMETRAJE!E$24,IF(G19=22,KILOMETRAJE!E$25,IF(G19=23,KILOMETRAJE!E$26,IF(G19=24,KILOMETRAJE!E$27,IF(G19=25,KILOMETRAJE!E$28,IF(G19=26,KILOMETRAJE!E$29,IF(G19=27,KILOMETRAJE!E$30,IF(G19=28,KILOMETRAJE!E$31,IF(G19=29,KILOMETRAJE!E$32,IF(G19=30,KILOMETRAJE!E$33,IF(G19=31,KILOMETRAJE!E$34,IF(G19=32,KILOMETRAJE!E$35,IF(G19=33,KILOMETRAJE!E$36,IF(G19=34,KILOMETRAJE!E$37,IF(G19=35,KILOMETRAJE!E$38,IF(G19=36,KILOMETRAJE!E$39,IF(G19=37,KILOMETRAJE!E$40,IF(G19=38,KILOMETRAJE!E$41,IF(G19=39,KILOMETRAJE!E$42,IF(G19=40,KILOMETRAJE!E$43,IF(G19=41,KILOMETRAJE!E$44,IF(G19=42,KILOMETRAJE!E$45,IF(G19=43,KILOMETRAJE!E$46,IF(G19=44,KILOMETRAJE!E$47,IF(G19=45,KILOMETRAJE!E$48,IF(G19=46,KILOMETRAJE!E$49,IF(G19=47,KILOMETRAJE!E$50,IF(G19=48,KILOMETRAJE!E$51,IF(G19=49,KILOMETRAJE!E$52,IF(G19=50,KILOMETRAJE!E$53,IF(G19=51,KILOMETRAJE!E$54,IF(G19=52,KILOMETRAJE!E$55,IF(G19=53,KILOMETRAJE!E$56,IF(G19=54,KILOMETRAJE!E$57,IF(G19=55,KILOMETRAJE!E$58,IF(G19=56,KILOMETRAJE!E$59,IF(G19=57,KILOMETRAJE!E$60,IF(G19=58,KILOMETRAJE!E$61,IF(G19=59,KILOMETRAJE!E$62,IF(G19=60,KILOMETRAJE!E$63,IF(G19=61,KILOMETRAJE!E$64,IF(G19=62,KILOMETRAJE!E$65)))))))))))))))))))))))))))))))))))))))))))))))))))))))))))))) -> FALSE | J19: =IF(G19=1,KILOMETRAJE!G$4,IF(G19=2,KILOMETRAJE!G$5,IF(G19=3,KILOMETRAJE!G$6,IF(G19=4,KILOMETRAJE!G$7,IF(G19=5,KILOMETRAJE!G$8,IF(G19=6,KILOMETRAJE!G$9,IF(G19=7,KILOMETRAJE!G$10,IF(G19=8,KILOMETRAJE!G$11,IF(G19=9,KILOMETRAJE!G$12,IF(G19=10,KILOMETRAJE!G$13,IF(G19=11,KILOMETRAJE!G$14,IF(G19=12,KILOMETRAJE!G$15,IF(G19=13,KILOMETRAJE!G$16,IF(G19=14,KILOMETRAJE!G$17,IF(G19=15,KILOMETRAJE!G$18,IF(G19=16,KILOMETRAJE!G$19,IF(G19=17,KILOMETRAJE!G$20,IF(G19=18,KILOMETRAJE!G$21,IF(G19=19,KILOMETRAJE!G$22,IF(G19=20,KILOMETRAJE!G$23,IF(G19=21,KILOMETRAJE!G$24,IF(G19=22,KILOMETRAJE!G$25,IF(G19=23,KILOMETRAJE!G$26,IF(G19=24,KILOMETRAJE!G$27,IF(G19=25,KILOMETRAJE!G$28,IF(G19=26,KILOMETRAJE!G$29,IF(G19=27,KILOMETRAJE!G$30,IF(G19=28,KILOMETRAJE!G$31,IF(G19=29,KILOMETRAJE!G$32,IF(G19=30,KILOMETRAJE!G$33,IF(G19=31,KILOMETRAJE!G$34,IF(G19=32,KILOMETRAJE!G$35,IF(G19=33,KILOMETRAJE!G$36,IF(G19=34,KILOMETRAJE!G$37,IF(G19=35,KILOMETRAJE!G$38,IF(G19=36,KILOMETRAJE!G$39,IF(G19=37,KILOMETRAJE!G$40,IF(G19=38,KILOMETRAJE!G$41,IF(G19=39,KILOMETRAJE!G$42,IF(G19=40,KILOMETRAJE!G$43,IF(G19=41,KILOMETRAJE!G$44,IF(G19=42,KILOMETRAJE!G$45,IF(G19=43,KILOMETRAJE!G$46,IF(G19=44,KILOMETRAJE!G$47,IF(G19=45,KILOMETRAJE!G$48,IF(G19=46,KILOMETRAJE!G$49,IF(G19=47,KILOMETRAJE!G$50,IF(G19=48,KILOMETRAJE!G$51,IF(G19=49,KILOMETRAJE!G$52,IF(G19=50,KILOMETRAJE!G$53,IF(G19=51,KILOMETRAJE!G$54,IF(G19=52,KILOMETRAJE!G$55,IF(G19=53,KILOMETRAJE!G$56,IF(G19=54,KILOMETRAJE!G$57,IF(G19=55,KILOMETRAJE!G$58,IF(G19=56,KILOMETRAJE!G$59,IF(G19=57,KILOMETRAJE!G$60,IF(G19=58,KILOMETRAJE!G$61,IF(G19=59,KILOMETRAJE!G$62,IF(G19=60,KILOMETRAJE!G$63,IF(G19=61,KILOMETRAJE!G$64,IF(G19=62,KILOMETRAJE!G$65)))))))))))))))))))))))))))))))))))))))))))))))))))))))))))))) -> FALSE | Q19: =(IF(N19=1,(J19*0.3)))+(IF(N19=2,(J19*0.15))+(IF(N19=3,(J19*0.15)))) -> 0
H20: =IF(G20=1,KILOMETRAJE!C$4,IF(G20=2,KILOMETRAJE!C$5,IF(G20=3,KILOMETRAJE!C$6,IF(G20=4,KILOMETRAJE!C$7,IF(G20=5,KILOMETRAJE!C$8,IF(G20=6,KILOMETRAJE!C$9,IF(G20=7,KILOMETRAJE!C$10,IF(G20=8,KILOMETRAJE!C$11,IF(G20=9,KILOMETRAJE!C$12,IF(G20=10,KILOMETRAJE!C$13,IF(G20=11,KILOMETRAJE!C$14,IF(G20=12,KILOMETRAJE!C$15,IF(G20=13,KILOMETRAJE!C$16,IF(G20=14,KILOMETRAJE!C$17,IF(G20=15,KILOMETRAJE!C$18,IF(G20=16,KILOMETRAJE!C$19,IF(G20=17,KILOMETRAJE!C$20,IF(G20=18,KILOMETRAJE!C$21,IF(G20=19,KILOMETRAJE!C$22,IF(G20=20,KILOMETRAJE!C$23,IF(G20=21,KILOMETRAJE!C$24,IF(G20=22,KILOMETRAJE!C$25,IF(G20=23,KILOMETRAJE!C$26,IF(G20=24,KILOMETRAJE!C$27,IF(G20=25,KILOMETRAJE!C$28,IF(G20=26,KILOMETRAJE!C$29,IF(G20=27,KILOMETRAJE!C$30,IF(G20=28,KILOMETRAJE!C$31,IF(G20=29,KILOMETRAJE!C$32,IF(G20=30,KILOMETRAJE!C$33,IF(G20=31,KILOMETRAJE!C$34,IF(G20=32,KILOMETRAJE!C$35,IF(G20=33,KILOMETRAJE!C$36,IF(G20=34,KILOMETRAJE!C$37,IF(G20=35,KILOMETRAJE!C$38,IF(G20=36,KILOMETRAJE!C$39,IF(G20=37,KILOMETRAJE!C$40,IF(G20=38,KILOMETRAJE!C$41,IF(G20=39,KILOMETRAJE!C$42,IF(G20=40,KILOMETRAJE!C$43,IF(G20=41,KILOMETRAJE!C$44,IF(G20=42,KILOMETRAJE!C$45,IF(G20=43,KILOMETRAJE!C$46,IF(G20=44,KILOMETRAJE!C$47,IF(G20=45,KILOMETRAJE!C$48,IF(G20=46,KILOMETRAJE!C$49,IF(G20=47,KILOMETRAJE!C$50,IF(G20=48,KILOMETRAJE!C$51,IF(G20=49,KILOMETRAJE!C$52,IF(G20=50,KILOMETRAJE!C$53,IF(G20=51,KILOMETRAJE!C$54,IF(G20=52,KILOMETRAJE!C$55,IF(G20=53,KILOMETRAJE!C$56,IF(G20=54,KILOMETRAJE!C$57,IF(G20=55,KILOMETRAJE!C$58,IF(G20=56,KILOMETRAJE!C$59,IF(G20=57,KILOMETRAJE!C$60,IF(G20=58,KILOMETRAJE!C$61,IF(G20=59,KILOMETRAJE!C$62,IF(G20=60,KILOMETRAJE!C$63,IF(G20=61,KILOMETRAJE!C$64,IF(G20=62,KILOMETRAJE!C$65)))))))))))))))))))))))))))))))))))))))))))))))))))))))))))))) -> FALSE | I20: =IF(G20=1,KILOMETRAJE!E$4,IF(G20=2,KILOMETRAJE!E$5,IF(G20=3,KILOMETRAJE!E$6,IF(G20=4,KILOMETRAJE!E$7,IF(G20=5,KILOMETRAJE!E$8,IF(G20=6,KILOMETRAJE!E$9,IF(G20=7,KILOMETRAJE!E$10,IF(G20=8,KILOMETRAJE!E$11,IF(G20=9,KILOMETRAJE!E$12,IF(G20=10,KILOMETRAJE!E$13,IF(G20=11,KILOMETRAJE!E$14,IF(G20=12,KILOMETRAJE!E$15,IF(G20=13,KILOMETRAJE!E$16,IF(G20=14,KILOMETRAJE!E$17,IF(G20=15,KILOMETRAJE!E$18,IF(G20=16,KILOMETRAJE!E$19,IF(G20=17,KILOMETRAJE!E$20,IF(G20=18,KILOMETRAJE!E$21,IF(G20=19,KILOMETRAJE!E$22,IF(G20=20,KILOMETRAJE!E$23,IF(G20=21,KILOMETRAJE!E$24,IF(G20=22,KILOMETRAJE!E$25,IF(G20=23,KILOMETRAJE!E$26,IF(G20=24,KILOMETRAJE!E$27,IF(G20=25,KILOMETRAJE!E$28,IF(G20=26,KILOMETRAJE!E$29,IF(G20=27,KILOMETRAJE!E$30,IF(G20=28,KILOMETRAJE!E$31,IF(G20=29,KILOMETRAJE!E$32,IF(G20=30,KILOMETRAJE!E$33,IF(G20=31,KILOMETRAJE!E$34,IF(G20=32,KILOMETRAJE!E$35,IF(G20=33,KILOMETRAJE!E$36,IF(G20=34,KILOMETRAJE!E$37,IF(G20=35,KILOMETRAJE!E$38,IF(G20=36,KILOMETRAJE!E$39,IF(G20=37,KILOMETRAJE!E$40,IF(G20=38,KILOMETRAJE!E$41,IF(G20=39,KILOMETRAJE!E$42,IF(G20=40,KILOMETRAJE!E$43,IF(G20=41,KILOMETRAJE!E$44,IF(G20=42,KILOMETRAJE!E$45,IF(G20=43,KILOMETRAJE!E$46,IF(G20=44,KILOMETRAJE!E$47,IF(G20=45,KILOMETRAJE!E$48,IF(G20=46,KILOMETRAJE!E$49,IF(G20=47,KILOMETRAJE!E$50,IF(G20=48,KILOMETRAJE!E$51,IF(G20=49,KILOMETRAJE!E$52,IF(G20=50,KILOMETRAJE!E$53,IF(G20=51,KILOMETRAJE!E$54,IF(G20=52,KILOMETRAJE!E$55,IF(G20=53,KILOMETRAJE!E$56,IF(G20=54,KILOMETRAJE!E$57,IF(G20=55,KILOMETRAJE!E$58,IF(G20=56,KILOMETRAJE!E$59,IF(G20=57,KILOMETRAJE!E$60,IF(G20=58,KILOMETRAJE!E$61,IF(G20=59,KILOMETRAJE!E$62,IF(G20=60,KILOMETRAJE!E$63,IF(G20=61,KILOMETRAJE!E$64,IF(G20=62,KILOMETRAJE!E$65)))))))))))))))))))))))))))))))))))))))))))))))))))))))))))))) -> FALSE | J20: =IF(G20=1,KILOMETRAJE!G$4,IF(G20=2,KILOMETRAJE!G$5,IF(G20=3,KILOMETRAJE!G$6,IF(G20=4,KILOMETRAJE!G$7,IF(G20=5,KILOMETRAJE!G$8,IF(G20=6,KILOMETRAJE!G$9,IF(G20=7,KILOMETRAJE!G$10,IF(G20=8,KILOMETRAJE!G$11,IF(G20=9,KILOMETRAJE!G$12,IF(G20=10,KILOMETRAJE!G$13,IF(G20=11,KILOMETRAJE!G$14,IF(G20=12,KILOMETRAJE!G$15,IF(G20=13,KILOMETRAJE!G$16,IF(G20=14,KILOMETRAJE!G$17,IF(G20=15,KILOMETRAJE!G$18,IF(G20=16,KILOMETRAJE!G$19,IF(G20=17,KILOMETRAJE!G$20,IF(G20=18,KILOMETRAJE!G$21,IF(G20=19,KILOMETRAJE!G$22,IF(G20=20,KILOMETRAJE!G$23,IF(G20=21,KILOMETRAJE!G$24,IF(G20=22,KILOMETRAJE!G$25,IF(G20=23,KILOMETRAJE!G$26,IF(G20=24,KILOMETRAJE!G$27,IF(G20=25,KILOMETRAJE!G$28,IF(G20=26,KILOMETRAJE!G$29,IF(G20=27,KILOMETRAJE!G$30,IF(G20=28,KILOMETRAJE!G$31,IF(G20=29,KILOMETRAJE!G$32,IF(G20=30,KILOMETRAJE!G$33,IF(G20=31,KILOMETRAJE!G$34,IF(G20=32,KILOMETRAJE!G$35,IF(G20=33,KILOMETRAJE!G$36,IF(G20=34,KILOMETRAJE!G$37,IF(G20=35,KILOMETRAJE!G$38,IF(G20=36,KILOMETRAJE!G$39,IF(G20=37,KILOMETRAJE!G$40,IF(G20=38,KILOMETRAJE!G$41,IF(G20=39,KILOMETRAJE!G$42,IF(G20=40,KILOMETRAJE!G$43,IF(G20=41,KILOMETRAJE!G$44,IF(G20=42,KILOMETRAJE!G$45,IF(G20=43,KILOMETRAJE!G$46,IF(G20=44,KILOMETRAJE!G$47,IF(G20=45,KILOMETRAJE!G$48,IF(G20=46,KILOMETRAJE!G$49,IF(G20=47,KILOMETRAJE!G$50,IF(G20=48,KILOMETRAJE!G$51,IF(G20=49,KILOMETRAJE!G$52,IF(G20=50,KILOMETRAJE!G$53,IF(G20=51,KILOMETRAJE!G$54,IF(G20=52,KILOMETRAJE!G$55,IF(G20=53,KILOMETRAJE!G$56,IF(G20=54,KILOMETRAJE!G$57,IF(G20=55,KILOMETRAJE!G$58,IF(G20=56,KILOMETRAJE!G$59,IF(G20=57,KILOMETRAJE!G$60,IF(G20=58,KILOMETRAJE!G$61,IF(G20=59,KILOMETRAJE!G$62,IF(G20=60,KILOMETRAJE!G$63,IF(G20=61,KILOMETRAJE!G$64,IF(G20=62,KILOMETRAJE!G$65)))))))))))))))))))))))))))))))))))))))))))))))))))))))))))))) -> FALSE | Q20: =(IF(N20=1,(J20*0.3)))+(IF(N20=2,(J20*0.15))+(IF(N20=3,(J20*0.15)))) -> 0
H21: =IF(G21=1,KILOMETRAJE!C$4,IF(G21=2,KILOMETRAJE!C$5,IF(G21=3,KILOMETRAJE!C$6,IF(G21=4,KILOMETRAJE!C$7,IF(G21=5,KILOMETRAJE!C$8,IF(G21=6,KILOMETRAJE!C$9,IF(G21=7,KILOMETRAJE!C$10,IF(G21=8,KILOMETRAJE!C$11,IF(G21=9,KILOMETRAJE!C$12,IF(G21=10,KILOMETRAJE!C$13,IF(G21=11,KILOMETRAJE!C$14,IF(G21=12,KILOMETRAJE!C$15,IF(G21=13,KILOMETRAJE!C$16,IF(G21=14,KILOMETRAJE!C$17,IF(G21=15,KILOMETRAJE!C$18,IF(G21=16,KILOMETRAJE!C$19,IF(G21=17,KILOMETRAJE!C$20,IF(G21=18,KILOMETRAJE!C$21,IF(G21=19,KILOMETRAJE!C$22,IF(G21=20,KILOMETRAJE!C$23,IF(G21=21,KILOMETRAJE!C$24,IF(G21=22,KILOMETRAJE!C$25,IF(G21=23,KILOMETRAJE!C$26,IF(G21=24,KILOMETRAJE!C$27,IF(G21=25,KILOMETRAJE!C$28,IF(G21=26,KILOMETRAJE!C$29,IF(G21=27,KILOMETRAJE!C$30,IF(G21=28,KILOMETRAJE!C$31,IF(G21=29,KILOMETRAJE!C$32,IF(G21=30,KILOMETRAJE!C$33,IF(G21=31,KILOMETRAJE!C$34,IF(G21=32,KILOMETRAJE!C$35,IF(G21=33,KILOMETRAJE!C$36,IF(G21=34,KILOMETRAJE!C$37,IF(G21=35,KILOMETRAJE!C$38,IF(G21=36,KILOMETRAJE!C$39,IF(G21=37,KILOMETRAJE!C$40,IF(G21=38,KILOMETRAJE!C$41,IF(G21=39,KILOMETRAJE!C$42,IF(G21=40,KILOMETRAJE!C$43,IF(G21=41,KILOMETRAJE!C$44,IF(G21=42,KILOMETRAJE!C$45,IF(G21=43,KILOMETRAJE!C$46,IF(G21=44,KILOMETRAJE!C$47,IF(G21=45,KILOMETRAJE!C$48,IF(G21=46,KILOMETRAJE!C$49,IF(G21=47,KILOMETRAJE!C$50,IF(G21=48,KILOMETRAJE!C$51,IF(G21=49,KILOMETRAJE!C$52,IF(G21=50,KILOMETRAJE!C$53,IF(G21=51,KILOMETRAJE!C$54,IF(G21=52,KILOMETRAJE!C$55,IF(G21=53,KILOMETRAJE!C$56,IF(G21=54,KILOMETRAJE!C$57,IF(G21=55,KILOMETRAJE!C$58,IF(G21=56,KILOMETRAJE!C$59,IF(G21=57,KILOMETRAJE!C$60,IF(G21=58,KILOMETRAJE!C$61,IF(G21=59,KILOMETRAJE!C$62,IF(G21=60,KILOMETRAJE!C$63,IF(G21=61,KILOMETRAJE!C$64,IF(G21=62,KILOMETRAJE!C$65)))))))))))))))))))))))))))))))))))))))))))))))))))))))))))))) -> FALSE | I21: =IF(G21=1,KILOMETRAJE!E$4,IF(G21=2,KILOMETRAJE!E$5,IF(G21=3,KILOMETRAJE!E$6,IF(G21=4,KILOMETRAJE!E$7,IF(G21=5,KILOMETRAJE!E$8,IF(G21=6,KILOMETRAJE!E$9,IF(G21=7,KILOMETRAJE!E$10,IF(G21=8,KILOMETRAJE!E$11,IF(G21=9,KILOMETRAJE!E$12,IF(G21=10,KILOMETRAJE!E$13,IF(G21=11,KILOMETRAJE!E$14,IF(G21=12,KILOMETRAJE!E$15,IF(G21=13,KILOMETRAJE!E$16,IF(G21=14,KILOMETRAJE!E$17,IF(G21=15,KILOMETRAJE!E$18,IF(G21=16,KILOMETRAJE!E$19,IF(G21=17,KILOMETRAJE!E$20,IF(G21=18,KILOMETRAJE!E$21,IF(G21=19,KILOMETRAJE!E$22,IF(G21=20,KILOMETRAJE!E$23,IF(G21=21,KILOMETRAJE!E$24,IF(G21=22,KILOMETRAJE!E$25,IF(G21=23,KILOMETRAJE!E$26,IF(G21=24,KILOMETRAJE!E$27,IF(G21=25,KILOMETRAJE!E$28,IF(G21=26,KILOMETRAJE!E$29,IF(G21=27,KILOMETRAJE!E$30,IF(G21=28,KILOMETRAJE!E$31,IF(G21=29,KILOMETRAJE!E$32,IF(G21=30,KILOMETRAJE!E$33,IF(G21=31,KILOMETRAJE!E$34,IF(G21=32,KILOMETRAJE!E$35,IF(G21=33,KILOMETRAJE!E$36,IF(G21=34,KILOMETRAJE!E$37,IF(G21=35,KILOMETRAJE!E$38,IF(G21=36,KILOMETRAJE!E$39,IF(G21=37,KILOMETRAJE!E$40,IF(G21=38,KILOMETRAJE!E$41,IF(G21=39,KILOMETRAJE!E$42,IF(G21=40,KILOMETRAJE!E$43,IF(G21=41,KILOMETRAJE!E$44,IF(G21=42,KILOMETRAJE!E$45,IF(G21=43,KILOMETRAJE!E$46,IF(G21=44,KILOMETRAJE!E$47,IF(G21=45,KILOMETRAJE!E$48,IF(G21=46,KILOMETRAJE!E$49,IF(G21=47,KILOMETRAJE!E$50,IF(G21=48,KILOMETRAJE!E$51,IF(G21=49,KILOMETRAJE!E$52,IF(G21=50,KILOMETRAJE!E$53,IF(G21=51,KILOMETRAJE!E$54,IF(G21=52,KILOMETRAJE!E$55,IF(G21=53,KILOMETRAJE!E$56,IF(G21=54,KILOMETRAJE!E$57,IF(G21=55,KILOMETRAJE!E$58,IF(G21=56,KILOMETRAJE!E$59,IF(G21=57,KILOMETRAJE!E$60,IF(G21=58,KILOMETRAJE!E$61,IF(G21=59,KILOMETRAJE!E$62,IF(G21=60,KILOMETRAJE!E$63,IF(G21=61,KILOMETRAJE!E$64,IF(G21=62,KILOMETRAJE!E$65)))))))))))))))))))))))))))))))))))))))))))))))))))))))))))))) -> FALSE | J21: =IF(G21=1,KILOMETRAJE!G$4,IF(G21=2,KILOMETRAJE!G$5,IF(G21=3,KILOMETRAJE!G$6,IF(G21=4,KILOMETRAJE!G$7,IF(G21=5,KILOMETRAJE!G$8,IF(G21=6,KILOMETRAJE!G$9,IF(G21=7,KILOMETRAJE!G$10,IF(G21=8,KILOMETRAJE!G$11,IF(G21=9,KILOMETRAJE!G$12,IF(G21=10,KILOMETRAJE!G$13,IF(G21=11,KILOMETRAJE!G$14,IF(G21=12,KILOMETRAJE!G$15,IF(G21=13,KILOMETRAJE!G$16,IF(G21=14,KILOMETRAJE!G$17,IF(G21=15,KILOMETRAJE!G$18,IF(G21=16,KILOMETRAJE!G$19,IF(G21=17,KILOMETRAJE!G$20,IF(G21=18,KILOMETRAJE!G$21,IF(G21=19,KILOMETRAJE!G$22,IF(G21=20,KILOMETRAJE!G$23,IF(G21=21,KILOMETRAJE!G$24,IF(G21=22,KILOMETRAJE!G$25,IF(G21=23,KILOMETRAJE!G$26,IF(G21=24,KILOMETRAJE!G$27,IF(G21=25,KILOMETRAJE!G$28,IF(G21=26,KILOMETRAJE!G$29,IF(G21=27,KILOMETRAJE!G$30,IF(G21=28,KILOMETRAJE!G$31,IF(G21=29,KILOMETRAJE!G$32,IF(G21=30,KILOMETRAJE!G$33,IF(G21=31,KILOMETRAJE!G$34,IF(G21=32,KILOMETRAJE!G$35,IF(G21=33,KILOMETRAJE!G$36,IF(G21=34,KILOMETRAJE!G$37,IF(G21=35,KILOMETRAJE!G$38,IF(G21=36,KILOMETRAJE!G$39,IF(G21=37,KILOMETRAJE!G$40,IF(G21=38,KILOMETRAJE!G$41,IF(G21=39,KILOMETRAJE!G$42,IF(G21=40,KILOMETRAJE!G$43,IF(G21=41,KILOMETRAJE!G$44,IF(G21=42,KILOMETRAJE!G$45,IF(G21=43,KILOMETRAJE!G$46,IF(G21=44,KILOMETRAJE!G$47,IF(G21=45,KILOMETRAJE!G$48,IF(G21=46,KILOMETRAJE!G$49,IF(G21=47,KILOMETRAJE!G$50,IF(G21=48,KILOMETRAJE!G$51,IF(G21=49,KILOMETRAJE!G$52,IF(G21=50,KILOMETRAJE!G$53,IF(G21=51,KILOMETRAJE!G$54,IF(G21=52,KILOMETRAJE!G$55,IF(G21=53,KILOMETRAJE!G$56,IF(G21=54,KILOMETRAJE!G$57,IF(G21=55,KILOMETRAJE!G$58,IF(G21=56,KILOMETRAJE!G$59,IF(G21=57,KILOMETRAJE!G$60,IF(G21=58,KILOMETRAJE!G$61,IF(G21=59,KILOMETRAJE!G$62,IF(G21=60,KILOMETRAJE!G$63,IF(G21=61,KILOMETRAJE!G$64,IF(G21=62,KILOMETRAJE!G$65)))))))))))))))))))))))))))))))))))))))))))))))))))))))))))))) -> FALSE | L21: =SUM(J19:J21)/K21 -> #DIV/0! | Q21: =(IF(N21=1,(J21*0.3)))+(IF(N21=2,(J21*0.15))+(IF(N21=3,(J21*0.15)))) -> 0 | R21: =+LOOKUP(P35,UNIDADES!B$3:B$73,UNIDADES!C$3:C$73) -> #N/A | S21: =((SUM(J19:J21)/R21))-K21 -> #N/A | T21: =(IF(M21=1,(S21*16)))+(IF(M21=2,(S21*17.26))+(IF(M21=3,(S21*17.66))+(IF(M21=4,(S21*18.06))+(IF(M21=5,(S21*18.46))+(IF(M21=6,(S21*18.86))+(IF(M21=7,(S21*19.26)))))))) -> 0
E29: CRUCES | F29: 45936 | H29: =+F29+1 -> 45937 | I29: =+H29+1 -> 45938 | J29: =+I29+1 -> 45939 | K29: =+J29+1 -> 45940 | L29: =+K29+2 -> 45942 | M29: =+L29+1 -> 45943 | N29: TOTAL
H30: 0 | K30: 0 | L30: 0 | N30: =SUM(F30:L30) -> 0
C32: PERCEPCIONES DE LA SEMANA | I32: ADELANTO DE LIQUIDACION | O32: TOTAL: | Q32: =+F42-L40 -> 0
C33: PAGO POR KM | F33: =SUM(Q18:Q29) -> 0 | I33: CONCEPTO | J33: FECHA | K33: FOLIO | L33: MONTO
C34: DIESEL A FAVOR | F34: =SUM(T18:T29) -> 0 | O34: REPORTE | P34: UNIDAD | Q34: ODM. INICIAL | S34: ODM. FINAL | T34: KM. RECORR | U34: KM | V34: DIESEL
C35: CRUCES | F35: =+N30 -> 0 | T35: =+S35-Q35 -> 0
C36: DOBLE OPERADOR | T36: =+S36-Q36 -> 0
C37: ESTANCIAS | T37: =+S37-Q37 -> 0
C38: BONO DE LA SIERRA
C39: AUTORIZO NAHUM
C40: ANTICIPO DE VIAJE 45313 | I40: TOTAL DEDUCCIONES: | L40: =SUM(L34:L39) -> 0
C41: CAMARA DISPONIBILIDAD MANEJO
C42: TOTAL DE PERCEPCIONES: | F42: =SUM(F33:G41) -> 0
P43: CODIGO C/V/PT
P44: 1 | Q44: CARGADO
P45: 2 | Q45: VACIO
P46: 3 | Q46: PT
D50: FIRMA DE AUTORIZACION | J50: FIRMA DE CONFORMIDAD

Sheet CERDA HERNANDEZ JOSE LUIS
Q2: SEMANA:
I3: FLETES SOTELO S.A DE C.V | Q3: =+'CHAVEZ VARELA NESTOR ADRIAN'!Q3:S3 -> 42
I4: RFC: FSO880915JP8
I5: CAMINO DE LOS ESTEROS 720 | Q5: FOLIO DE LIQUIDACION
I6: PARTIDO DOBALDO CD.JUAREZ CHIHU. | Q6: =+'HARO IMPERIAL JOSÉ ANTONIO'!Q6+1 -> 1975
I9: INFORMACION DEL OPERADOR
D11: OPERADOR: | E11: CERDA HERNANDEZ JOSE LUIS | K11: FECHA DE PERIODO: | L11: =+NOMINA!B3 -> SEMANA #42 PERIODO DEL 06 AL 12 DE OCTUBRE DEL 2025
D12: UNIDAD: | E12: F-117
D14: ODOM.INIC: | F14: 971896 | I14: COMBUSTIBLE INICI: | O14: COMBUSTIBLE CARGADO:
D15: ODOM.FINAL: | F15: 974618 | I15: COMBUSTIBLE FIN: | O15: DIF. DE DIESEL:
D16: KM RECORRIDOS: | F16: =SUM(J19:J27) -> 4084 | I16: DIESEL CONSUMIDO: | J16: =SUM(K19:K27) -> 1159.712 | O16: RENDIMIENTO: | P16: =+F16/J16 -> 3.521564
C18: FOLIO LIQUIDACION | D18: CORDENADA | E18: FECHA SALIDA | F18: FECHA LLEGADA | G18: 14 | H18: ORIGEN | I18: DESTINO | J18: KMS | K18: RECARGA | L18: RENDIMIENTO | M18: REND.PAGO | N18: C / V / PT | O18: REMOLQUE | P18: CLIENTE | Q18: PAGO POR KM | R18: RENDIMIENTO PAGO | S18: LITROS A PAGO | T18: DIESEL A FAVOR | U18: SALIDA | V18: REGRESO
C19: 46372 | D19: 2873741-1 | E19: 45935 | F19: 45936 | G19: 1 | H19: =IF(G19=1,KILOMETRAJE!C$4,IF(G19=2,KILOMETRAJE!C$5,IF(G19=3,KILOMETRAJE!C$6,IF(G19=4,KILOMETRAJE!C$7,IF(G19=5,KILOMETRAJE!C$8,IF(G19=6,KILOMETRAJE!C$9,IF(G19=7,KILOMETRAJE!C$10,IF(G19=8,KILOMETRAJE!C$11,IF(G19=9,KILOMETRAJE!C$12,IF(G19=10,KILOMETRAJE!C$13,IF(G19=11,KILOMETRAJE!C$14,IF(G19=12,KILOMETRAJE!C$15,IF(G19=13,KILOMETRAJE!C$16,IF(G19=14,KILOMETRAJE!C$17,IF(G19=15,KILOMETRAJE!C$18,IF(G19=16,KILOMETRAJE!C$19,IF(G19=17,KILOMETRAJE!C$20,IF(G19=18,KILOMETRAJE!C$21,IF(G19=19,KILOMETRAJE!C$22,IF(G19=20,KILOMETRAJE!C$23,IF(G19=21,KILOMETRAJE!C$24,IF(G19=22,KILOMETRAJE!C$25,IF(G19=23,KILOMETRAJE!C$26,IF(G19=24,KILOMETRAJE!C$27,IF(G19=25,KILOMETRAJE!C$28,IF(G19=26,KILOMETRAJE!C$29,IF(G19=27,KILOMETRAJE!C$30,IF(G19=28,KILOMETRAJE!C$31,IF(G19=29,KILOMETRAJE!C$32,IF(G19=30,KILOMETRAJE!C$33,IF(G19=31,KILOMETRAJE!C$34,IF(G19=32,KILOMETRAJE!C$35,IF(G19=33,KILOMETRAJE!C$36,IF(G19=34,KILOMETRAJE!C$37,IF(G19=35,KILOMETRAJE!C$38,IF(G19=36,KILOMETRAJE!C$39,IF(G19=37,KILOMETRAJE!C$40,IF(G19=38,KILOMETRAJE!C$41,IF(G19=39,KILOMETRAJE!C$42,IF(G19=40,KILOMETRAJE!C$43,IF(G19=41,KILOMETRAJE!C$44,IF(G19=42,KILOMETRAJE!C$45,IF(G19=43,KILOMETRAJE!C$46,IF(G19=44,KILOMETRAJE!C$47,IF(G19=45,KILOMETRAJE!C$48,IF(G19=46,KILOMETRAJE!C$49,IF(G19=47,KILOMETRAJE!C$50,IF(G19=48,KILOMETRAJE!C$51,IF(G19=49,KILOMETRAJE!C$52,IF(G19=50,KILOMETRAJE!C$53,IF(G19=51,KILOMETRAJE!C$54,IF(G19=52,KILOMETRAJE!C$55,IF(G19=53,KILOMETRAJE!C$56,IF(G19=54,KILOMETRAJE!C$57,IF(G19=55,KILOMETRAJE!C$58,IF(G19=56,KILOMETRAJE!C$59,IF(G19=57,KILOMETRAJE!C$60,IF(G19=58,KILOMETRAJE!C$61,IF(G19=59,KILOMETRAJE!C$62,IF(G19=60,KILOMETRAJE!C$63,IF(G19=61,KILOMETRAJE!C$64,IF(G19=62,KILOMETRAJE!C$65)))))))))))))))))))))))))))))))))))))))))))))))))))))))))))))) -> JRZ | I19: =IF(G19=1,KILOMETRAJE!E$4,IF(G19=2,KILOMETRAJE!E$5,IF(G19=3,KILOMETRAJE!E$6,IF(G19=4,KILOMETRAJE!E$7,IF(G19=5,KILOMETRAJE!E$8,IF(G19=6,KILOMETRAJE!E$9,IF(G19=7,KILOMETRAJE!E$10,IF(G19=8,KILOMETRAJE!E$11,IF(G19=9,KILOMETRAJE!E$12,IF(G19=10,KILOMETRAJE!E$13,IF(G19=11,KILOMETRAJE!E$14,IF(G19=12,KILOMETRAJE!E$15,IF(G19=13,KILOMETRAJE!E$16,IF(G19=14,KILOMETRAJE!E$17,IF(G19=15,KILOMETRAJE!E$18,IF(G19=16,KILOMETRAJE!E$19,IF(G19=17,KILOMETRAJE!E$20,IF(G19=18,KILOMETRAJE!E$21,IF(G19=19,KILOMETRAJE!E$22,IF(G19=20,KILOMETRAJE!E$23,IF(G19=21,KILOMETRAJE!E$24,IF(G19=22,KILOMETRAJE!E$25,IF(G19=23,KILOMETRAJE!E$26,IF(G19=24,KILOMETRAJE!E$27,IF(G19=25,KILOMETRAJE!E$28,IF(G19=26,KILOMETRAJE!E$29,IF(G19=27,KILOMETRAJE!E$30,IF(G19=28,KILOMETRAJE!E$31,IF(G19=29,KILOMETRAJE!E$32,IF(G19=30,KILOMETRAJE!E$33,IF(G19=31,KILOMETRAJE!E$34,IF(G19=32,KILOMETRAJE!E$35,IF(G19=33,KILOMETRAJE!E$36,IF(G19=34,KILOMETRAJE!E$37,IF(G19=35,KILOMETRAJE!E$38,IF(G19=36,KILOMETRAJE!E$39,IF(G19=37,KILOMETRAJE!E$40,IF(G19=38,KILOMETRAJE!E$41,IF(G19=39,KILOMETRAJE!E$42,IF(G19=40,KILOMETRAJE!E$43,IF(G19=41,KILOMETRAJE!E$44,IF(G19=42,KILOMETRAJE!E$45,IF(G19=43,KILOMETRAJE!E$46,IF(G19=44,KILOMETRAJE!E$47,IF(G19=45,KILOMETRAJE!E$48,IF(G19=46,KILOMETRAJE!E$49,IF(G19=47,KILOMETRAJE!E$50,IF(G19=48,KILOMETRAJE!E$51,IF(G19=49,KILOMETRAJE!E$52,IF(G19=50,KILOMETRAJE!E$53,IF(G19=51,KILOMETRAJE!E$54,IF(G19=52,KILOMETRAJE!E$55,IF(G19=53,KILOMETRAJE!E$56,IF(G19=54,KILOMETRAJE!E$57,IF(G19=55,KILOMETRAJE!E$58,IF(G19=56,KILOMETRAJE!E$59,IF(G19=57,KILOMETRAJE!E$60,IF(G19=58,KILOMETRAJE!E$61,IF(G19=59,KILOMETRAJE!E$62,IF(G19=60,KILOMETRAJE!E$63,IF(G19=61,KILOMETRAJE!E$64,IF(G19=62,KILOMETRAJE!E$65)))))))))))))))))))))))))))))))))))))))))))))))))))))))))))))) -> OBRG | J19: =IF(G19=1,KILOMETRAJE!G$4,IF(G19=2,KILOMETRAJE!G$5,IF(G19=3,KILOMETRAJE!G$6,IF(G19=4,KILOMETRAJE!G$7,IF(G19=5,KILOMETRAJE!G$8,IF(G19=6,KILOMETRAJE!G$9,IF(G19=7,KILOMETRAJE!G$10,IF(G19=8,KILOMETRAJE!G$11,IF(G19=9,KILOMETRAJE!G$12,IF(G19=10,KILOMETRAJE!G$13,IF(G19=11,KILOMETRAJE!G$14,IF(G19=12,KILOMETRAJE!G$15,IF(G19=13,KILOMETRAJE!G$16,IF(G19=14,KILOMETRAJE!G$17,IF(G19=15,KILOMETRAJE!G$18,IF(G19=16,KILOMETRAJE!G$19,IF(G19=17,KILOMETRAJE!G$20,IF(G19=18,KILOMETRAJE!G$21,IF(G19=19,KILOMETRAJE!G$22,IF(G19=20,KILOMETRAJE!G$23,IF(G19=21,KILOMETRAJE!G$24,IF(G19=22,KILOMETRAJE!G$25,IF(G19=23,KILOMETRAJE!G$26,IF(G19=24,KILOMETRAJE!G$27,IF(G19=25,KILOMETRAJE!G$28,IF(G19=26,KILOMETRAJE!G$29,IF(G19=27,KILOMETRAJE!G$30,IF(G19=28,KILOMETRAJE!G$31,IF(G19=29,KILOMETRAJE!G$32,IF(G19=30,KILOMETRAJE!G$33,IF(G19=31,KILOMETRAJE!G$34,IF(G19=32,KILOMETRAJE!G$35,IF(G19=33,KILOMETRAJE!G$36,IF(G19=34,KILOMETRAJE!G$37,IF(G19=35,KILOMETRAJE!G$38,IF(G19=36,KILOMETRAJE!G$39,IF(G19=37,KILOMETRAJE!G$40,IF(G19=38,KILOMETRAJE!G$41,IF(G19=39,KILOMETRAJE!G$42,IF(G19=40,KILOMETRAJE!G$43,IF(G19=41,KILOMETRAJE!G$44,IF(G19=42,KILOMETRAJE!G$45,IF(G19=43,KILOMETRAJE!G$46,IF(G19=44,KILOMETRAJE!G$47,IF(G19=45,KILOMETRAJE!G$48,IF(G19=46,KILOMETRAJE!G$49,IF(G19=47,KILOMETRAJE!G$50,IF(G19=48,KILOMETRAJE!G$51,IF(G19=49,KILOMETRAJE!G$52,IF(G19=50,KILOMETRAJE!G$53,IF(G19=51,KILOMETRAJE!G$54,IF(G19=52,KILOMETRAJE!G$55,IF(G19=53,KILOMETRAJE!G$56,IF(G19=54,KILOMETRAJE!G$57,IF(G19=55,KILOMETRAJE!G$58,IF(G19=56,KILOMETRAJE!G$59,IF(G19=57,KILOMETRAJE!G$60,IF(G19=58,KILOMETRAJE!G$61,IF(G19=59,KILOMETRAJE!G$62,IF(G19=60,KILOMETRAJE!G$63,IF(G19=61,KILOMETRAJE!G$64,IF(G19=62,KILOMETRAJE!G$65)))))))))))))))))))))))))))))))))))))))))))))))))))))))))))))) -> 1021 | N19: 2 | O19: FSM53967 | P19: SOTELO | Q19: =(IF(N19=1,(J19*0.3)))+(IF(N19=2,(J19*0.15))+(IF(N19=3,(J19*0.15)))) -> 153.15 | V19: 9
D20: 2874027-2 | E20: 45937 | F20: 45938 | G20: 2 | H20: =IF(G20=1,KILOMETRAJE!C$4,IF(G20=2,KILOMETRAJE!C$5,IF(G20=3,KILOMETRAJE!C$6,IF(G20=4,KILOMETRAJE!C$7,IF(G20=5,KILOMETRAJE!C$8,IF(G20=6,KILOMETRAJE!C$9,IF(G20=7,KILOMETRAJE!C$10,IF(G20=8,KILOMETRAJE!C$11,IF(G20=9,KILOMETRAJE!C$12,IF(G20=10,KILOMETRAJE!C$13,IF(G20=11,KILOMETRAJE!C$14,IF(G20=12,KILOMETRAJE!C$15,IF(G20=13,KILOMETRAJE!C$16,IF(G20=14,KILOMETRAJE!C$17,IF(G20=15,KILOMETRAJE!C$18,IF(G20=16,KILOMETRAJE!C$19,IF(G20=17,KILOMETRAJE!C$20,IF(G20=18,KILOMETRAJE!C$21,IF(G20=19,KILOMETRAJE!C$22,IF(G20=20,KILOMETRAJE!C$23,IF(G20=21,KILOMETRAJE!C$24,IF(G20=22,KILOMETRAJE!C$25,IF(G20=23,KILOMETRAJE!C$26,IF(G20=24,KILOMETRAJE!C$27,IF(G20=25,KILOMETRAJE!C$28,IF(G20=26,KILOMETRAJE!C$29,IF(G20=27,KILOMETRAJE!C$30,IF(G20=28,KILOMETRAJE!C$31,IF(G20=29,KILOMETRAJE!C$32,IF(G20=30,KILOMETRAJE!C$33,IF(G20=31,KILOMETRAJE!C$34,IF(G20=32,KILOMETRAJE!C$35,IF(G20=33,KILOMETRAJE!C$36,IF(G20=34,KILOMETRAJE!C$37,IF(G20=35,KILOMETRAJE!C$38,IF(G20=36,KILOMETRAJE!C$39,IF(G20=37,KILOMETRAJE!C$40,IF(G20=38,KILOMETRAJE!C$41,IF(G20=39,KILOMETRAJE!C$42,IF(G20=40,KILOMETRAJE!C$43,IF(G20=41,KILOMETRAJE!C$44,IF(G20=42,KILOMETRAJE!C$45,IF(G20=43,KILOMETRAJE!C$46,IF(G20=44,KILOMETRAJE!C$47,IF(G20=45,KILOMETRAJE!C$48,IF(G20=46,KILOMETRAJE!C$49,IF(G20=47,KILOMETRAJE!C$50,IF(G20=48,KILOMETRAJE!C$51,IF(G20=49,KILOMETRAJE!C$52,IF(G20=50,KILOMETRAJE!C$53,IF(G20=51,KILOMETRAJE!C$54,IF(G20=52,KILOMETRAJE!C$55,IF(G20=53,KILOMETRAJE!C$56,IF(G20=54,KILOMETRAJE!C$57,IF(G20=55,KILOMETRAJE!C$58,IF(G20=56,KILOMETRAJE!C$59,IF(G20=57,KILOMETRAJE!C$60,IF(G20=58,KILOMETRAJE!C$61,IF(G20=59,KILOMETRAJE!C$62,IF(G20=60,KILOMETRAJE!C$63,IF(G20=61,KILOMETRAJE!C$64,IF(G20=62,KILOMETRAJE!C$65)))))))))))))))))))))))))))))))))))))))))))))))))))))))))))))) -> OBRG | I20: =IF(G20=1,KILOMETRAJE!E$4,IF(G20=2,KILOMETRAJE!E$5,IF(G20=3,KILOMETRAJE!E$6,IF(G20=4,KILOMETRAJE!E$7,IF(G20=5,KILOMETRAJE!E$8,IF(G20=6,KILOMETRAJE!E$9,IF(G20=7,KILOMETRAJE!E$10,IF(G20=8,KILOMETRAJE!E$11,IF(G20=9,KILOMETRAJE!E$12,IF(G20=10,KILOMETRAJE!E$13,IF(G20=11,KILOMETRAJE!E$14,IF(G20=12,KILOMETRAJE!E$15,IF(G20=13,KILOMETRAJE!E$16,IF(G20=14,KILOMETRAJE!E$17,IF(G20=15,KILOMETRAJE!E$18,IF(G20=16,KILOMETRAJE!E$19,IF(G20=17,KILOMETRAJE!E$20,IF(G20=18,KILOMETRAJE!E$21,IF(G20=19,KILOMETRAJE!E$22,IF(G20=20,KILOMETRAJE!E$23,IF(G20=21,KILOMETRAJE!E$24,IF(G20=22,KILOMETRAJE!E$25,IF(G20=23,KILOMETRAJE!E$26,IF(G20=24,KILOMETRAJE!E$27,IF(G20=25,KILOMETRAJE!E$28,IF(G20=26,KILOMETRAJE!E$29,IF(G20=27,KILOMETRAJE!E$30,IF(G20=28,KILOMETRAJE!E$31,IF(G20=29,KILOMETRAJE!E$32,IF(G20=30,KILOMETRAJE!E$33,IF(G20=31,KILOMETRAJE!E$34,IF(G20=32,KILOMETRAJE!E$35,IF(G20=33,KILOMETRAJE!E$36,IF(G20=34,KILOMETRAJE!E$37,IF(G20=35,KILOMETRAJE!E$38,IF(G20=36,KILOMETRAJE!E$39,IF(G20=37,KILOMETRAJE!E$40,IF(G20=38,KILOMETRAJE!E$41,IF(G20=39,KILOMETRAJE!E$42,IF(G20=40,KILOMETRAJE!E$43,IF(G20=41,KILOMETRAJE!E$44,IF(G20=42,KILOMETRAJE!E$45,IF(G20=43,KILOMETRAJE!E$46,IF(G20=44,KILOMETRAJE!E$47,IF(G20=45,KILOMETRAJE!E$48,IF(G20=46,KILOMETRAJE!E$49,IF(G20=47,KILOMETRAJE!E$50,IF(G20=48,KILOMETRAJE!E$51,IF(G20=49,KILOMETRAJE!E$52,IF(G20=50,KILOMETRAJE!E$53,IF(G20=51,KILOMETRAJE!E$54,IF(G20=52,KILOMETRAJE!E$55,IF(G20=53,KILOMETRAJE!E$56,IF(G20=54,KILOMETRAJE!E$57,IF(G20=55,KILOMETRAJE!E$58,IF(G20=56,KILOMETRAJE!E$59,IF(G20=57,KILOMETRAJE!E$60,IF(G20=58,KILOMETRAJE!E$61,IF(G20=59,KILOMETRAJE!E$62,IF(G20=60,KILOMETRAJE!E$63,IF(G20=61,KILOMETRAJE!E$64,IF(G20=62,KILOMETRAJE!E$65)))))))))))))))))))))))))))))))))))))))))))))))))))))))))))))) -> JRZ | J20: =IF(G20=1,KILOMETRAJE!G$4,IF(G20=2,KILOMETRAJE!G$5,IF(G20=3,KILOMETRAJE!G$6,IF(G20=4,KILOMETRAJE!G$7,IF(G20=5,KILOMETRAJE!G$8,IF(G20=6,KILOMETRAJE!G$9,IF(G20=7,KILOMETRAJE!G$10,IF(G20=8,KILOMETRAJE!G$11,IF(G20=9,KILOMETRAJE!G$12,IF(G20=10,KILOMETRAJE!G$13,IF(G20=11,KILOMETRAJE!G$14,IF(G20=12,KILOMETRAJE!G$15,IF(G20=13,KILOMETRAJE!G$16,IF(G20=14,KILOMETRAJE!G$17,IF(G20=15,KILOMETRAJE!G$18,IF(G20=16,KILOMETRAJE!G$19,IF(G20=17,KILOMETRAJE!G$20,IF(G20=18,KILOMETRAJE!G$21,IF(G20=19,KILOMETRAJE!G$22,IF(G20=20,KILOMETRAJE!G$23,IF(G20=21,KILOMETRAJE!G$24,IF(G20=22,KILOMETRAJE!G$25,IF(G20=23,KILOMETRAJE!G$26,IF(G20=24,KILOMETRAJE!G$27,IF(G20=25,KILOMETRAJE!G$28,IF(G20=26,KILOMETRAJE!G$29,IF(G20=27,KILOMETRAJE!G$30,IF(G20=28,KILOMETRAJE!G$31,IF(G20=29,KILOMETRAJE!G$32,IF(G20=30,KILOMETRAJE!G$33,IF(G20=31,KILOMETRAJE!G$34,IF(G20=32,KILOMETRAJE!G$35,IF(G20=33,KILOMETRAJE!G$36,IF(G20=34,KILOMETRAJE!G$37,IF(G20=35,KILOMETRAJE!G$38,IF(G20=36,KILOMETRAJE!G$39,IF(G20=37,KILOMETRAJE!G$40,IF(G20=38,KILOMETRAJE!G$41,IF(G20=39,KILOMETRAJE!G$42,IF(G20=40,KILOMETRAJE!G$43,IF(G20=41,KILOMETRAJE!G$44,IF(G20=42,KILOMETRAJE!G$45,IF(G20=43,KILOMETRAJE!G$46,IF(G20=44,KILOMETRAJE!G$47,IF(G20=45,KILOMETRAJE!G$48,IF(G20=46,KILOMETRAJE!G$49,IF(G20=47,KILOMETRAJE!G$50,IF(G20=48,KILOMETRAJE!G$51,IF(G20=49,KILOMETRAJE!G$52,IF(G20=50,KILOMETRAJE!G$53,IF(G20=51,KILOMETRAJE!G$54,IF(G20=52,KILOMETRAJE!G$55,IF(G20=53,KILOMETRAJE!G$56,IF(G20=54,KILOMETRAJE!G$57,IF(G20=55,KILOMETRAJE!G$58,IF(G20=56,KILOMETRAJE!G$59,IF(G20=57,KILOMETRAJE!G$60,IF(G20=58,KILOMETRAJE!G$61,IF(G20=59,KILOMETRAJE!G$62,IF(G20=60,KILOMETRAJE!G$63,IF(G20=61,KILOMETRAJE!G$64,IF(G20=62,KILOMETRAJE!G$65)))))))))))))))))))))))))))))))))))))))))))))))))))))))))))))) -> 1021 | K20: 599.686 | L20: =SUM(J18:J20)/K20 -> 3.4051153 | M20: 6 | N20: 1 | O20: FSM22305 | P20: YAZAKI | Q20: =(IF(N20=1,(J20*0.3)))+(IF(N20=2,(J20*0.15))+(IF(N20=3,(J20*0.15)))) -> 306.3 | R20: =+LOOKUP(P35,UNIDADES!B$3:B$73,UNIDADES!C$3:C$73) -> 2.701058 | S20: =((SUM(J18:J20)/R20))-K20 -> 156.31406 | T20: =(IF(M20=1,(S20*16)))+(IF(M20=2,(S20*17.26))+(IF(M20=3,(S20*17.66))+(IF(M20=4,(S20*18.06))+(IF(M20=5,(S20*18.46))+(IF(M20=6,(S20*18.86))+(IF(M20=7,(S20*19.26)))))))) -> 2948.0831 | V20: 9
C21: 45938 | D21: 2874535-1 | E21: 45939 | F21: 45940 | G21: 1 | H21: =IF(G21=1,KILOMETRAJE!C$4,IF(G21=2,KILOMETRAJE!C$5,IF(G21=3,KILOMETRAJE!C$6,IF(G21=4,KILOMETRAJE!C$7,IF(G21=5,KILOMETRAJE!C$8,IF(G21=6,KILOMETRAJE!C$9,IF(G21=7,KILOMETRAJE!C$10,IF(G21=8,KILOMETRAJE!C$11,IF(G21=9,KILOMETRAJE!C$12,IF(G21=10,KILOMETRAJE!C$13,IF(G21=11,KILOMETRAJE!C$14,IF(G21=12,KILOMETRAJE!C$15,IF(G21=13,KILOMETRAJE!C$16,IF(G21=14,KILOMETRAJE!C$17,IF(G21=15,KILOMETRAJE!C$18,IF(G21=16,KILOMETRAJE!C$19,IF(G21=17,KILOMETRAJE!C$20,IF(G21=18,KILOMETRAJE!C$21,IF(G21=19,KILOMETRAJE!C$22,IF(G21=20,KILOMETRAJE!C$23,IF(G21=21,KILOMETRAJE!C$24,IF(G21=22,KILOMETRAJE!C$25,IF(G21=23,KILOMETRAJE!C$26,IF(G21=24,KILOMETRAJE!C$27,IF(G21=25,KILOMETRAJE!C$28,IF(G21=26,KILOMETRAJE!C$29,IF(G21=27,KILOMETRAJE!C$30,IF(G21=28,KILOMETRAJE!C$31,IF(G21=29,KILOMETRAJE!C$32,IF(G21=30,KILOMETRAJE!C$33,IF(G21=31,KILOMETRAJE!C$34,IF(G21=32,KILOMETRAJE!C$35,IF(G21=33,KILOMETRAJE!C$36,IF(G21=34,KILOMETRAJE!C$37,IF(G21=35,KILOMETRAJE!C$38,IF(G21=36,KILOMETRAJE!C$39,IF(G21=37,KILOMETRAJE!C$40,IF(G21=38,KILOMETRAJE!C$41,IF(G21=39,KILOMETRAJE!C$42,IF(G21=40,KILOMETRAJE!C$43,IF(G21=41,KILOMETRAJE!C$44,IF(G21=42,KILOMETRAJE!C$45,IF(G21=43,KILOMETRAJE!C$46,IF(G21=44,KILOMETRAJE!C$47,IF(G21=45,KILOMETRAJE!C$48,IF(G21=46,KILOMETRAJE!C$49,IF(G21=47,KILOMETRAJE!C$50,IF(G21=48,KILOMETRAJE!C$51,IF(G21=49,KILOMETRAJE!C$52,IF(G21=50,KILOMETRAJE!C$53,IF(G21=51,KILOMETRAJE!C$54,IF(G21=52,KILOMETRAJE!C$55,IF(G21=53,KILOMETRAJE!C$56,IF(G21=54,KILOMETRAJE!C$57,IF(G21=55,KILOMETRAJE!C$58,IF(G21=56,KILOMETRAJE!C$59,IF(G21=57,KILOMETRAJE!C$60,IF(G21=58,KILOMETRAJE!C$61,IF(G21=59,KILOMETRAJE!C$62,IF(G21=60,KILOMETRAJE!C$63,IF(G21=61,KILOMETRAJE!C$64,IF(G21=62,KILOMETRAJE!C$65)))))))))))))))))))))))))))))))))))))))))))))))))))))))))))))) -> JRZ | I21: =IF(G21=1,KILOMETRAJE!E$4,IF(G21=2,KILOMETRAJE!E$5,IF(G21=3,KILOMETRAJE!E$6,IF(G21=4,KILOMETRAJE!E$7,IF(G21=5,KILOMETRAJE!E$8,IF(G21=6,KILOMETRAJE!E$9,IF(G21=7,KILOMETRAJE!E$10,IF(G21=8,KILOMETRAJE!E$11,IF(G21=9,KILOMETRAJE!E$12,IF(G21=10,KILOMETRAJE!E$13,IF(G21=11,KILOMETRAJE!E$14,IF(G21=12,KILOMETRAJE!E$15,IF(G21=13,KILOMETRAJE!E$16,IF(G21=14,KILOMETRAJE!E$17,IF(G21=15,KILOMETRAJE!E$18,IF(G21=16,KILOMETRAJE!E$19,IF(G21=17,KILOMETRAJE!E$20,IF(G21=18,KILOMETRAJE!E$21,IF(G21=19,KILOMETRAJE!E$22,IF(G21=20,KILOMETRAJE!E$23,IF(G21=21,KILOMETRAJE!E$24,IF(G21=22,KILOMETRAJE!E$25,IF(G21=23,KILOMETRAJE!E$26,IF(G21=24,KILOMETRAJE!E$27,IF(G21=25,KILOMETRAJE!E$28,IF(G21=26,KILOMETRAJE!E$29,IF(G21=27,KILOMETRAJE!E$30,IF(G21=28,KILOMETRAJE!E$31,IF(G21=29,KILOMETRAJE!E$32,IF(G21=30,KILOMETRAJE!E$33,IF(G21=31,KILOMETRAJE!E$34,IF(G21=32,KILOMETRAJE!E$35,IF(G21=33,KILOMETRAJE!E$36,IF(G21=34,KILOMETRAJE!E$37,IF(G21=35,KILOMETRAJE!E$38,IF(G21=36,KILOMETRAJE!E$39,IF(G21=37,KILOMETRAJE!E$40,IF(G21=38,KILOMETRAJE!E$41,IF(G21=39,KILOMETRAJE!E$42,IF(G21=40,KILOMETRAJE!E$43,IF(G21=41,KILOMETRAJE!E$44,IF(G21=42,KILOMETRAJE!E$45,IF(G21=43,KILOMETRAJE!E$46,IF(G21=44,KILOMETRAJE!E$47,IF(G21=45,KILOMETRAJE!E$48,IF(G21=46,KILOMETRAJE!E$49,IF(G21=47,KILOMETRAJE!E$50,IF(G21=48,KILOMETRAJE!E$51,IF(G21=49,KILOMETRAJE!E$52,IF(G21=50,KILOMETRAJE!E$53,IF(G21=51,KILOMETRAJE!E$54,IF(G21=52,KILOMETRAJE!E$55,IF(G21=53,KILOMETRAJE!E$56,IF(G21=54,KILOMETRAJE!E$57,IF(G21=55,KILOMETRAJE!E$58,IF(G21=56,KILOMETRAJE!E$59,IF(G21=57,KILOMETRAJE!E$60,IF(G21=58,KILOMETRAJE!E$61,IF(G21=59,KILOMETRAJE!E$62,IF(G21=60,KILOMETRAJE!E$63,IF(G21=61,KILOMETRAJE!E$64,IF(G21=62,KILOMETRAJE!E$65)))))))))))))))))))))))))))))))))))))))))))))))))))))))))))))) -> OBRG | J21: =IF(G21=1,KILOMETRAJE!G$4,IF(G21=2,KILOMETRAJE!G$5,IF(G21=3,KILOMETRAJE!G$6,IF(G21=4,KILOMETRAJE!G$7,IF(G21=5,KILOMETRAJE!G$8,IF(G21=6,KILOMETRAJE!G$9,IF(G21=7,KILOMETRAJE!G$10,IF(G21=8,KILOMETRAJE!G$11,IF(G21=9,KILOMETRAJE!G$12,IF(G21=10,KILOMETRAJE!G$13,IF(G21=11,KILOMETRAJE!G$14,IF(G21=12,KILOMETRAJE!G$15,IF(G21=13,KILOMETRAJE!G$16,IF(G21=14,KILOMETRAJE!G$17,IF(G21=15,KILOMETRAJE!G$18,IF(G21=16,KILOMETRAJE!G$19,IF(G21=17,KILOMETRAJE!G$20,IF(G21=18,KILOMETRAJE!G$21,IF(G21=19,KILOMETRAJE!G$22,IF(G21=20,KILOMETRAJE!G$23,IF(G21=21,KILOMETRAJE!G$24,IF(G21=22,KILOMETRAJE!G$25,IF(G21=23,KILOMETRAJE!G$26,IF(G21=24,KILOMETRAJE!G$27,IF(G21=25,KILOMETRAJE!G$28,IF(G21=26,KILOMETRAJE!G$29,IF(G21=27,KILOMETRAJE!G$30,IF(G21=28,KILOMETRAJE!G$31,IF(G21=29,KILOMETRAJE!G$32,IF(G21=30,KILOMETRAJE!G$33,IF(G21=31,KILOMETRAJE!G$34,IF(G21=32,KILOMETRAJE!G$35,IF(G21=33,KILOMETRAJE!G$36,IF(G21=34,KILOMETRAJE!G$37,IF(G21=35,KILOMETRAJE!G$38,IF(G21=36,KILOMETRAJE!G$39,IF(G21=37,KILOMETRAJE!G$40,IF(G21=38,KILOMETRAJE!G$41,IF(G21=39,KILOMETRAJE!G$42,IF(G21=40,KILOMETRAJE!G$43,IF(G21=41,KILOMETRAJE!G$44,IF(G21=42,KILOMETRAJE!G$45,IF(G21=43,KILOMETRAJE!G$46,IF(G21=44,KILOMETRAJE!G$47,IF(G21=45,KILOMETRAJE!G$48,IF(G21=46,KILOMETRAJE!G$49,IF(G21=47,KILOMETRAJE!G$50,IF(G21=48,KILOMETRAJE!G$51,IF(G21=49,KILOMETRAJE!G$52,IF(G21=50,KILOMETRAJE!G$53,IF(G21=51,KILOMETRAJE!G$54,IF(G21=52,KILOMETRAJE!G$55,IF(G21=53,KILOMETRAJE!G$56,IF(G21=54,KILOMETRAJE!G$57,IF(G21=55,KILOMETRAJE!G$58,IF(G21=56,KILOMETRAJE!G$59,IF(G21=57,KILOMETRAJE!G$60,IF(G21=58,KILOMETRAJE!G$61,IF(G21=59,KILOMETRAJE!G$62,IF(G21=60,KILOMETRAJE!G$63,IF(G21=61,KILOMETRAJE!G$64,IF(G21=62,KILOMETRAJE!G$65)))))))))))))))))))))))))))))))))))))))))))))))))))))))))))))) -> 1021 | N21: 2 | O21: FSM53947 | P21: SOTELO | Q21: =(IF(N21=1,(J21*0.3)))+(IF(N21=2,(J21*0.15))+(IF(N21=3,(J21*0.15)))) -> 153.15 | U21: 61 | V21: 60
D22: 2874787-2 | E22: 45940 | F22: 45941 | G22: 2 | H22: =IF(G22=1,KILOMETRAJE!C$4,IF(G22=2,KILOMETRAJE!C$5,IF(G22=3,KILOMETRAJE!C$6,IF(G22=4,KILOMETRAJE!C$7,IF(G22=5,KILOMETRAJE!C$8,IF(G22=6,KILOMETRAJE!C$9,IF(G22=7,KILOMETRAJE!C$10,IF(G22=8,KILOMETRAJE!C$11,IF(G22=9,KILOMETRAJE!C$12,IF(G22=10,KILOMETRAJE!C$13,IF(G22=11,KILOMETRAJE!C$14,IF(G22=12,KILOMETRAJE!C$15,IF(G22=13,KILOMETRAJE!C$16,IF(G22=14,KILOMETRAJE!C$17,IF(G22=15,KILOMETRAJE!C$18,IF(G22=16,KILOMETRAJE!C$19,IF(G22=17,KILOMETRAJE!C$20,IF(G22=18,KILOMETRAJE!C$21,IF(G22=19,KILOMETRAJE!C$22,IF(G22=20,KILOMETRAJE!C$23,IF(G22=21,KILOMETRAJE!C$24,IF(G22=22,KILOMETRAJE!C$25,IF(G22=23,KILOMETRAJE!C$26,IF(G22=24,KILOMETRAJE!C$27,IF(G22=25,KILOMETRAJE!C$28,IF(G22=26,KILOMETRAJE!C$29,IF(G22=27,KILOMETRAJE!C$30,IF(G22=28,KILOMETRAJE!C$31,IF(G22=29,KILOMETRAJE!C$32,IF(G22=30,KILOMETRAJE!C$33,IF(G22=31,KILOMETRAJE!C$34,IF(G22=32,KILOMETRAJE!C$35,IF(G22=33,KILOMETRAJE!C$36,IF(G22=34,KILOMETRAJE!C$37,IF(G22=35,KILOMETRAJE!C$38,IF(G22=36,KILOMETRAJE!C$39,IF(G22=37,KILOMETRAJE!C$40,IF(G22=38,KILOMETRAJE!C$41,IF(G22=39,KILOMETRAJE!C$42,IF(G22=40,KILOMETRAJE!C$43,IF(G22=41,KILOMETRAJE!C$44,IF(G22=42,KILOMETRAJE!C$45,IF(G22=43,KILOMETRAJE!C$46,IF(G22=44,KILOMETRAJE!C$47,IF(G22=45,KILOMETRAJE!C$48,IF(G22=46,KILOMETRAJE!C$49,IF(G22=47,KILOMETRAJE!C$50,IF(G22=48,KILOMETRAJE!C$51,IF(G22=49,KILOMETRAJE!C$52,IF(G22=50,KILOMETRAJE!C$53,IF(G22=51,KILOMETRAJE!C$54,IF(G22=52,KILOMETRAJE!C$55,IF(G22=53,KILOMETRAJE!C$56,IF(G22=54,KILOMETRAJE!C$57,IF(G22=55,KILOMETRAJE!C$58,IF(G22=56,KILOMETRAJE!C$59,IF(G22=57,KILOMETRAJE!C$60,IF(G22=58,KILOMETRAJE!C$61,IF(G22=59,KILOMETRAJE!C$62,IF(G22=60,KILOMETRAJE!C$63,IF(G22=61,KILOMETRAJE!C$64,IF(G22=62,KILOMETRAJE!C$65)))))))))))))))))))))))))))))))))))))))))))))))))))))))))))))) -> OBRG | I22: =IF(G22=1,KILOMETRAJE!E$4,IF(G22=2,KILOMETRAJE!E$5,IF(G22=3,KILOMETRAJE!E$6,IF(G22=4,KILOMETRAJE!E$7,IF(G22=5,KILOMETRAJE!E$8,IF(G22=6,KILOMETRAJE!E$9,IF(G22=7,KILOMETRAJE!E$10,IF(G22=8,KILOMETRAJE!E$11,IF(G22=9,KILOMETRAJE!E$12,IF(G22=10,KILOMETRAJE!E$13,IF(G22=11,KILOMETRAJE!E$14,IF(G22=12,KILOMETRAJE!E$15,IF(G22=13,KILOMETRAJE!E$16,IF(G22=14,KILOMETRAJE!E$17,IF(G22=15,KILOMETRAJE!E$18,IF(G22=16,KILOMETRAJE!E$19,IF(G22=17,KILOMETRAJE!E$20,IF(G22=18,KILOMETRAJE!E$21,IF(G22=19,KILOMETRAJE!E$22,IF(G22=20,KILOMETRAJE!E$23,IF(G22=21,KILOMETRAJE!E$24,IF(G22=22,KILOMETRAJE!E$25,IF(G22=23,KILOMETRAJE!E$26,IF(G22=24,KILOMETRAJE!E$27,IF(G22=25,KILOMETRAJE!E$28,IF(G22=26,KILOMETRAJE!E$29,IF(G22=27,KILOMETRAJE!E$30,IF(G22=28,KILOMETRAJE!E$31,IF(G22=29,KILOMETRAJE!E$32,IF(G22=30,KILOMETRAJE!E$33,IF(G22=31,KILOMETRAJE!E$34,IF(G22=32,KILOMETRAJE!E$35,IF(G22=33,KILOMETRAJE!E$36,IF(G22=34,KILOMETRAJE!E$37,IF(G22=35,KILOMETRAJE!E$38,IF(G22=36,KILOMETRAJE!E$39,IF(G22=37,KILOMETRAJE!E$40,IF(G22=38,KILOMETRAJE!E$41,IF(G22=39,KILOMETRAJE!E$42,IF(G22=40,KILOMETRAJE!E$43,IF(G22=41,KILOMETRAJE!E$44,IF(G22=42,KILOMETRAJE!E$45,IF(G22=43,KILOMETRAJE!E$46,IF(G22=44,KILOMETRAJE!E$47,IF(G22=45,KILOMETRAJE!E$48,IF(G22=46,KILOMETRAJE!E$49,IF(G22=47,KILOMETRAJE!E$50,IF(G22=48,KILOMETRAJE!E$51,IF(G22=49,KILOMETRAJE!E$52,IF(G22=50,KILOMETRAJE!E$53,IF(G22=51,KILOMETRAJE!E$54,IF(G22=52,KILOMETRAJE!E$55,IF(G22=53,KILOMETRAJE!E$56,IF(G22=54,KILOMETRAJE!E$57,IF(G22=55,KILOMETRAJE!E$58,IF(G22=56,KILOMETRAJE!E$59,IF(G22=57,KILOMETRAJE!E$60,IF(G22=58,KILOMETRAJE!E$61,IF(G22=59,KILOMETRAJE!E$62,IF(G22=60,KILOMETRAJE!E$63,IF(G22=61,KILOMETRAJE!E$64,IF(G22=62,KILOMETRAJE!E$65)))))))))))))))))))))))))))))))))))))))))))))))))))))))))))))) -> JRZ | J22: =IF(G22=1,KILOMETRAJE!G$4,IF(G22=2,KILOMETRAJE!G$5,IF(G22=3,KILOMETRAJE!G$6,IF(G22=4,KILOMETRAJE!G$7,IF(G22=5,KILOMETRAJE!G$8,IF(G22=6,KILOMETRAJE!G$9,IF(G22=7,KILOMETRAJE!G$10,IF(G22=8,KILOMETRAJE!G$11,IF(G22=9,KILOMETRAJE!G$12,IF(G22=10,KILOMETRAJE!G$13,IF(G22=11,KILOMETRAJE!G$14,IF(G22=12,KILOMETRAJE!G$15,IF(G22=13,KILOMETRAJE!G$16,IF(G22=14,KILOMETRAJE!G$17,IF(G22=15,KILOMETRAJE!G$18,IF(G22=16,KILOMETRAJE!G$19,IF(G22=17,KILOMETRAJE!G$20,IF(G22=18,KILOMETRAJE!G$21,IF(G22=19,KILOMETRAJE!G$22,IF(G22=20,KILOMETRAJE!G$23,IF(G22=21,KILOMETRAJE!G$24,IF(G22=22,KILOMETRAJE!G$25,IF(G22=23,KILOMETRAJE!G$26,IF(G22=24,KILOMETRAJE!G$27,IF(G22=25,KILOMETRAJE!G$28,IF(G22=26,KILOMETRAJE!G$29,IF(G22=27,KILOMETRAJE!G$30,IF(G22=28,KILOMETRAJE!G$31,IF(G22=29,KILOMETRAJE!G$32,IF(G22=30,KILOMETRAJE!G$33,IF(G22=31,KILOMETRAJE!G$34,IF(G22=32,KILOMETRAJE!G$35,IF(G22=33,KILOMETRAJE!G$36,IF(G22=34,KILOMETRAJE!G$37,IF(G22=35,KILOMETRAJE!G$38,IF(G22=36,KILOMETRAJE!G$39,IF(G22=37,KILOMETRAJE!G$40,IF(G22=38,KILOMETRAJE!G$41,IF(G22=39,KILOMETRAJE!G$42,IF(G22=40,KILOMETRAJE!G$43,IF(G22=41,KILOMETRAJE!G$44,IF(G22=42,KILOMETRAJE!G$45,IF(G22=43,KILOMETRAJE!G$46,IF(G22=44,KILOMETRAJE!G$47,IF(G22=45,KILOMETRAJE!G$48,IF(G22=46,KILOMETRAJE!G$49,IF(G22=47,KILOMETRAJE!G$50,IF(G22=48,KILOMETRAJE!G$51,IF(G22=49,KILOMETRAJE!G$52,IF(G22=50,KILOMETRAJE!G$53,IF(G22=51,KILOMETRAJE!G$54,IF(G22=52,KILOMETRAJE!G$55,IF(G22=53,KILOMETRAJE!G$56,IF(G22=54,KILOMETRAJE!G$57,IF(G22=55,KILOMETRAJE!G$58,IF(G22=56,KILOMETRAJE!G$59,IF(G22=57,KILOMETRAJE!G$60,IF(G22=58,KILOMETRAJE!G$61,IF(G22=59,KILOMETRAJE!G$62,IF(G22=60,KILOMETRAJE!G$63,IF(G22=61,KILOMETRAJE!G$64,IF(G22=62,KILOMETRAJE!G$65)))))))))))))))))))))))))))))))))))))))))))))))))))))))))))))) -> 1021 | K22: 560.026 | L22: =SUM(J21:J22)/K22 -> 3.6462593 | M22: 7 | N22: 1 | O22: FSM54003 | P22: YAZAKI | Q22: =(IF(N22=1,(J22*0.3)))+(IF(N22=2,(J22*0.15))+(IF(N22=3,(J22*0.15)))) -> 306.3 | R22: =+LOOKUP(P36,UNIDADES!B$3:B$73,UNIDADES!C$3:C$73) -> 2.701058 | S22: =((SUM(J21:J22)/R22))-K22 -> 195.97406 | T22: =(IF(M22=1,(S22*16)))+(IF(M22=2,(S22*17.26))+(IF(M22=3,(S22*17.66))+(IF(M22=4,(S22*18.06))+(IF(M22=5,(S22*18.46))+(IF(M22=6,(S22*18.86))+(IF(M22=7,(S22*19.26)))))))) -> 3774.4603 | U22: 60 | V22: 59
E29: CRUCES | F29: =+'CHAVEZ VARELA NESTOR ADRIAN'!F29:G29 -> 45936 | H29: =+F29+1 -> 45937 | I29: =+H29+1 -> 45938 | J29: =+I29+1 -> 45939 | K29: =+J29+1 -> 45940 | L29: =+K29+2 -> 45942 | N29: TOTAL
H30: 0 | I30: 0 | K30: 0 | L30: 0 | N30: =SUM(F30:L30) -> 0
C32: PERCEPCIONES DE LA SEMANA | I32: ADELANTO DE LIQUIDACION | O32: TOTAL: | Q32: =+F42-L40 -> 8241.4434
C33: PAGO POR KM | F33: =SUM(Q18:Q29) -> 918.9 | I33: CONCEPTO | J33: FECHA | K33: FOLIO | L33: MONTO
C34: DIESEL A FAVOR | F34: =SUM(T18:T29) -> 6722.5434 | Q34: ODM. INICIAL | S34: ODM. FINAL | T34: KM. RECORR
C35: CRUCES | F35: =+N30 -> 0 | O35: 46372 | P35: F-112 | Q35: 382419 | S35: 384479 | T35: =+S35-Q35 -> 2060 | U35: 2042 | V35: 599.686
C36: DOBLE OPERADOR | O36: 45938 | P36: F-117 | Q36: 356499 | S36: 358653 | T36: =+S36-Q36 -> 2154 | U36: 2042 | V36: 560.026
C37: ESTANCIAS | T37: =+S37-Q37 -> 0
C38: BONO DE LA SIERRA
C39: TALLER EXTERNO
C40: PENDIENTE | I40: TOTAL DEDUCCIONES: | L40: =SUM(L34:L39) -> 0
C41: BONO CAMARAS | F41: 600
C42: TOTAL DE PERCEPCIONES: | F42: =SUM(F33:G41) -> 8241.4434 | P42: CODIGO C/V/PT
P43: 1 | Q43: CARGADO
C44: OBSERVACIONES: | P44: 2 | Q44: VACIO
P45: 3 | Q45: PT
D50: FIRMA DE AUTORIZACION | J50: FIRMA DE CONFORMIDAD

Sheet ESCARCEGA GALDEAN JESUS OMAR
Q2: SEMANA:
I3: FLETES SOTELO S.A DE C.V | Q3: =+'CERDA HERNANDEZ JOSE LUIS'!Q3 -> 42
I4: RFC: FSO880915JP8
I5: CAMINO DE LOS ESTEROS 720 | Q5: FOLIO DE LIQUIDACION
I6: PARTIDO DOBALDO CD.JUAREZ CHIHU. | Q6: =+'CERDA HERNANDEZ JOSE LUIS'!Q6+1 -> 1976
I9: INFORMACION DEL OPERADOR
D11: OPERADOR: | E11: ESCARCEGA GALDEAN JESUS OMAR | K11: FECHA DE PERIODO: | L11: =+NOMINA!B3 -> SEMANA #42 PERIODO DEL 06 AL 12 DE OCTUBRE DEL 2025
D12: UNIDAD: | E12: F-112
D14: ODOM.INIC: | F14: 182091 | I14: COMBUSTIBLE INICI: | O14: COMBUSTIBLE CARGADO:
D15: ODOM.FINAL: | F15: 184096 | I15: COMBUSTIBLE FIN: | O15: DIF. DE DIESEL:
D16: KM RECORRIDOS: | F16: =SUM(J20:J30) -> 0 | I16: DIESEL CONSUMIDO: | J16: =SUM(K20:K30) -> 0 | O16: RENDIMIENTO: | P16: =+F16/J16 -> #DIV/0!
C18: FOLIO LIQUIDACION | D18: CORDENADA | E18: FECHA SALIDA | F18: FECHA LLEGADA | G18: R: | H18: ORIGEN | I18: DESTINO | J18: KMS | K18: RECARGA | L18: RENDIMIENTO | M18: REND.PAGO | N18: C / V / PT | O18: REMOLQUE | P18: CLIENTE | Q18: PAGO POR KM | R18: RENDIMIENTO PAGO | S18: LITROS A PAGO | T18: DIESEL A FAVOR | U18: SALIDA | V18: REGRESO
H19: =IF(G19=1,KILOMETRAJE!C$4,IF(G19=2,KILOMETRAJE!C$5,IF(G19=3,KILOMETRAJE!C$6,IF(G19=4,KILOMETRAJE!C$7,IF(G19=5,KILOMETRAJE!C$8,IF(G19=6,KILOMETRAJE!C$9,IF(G19=7,KILOMETRAJE!C$10,IF(G19=8,KILOMETRAJE!C$11,IF(G19=9,KILOMETRAJE!C$12,IF(G19=10,KILOMETRAJE!C$13,IF(G19=11,KILOMETRAJE!C$14,IF(G19=12,KILOMETRAJE!C$15,IF(G19=13,KILOMETRAJE!C$16,IF(G19=14,KILOMETRAJE!C$17,IF(G19=15,KILOMETRAJE!C$18,IF(G19=16,KILOMETRAJE!C$19,IF(G19=17,KILOMETRAJE!C$20,IF(G19=18,KILOMETRAJE!C$21,IF(G19=19,KILOMETRAJE!C$22,IF(G19=20,KILOMETRAJE!C$23,IF(G19=21,KILOMETRAJE!C$24,IF(G19=22,KILOMETRAJE!C$25,IF(G19=23,KILOMETRAJE!C$26,IF(G19=24,KILOMETRAJE!C$27,IF(G19=25,KILOMETRAJE!C$28,IF(G19=26,KILOMETRAJE!C$29,IF(G19=27,KILOMETRAJE!C$30,IF(G19=28,KILOMETRAJE!C$31,IF(G19=29,KILOMETRAJE!C$32,IF(G19=30,KILOMETRAJE!C$33,IF(G19=31,KILOMETRAJE!C$34,IF(G19=32,KILOMETRAJE!C$35,IF(G19=33,KILOMETRAJE!C$36,IF(G19=34,KILOMETRAJE!C$37,IF(G19=35,KILOMETRAJE!C$38,IF(G19=36,KILOMETRAJE!C$39,IF(G19=37,KILOMETRAJE!C$40,IF(G19=38,KILOMETRAJE!C$41,IF(G19=39,KILOMETRAJE!C$42,IF(G19=40,KILOMETRAJE!C$43,IF(G19=41,KILOMETRAJE!C$44,IF(G19=42,KILOMETRAJE!C$45,IF(G19=43,KILOMETRAJE!C$46,IF(G19=44,KILOMETRAJE!C$47,IF(G19=45,KILOMETRAJE!C$48,IF(G19=46,KILOMETRAJE!C$49,IF(G19=47,KILOMETRAJE!C$50,IF(G19=48,KILOMETRAJE!C$51,IF(G19=49,KILOMETRAJE!C$52,IF(G19=50,KILOMETRAJE!C$53,IF(G19=51,KILOMETRAJE!C$54,IF(G19=52,KILOMETRAJE!C$55,IF(G19=53,KILOMETRAJE!C$56,IF(G19=54,KILOMETRAJE!C$57,IF(G19=55,KILOMETRAJE!C$58,IF(G19=56,KILOMETRAJE!C$59,IF(G19=57,KILOMETRAJE!C$60,IF(G19=58,KILOMETRAJE!C$61,IF(G19=59,KILOMETRAJE!C$62,IF(G19=60,KILOMETRAJE!C$63,IF(G19=61,KILOMETRAJE!C$64,IF(G19=62,KILOMETRAJE!C$65)))))))))))))))))))))))))))))))))))))))))))))))))))))))))))))) -> FALSE | I19: =IF(G19=1,KILOMETRAJE!E$4,IF(G19=2,KILOMETRAJE!E$5,IF(G19=3,KILOMETRAJE!E$6,IF(G19=4,KILOMETRAJE!E$7,IF(G19=5,KILOMETRAJE!E$8,IF(G19=6,KILOMETRAJE!E$9,IF(G19=7,KILOMETRAJE!E$10,IF(G19=8,KILOMETRAJE!E$11,IF(G19=9,KILOMETRAJE!E$12,IF(G19=10,KILOMETRAJE!E$13,IF(G19=11,KILOMETRAJE!E$14,IF(G19=12,KILOMETRAJE!E$15,IF(G19=13,KILOMETRAJE!E$16,IF(G19=14,KILOMETRAJE!E$17,IF(G19=15,KILOMETRAJE!E$18,IF(G19=16,KILOMETRAJE!E$19,IF(G19=17,KILOMETRAJE!E$20,IF(G19=18,KILOMETRAJE!E$21,IF(G19=19,KILOMETRAJE!E$22,IF(G19=20,KILOMETRAJE!E$23,IF(G19=21,KILOMETRAJE!E$24,IF(G19=22,KILOMETRAJE!E$25,IF(G19=23,KILOMETRAJE!E$26,IF(G19=24,KILOMETRAJE!E$27,IF(G19=25,KILOMETRAJE!E$28,IF(G19=26,KILOMETRAJE!E$29,IF(G19=27,KILOMETRAJE!E$30,IF(G19=28,KILOMETRAJE!E$31,IF(G19=29,KILOMETRAJE!E$32,IF(G19=30,KILOMETRAJE!E$33,IF(G19=31,KILOMETRAJE!E$34,IF(G19=32,KILOMETRAJE!E$35,IF(G19=33,KILOMETRAJE!E$36,IF(G19=34,KILOMETRAJE!E$37,IF(G19=35,KILOMETRAJE!E$38,IF(G19=36,KILOMETRAJE!E$39,IF(G19=37,KILOMETRAJE!E$40,IF(G19=38,KILOMETRAJE!E$41,IF(G19=39,KILOMETRAJE!E$42,IF(G19=40,KILOMETRAJE!E$43,IF(G19=41,KILOMETRAJE!E$44,IF(G19=42,KILOMETRAJE!E$45,IF(G19=43,KILOMETRAJE!E$46,IF(G19=44,KILOMETRAJE!E$47,IF(G19=45,KILOMETRAJE!E$48,IF(G19=46,KILOMETRAJE!E$49,IF(G19=47,KILOMETRAJE!E$50,IF(G19=48,KILOMETRAJE!E$51,IF(G19=49,KILOMETRAJE!E$52,IF(G19=50,KILOMETRAJE!E$53,IF(G19=51,KILOMETRAJE!E$54,IF(G19=52,KILOMETRAJE!E$55,IF(G19=53,KILOMETRAJE!E$56,IF(G19=54,KILOMETRAJE!E$57,IF(G19=55,KILOMETRAJE!E$58,IF(G19=56,KILOMETRAJE!E$59,IF(G19=57,KILOMETRAJE!E$60,IF(G19=58,KILOMETRAJE!E$61,IF(G19=59,KILOMETRAJE!E$62,IF(G19=60,KILOMETRAJE!E$63,IF(G19=61,KILOMETRAJE!E$64,IF(G19=62,KILOMETRAJE!E$65)))))))))))))))))))))))))))))))))))))))))))))))))))))))))))))) -> FALSE | J19: =IF(G19=1,KILOMETRAJE!G$4,IF(G19=2,KILOMETRAJE!G$5,IF(G19=3,KILOMETRAJE!G$6,IF(G19=4,KILOMETRAJE!G$7,IF(G19=5,KILOMETRAJE!G$8,IF(G19=6,KILOMETRAJE!G$9,IF(G19=7,KILOMETRAJE!G$10,IF(G19=8,KILOMETRAJE!G$11,IF(G19=9,KILOMETRAJE!G$12,IF(G19=10,KILOMETRAJE!G$13,IF(G19=11,KILOMETRAJE!G$14,IF(G19=12,KILOMETRAJE!G$15,IF(G19=13,KILOMETRAJE!G$16,IF(G19=14,KILOMETRAJE!G$17,IF(G19=15,KILOMETRAJE!G$18,IF(G19=16,KILOMETRAJE!G$19,IF(G19=17,KILOMETRAJE!G$20,IF(G19=18,KILOMETRAJE!G$21,IF(G19=19,KILOMETRAJE!G$22,IF(G19=20,KILOMETRAJE!G$23,IF(G19=21,KILOMETRAJE!G$24,IF(G19=22,KILOMETRAJE!G$25,IF(G19=23,KILOMETRAJE!G$26,IF(G19=24,KILOMETRAJE!G$27,IF(G19=25,KILOMETRAJE!G$28,IF(G19=26,KILOMETRAJE!G$29,IF(G19=27,KILOMETRAJE!G$30,IF(G19=28,KILOMETRAJE!G$31,IF(G19=29,KILOMETRAJE!G$32,IF(G19=30,KILOMETRAJE!G$33,IF(G19=31,KILOMETRAJE!G$34,IF(G19=32,KILOMETRAJE!G$35,IF(G19=33,KILOMETRAJE!G$36,IF(G19=34,KILOMETRAJE!G$37,IF(G19=35,KILOMETRAJE!G$38,IF(G19=36,KILOMETRAJE!G$39,IF(G19=37,KILOMETRAJE!G$40,IF(G19=38,KILOMETRAJE!G$41,IF(G19=39,KILOMETRAJE!G$42,IF(G19=40,KILOMETRAJE!G$43,IF(G19=41,KILOMETRAJE!G$44,IF(G19=42,KILOMETRAJE!G$45,IF(G19=43,KILOMETRAJE!G$46,IF(G19=44,KILOMETRAJE!G$47,IF(G19=45,KILOMETRAJE!G$48,IF(G19=46,KILOMETRAJE!G$49,IF(G19=47,KILOMETRAJE!G$50,IF(G19=48,KILOMETRAJE!G$51,IF(G19=49,KILOMETRAJE!G$52,IF(G19=50,KILOMETRAJE!G$53,IF(G19=51,KILOMETRAJE!G$54,IF(G19=52,KILOMETRAJE!G$55,IF(G19=53,KILOMETRAJE!G$56,IF(G19=54,KILOMETRAJE!G$57,IF(G19=55,KILOMETRAJE!G$58,IF(G19=56,KILOMETRAJE!G$59,IF(G19=57,KILOMETRAJE!G$60,IF(G19=58,KILOMETRAJE!G$61,IF(G19=59,KILOMETRAJE!G$62,IF(G19=60,KILOMETRAJE!G$63,IF(G19=61,KILOMETRAJE!G$64,IF(G19=62,KILOMETRAJE!G$65)))))))))))))))))))))))))))))))))))))))))))))))))))))))))))))) -> FALSE | Q19: =(IF(N19=1,(J19*0.3)))+(IF(N19=2,(J19*0.15))+(IF(N19=3,(J19*0.15)))) -> 0
